[2024-12-30T06:22:42.495+0000] {processor.py:186} INFO - Started process (PID=38) to work on /opt/airflow/dags/local_to_gcs.py
[2024-12-30T06:22:42.506+0000] {processor.py:914} INFO - Processing file /opt/airflow/dags/local_to_gcs.py for tasks to queue
[2024-12-30T06:22:42.576+0000] {logging_mixin.py:190} INFO - [2024-12-30T06:22:42.576+0000] {dagbag.py:588} INFO - Filling up the DagBag from /opt/airflow/dags/local_to_gcs.py
[2024-12-30T06:22:42.863+0000] {logging_mixin.py:190} INFO - [2024-12-30T06:22:42.831+0000] {dagbag.py:387} ERROR - Failed to import: /opt/airflow/dags/local_to_gcs.py
Traceback (most recent call last):
  File "/home/airflow/.local/lib/python3.12/site-packages/airflow/models/dagbag.py", line 383, in parse
    loader.exec_module(new_module)
  File "<frozen importlib._bootstrap_external>", line 999, in exec_module
  File "<frozen importlib._bootstrap>", line 488, in _call_with_frames_removed
  File "/opt/airflow/dags/local_to_gcs.py", line 66, in <module>
    retail_dag = retail()  # Instantiate the DAG
                 ^^^^^^^^
  File "/home/airflow/.local/lib/python3.12/site-packages/airflow/models/dag.py", line 4307, in factory
    f(**f_kwargs)
  File "/opt/airflow/dags/local_to_gcs.py", line 31, in retail
    csv_files = [f for f in os.listdir(dataset_folder) if f.endswith(".csv")]
                            ^^^^^^^^^^^^^^^^^^^^^^^^^^
FileNotFoundError: [Errno 2] No such file or directory: 'include/dataset/'
[2024-12-30T06:22:42.870+0000] {processor.py:927} WARNING - No viable dags retrieved from /opt/airflow/dags/local_to_gcs.py
[2024-12-30T06:22:43.081+0000] {processor.py:208} INFO - Processing /opt/airflow/dags/local_to_gcs.py took 0.720 seconds
[2024-12-30T06:23:13.659+0000] {processor.py:186} INFO - Started process (PID=106) to work on /opt/airflow/dags/local_to_gcs.py
[2024-12-30T06:23:13.660+0000] {processor.py:914} INFO - Processing file /opt/airflow/dags/local_to_gcs.py for tasks to queue
[2024-12-30T06:23:13.663+0000] {logging_mixin.py:190} INFO - [2024-12-30T06:23:13.662+0000] {dagbag.py:588} INFO - Filling up the DagBag from /opt/airflow/dags/local_to_gcs.py
[2024-12-30T06:23:13.693+0000] {logging_mixin.py:190} INFO - [2024-12-30T06:23:13.688+0000] {dagbag.py:387} ERROR - Failed to import: /opt/airflow/dags/local_to_gcs.py
Traceback (most recent call last):
  File "/home/airflow/.local/lib/python3.12/site-packages/airflow/models/dagbag.py", line 383, in parse
    loader.exec_module(new_module)
  File "<frozen importlib._bootstrap_external>", line 999, in exec_module
  File "<frozen importlib._bootstrap>", line 488, in _call_with_frames_removed
  File "/opt/airflow/dags/local_to_gcs.py", line 66, in <module>
    retail_dag = retail()  # Instantiate the DAG
                 ^^^^^^^^
  File "/home/airflow/.local/lib/python3.12/site-packages/airflow/models/dag.py", line 4307, in factory
    f(**f_kwargs)
  File "/opt/airflow/dags/local_to_gcs.py", line 31, in retail
    csv_files = [f for f in os.listdir(dataset_folder) if f.endswith(".csv")]
                            ^^^^^^^^^^^^^^^^^^^^^^^^^^
FileNotFoundError: [Errno 2] No such file or directory: 'include/dataset/'
[2024-12-30T06:23:13.695+0000] {processor.py:927} WARNING - No viable dags retrieved from /opt/airflow/dags/local_to_gcs.py
[2024-12-30T06:23:13.720+0000] {processor.py:208} INFO - Processing /opt/airflow/dags/local_to_gcs.py took 0.069 seconds
[2024-12-30T06:23:44.236+0000] {processor.py:186} INFO - Started process (PID=172) to work on /opt/airflow/dags/local_to_gcs.py
[2024-12-30T06:23:44.239+0000] {processor.py:914} INFO - Processing file /opt/airflow/dags/local_to_gcs.py for tasks to queue
[2024-12-30T06:23:44.243+0000] {logging_mixin.py:190} INFO - [2024-12-30T06:23:44.242+0000] {dagbag.py:588} INFO - Filling up the DagBag from /opt/airflow/dags/local_to_gcs.py
[2024-12-30T06:23:44.289+0000] {logging_mixin.py:190} INFO - [2024-12-30T06:23:44.281+0000] {dagbag.py:387} ERROR - Failed to import: /opt/airflow/dags/local_to_gcs.py
Traceback (most recent call last):
  File "/home/airflow/.local/lib/python3.12/site-packages/airflow/models/dagbag.py", line 383, in parse
    loader.exec_module(new_module)
  File "<frozen importlib._bootstrap_external>", line 999, in exec_module
  File "<frozen importlib._bootstrap>", line 488, in _call_with_frames_removed
  File "/opt/airflow/dags/local_to_gcs.py", line 66, in <module>
    retail_dag = retail()  # Instantiate the DAG
                 ^^^^^^^^
  File "/home/airflow/.local/lib/python3.12/site-packages/airflow/models/dag.py", line 4307, in factory
    f(**f_kwargs)
  File "/opt/airflow/dags/local_to_gcs.py", line 31, in retail
    csv_files = [f for f in os.listdir(dataset_folder) if f.endswith(".csv")]
                            ^^^^^^^^^^^^^^^^^^^^^^^^^^
FileNotFoundError: [Errno 2] No such file or directory: 'include/dataset/'
[2024-12-30T06:23:44.297+0000] {processor.py:927} WARNING - No viable dags retrieved from /opt/airflow/dags/local_to_gcs.py
[2024-12-30T06:23:44.331+0000] {processor.py:208} INFO - Processing /opt/airflow/dags/local_to_gcs.py took 0.103 seconds
[2024-12-30T06:24:15.060+0000] {processor.py:186} INFO - Started process (PID=238) to work on /opt/airflow/dags/local_to_gcs.py
[2024-12-30T06:24:15.061+0000] {processor.py:914} INFO - Processing file /opt/airflow/dags/local_to_gcs.py for tasks to queue
[2024-12-30T06:24:15.065+0000] {logging_mixin.py:190} INFO - [2024-12-30T06:24:15.064+0000] {dagbag.py:588} INFO - Filling up the DagBag from /opt/airflow/dags/local_to_gcs.py
[2024-12-30T06:24:15.128+0000] {logging_mixin.py:190} INFO - [2024-12-30T06:24:15.115+0000] {dagbag.py:387} ERROR - Failed to import: /opt/airflow/dags/local_to_gcs.py
Traceback (most recent call last):
  File "/home/airflow/.local/lib/python3.12/site-packages/airflow/models/dagbag.py", line 383, in parse
    loader.exec_module(new_module)
  File "<frozen importlib._bootstrap_external>", line 999, in exec_module
  File "<frozen importlib._bootstrap>", line 488, in _call_with_frames_removed
  File "/opt/airflow/dags/local_to_gcs.py", line 66, in <module>
    retail_dag = retail()  # Instantiate the DAG
                 ^^^^^^^^
  File "/home/airflow/.local/lib/python3.12/site-packages/airflow/models/dag.py", line 4307, in factory
    f(**f_kwargs)
  File "/opt/airflow/dags/local_to_gcs.py", line 31, in retail
    csv_files = [f for f in os.listdir(dataset_folder) if f.endswith(".csv")]
                            ^^^^^^^^^^^^^^^^^^^^^^^^^^
FileNotFoundError: [Errno 2] No such file or directory: 'include/dataset/'
[2024-12-30T06:24:15.132+0000] {processor.py:927} WARNING - No viable dags retrieved from /opt/airflow/dags/local_to_gcs.py
[2024-12-30T06:24:15.176+0000] {processor.py:208} INFO - Processing /opt/airflow/dags/local_to_gcs.py took 0.126 seconds
[2024-12-30T06:24:45.344+0000] {processor.py:186} INFO - Started process (PID=305) to work on /opt/airflow/dags/local_to_gcs.py
[2024-12-30T06:24:45.346+0000] {processor.py:914} INFO - Processing file /opt/airflow/dags/local_to_gcs.py for tasks to queue
[2024-12-30T06:24:45.350+0000] {logging_mixin.py:190} INFO - [2024-12-30T06:24:45.349+0000] {dagbag.py:588} INFO - Filling up the DagBag from /opt/airflow/dags/local_to_gcs.py
[2024-12-30T06:24:45.407+0000] {logging_mixin.py:190} INFO - [2024-12-30T06:24:45.399+0000] {dagbag.py:387} ERROR - Failed to import: /opt/airflow/dags/local_to_gcs.py
Traceback (most recent call last):
  File "/home/airflow/.local/lib/python3.12/site-packages/airflow/models/dagbag.py", line 383, in parse
    loader.exec_module(new_module)
  File "<frozen importlib._bootstrap_external>", line 999, in exec_module
  File "<frozen importlib._bootstrap>", line 488, in _call_with_frames_removed
  File "/opt/airflow/dags/local_to_gcs.py", line 66, in <module>
    retail_dag = retail()  # Instantiate the DAG
                 ^^^^^^^^
  File "/home/airflow/.local/lib/python3.12/site-packages/airflow/models/dag.py", line 4307, in factory
    f(**f_kwargs)
  File "/opt/airflow/dags/local_to_gcs.py", line 31, in retail
    csv_files = [f for f in os.listdir(dataset_folder) if f.endswith(".csv")]
                            ^^^^^^^^^^^^^^^^^^^^^^^^^^
FileNotFoundError: [Errno 2] No such file or directory: 'include/dataset/'
[2024-12-30T06:24:45.410+0000] {processor.py:927} WARNING - No viable dags retrieved from /opt/airflow/dags/local_to_gcs.py
[2024-12-30T06:24:45.454+0000] {processor.py:208} INFO - Processing /opt/airflow/dags/local_to_gcs.py took 0.125 seconds
[2024-12-30T06:25:16.186+0000] {processor.py:186} INFO - Started process (PID=371) to work on /opt/airflow/dags/local_to_gcs.py
[2024-12-30T06:25:16.188+0000] {processor.py:914} INFO - Processing file /opt/airflow/dags/local_to_gcs.py for tasks to queue
[2024-12-30T06:25:16.191+0000] {logging_mixin.py:190} INFO - [2024-12-30T06:25:16.190+0000] {dagbag.py:588} INFO - Filling up the DagBag from /opt/airflow/dags/local_to_gcs.py
[2024-12-30T06:25:16.228+0000] {logging_mixin.py:190} INFO - [2024-12-30T06:25:16.221+0000] {dagbag.py:387} ERROR - Failed to import: /opt/airflow/dags/local_to_gcs.py
Traceback (most recent call last):
  File "/home/airflow/.local/lib/python3.12/site-packages/airflow/models/dagbag.py", line 383, in parse
    loader.exec_module(new_module)
  File "<frozen importlib._bootstrap_external>", line 999, in exec_module
  File "<frozen importlib._bootstrap>", line 488, in _call_with_frames_removed
  File "/opt/airflow/dags/local_to_gcs.py", line 66, in <module>
    retail_dag = retail()  # Instantiate the DAG
                 ^^^^^^^^
  File "/home/airflow/.local/lib/python3.12/site-packages/airflow/models/dag.py", line 4307, in factory
    f(**f_kwargs)
  File "/opt/airflow/dags/local_to_gcs.py", line 31, in retail
    csv_files = [f for f in os.listdir(dataset_folder) if f.endswith(".csv")]
                            ^^^^^^^^^^^^^^^^^^^^^^^^^^
FileNotFoundError: [Errno 2] No such file or directory: 'include/dataset/'
[2024-12-30T06:25:16.230+0000] {processor.py:927} WARNING - No viable dags retrieved from /opt/airflow/dags/local_to_gcs.py
[2024-12-30T06:25:16.257+0000] {processor.py:208} INFO - Processing /opt/airflow/dags/local_to_gcs.py took 0.081 seconds
[2024-12-30T06:25:46.470+0000] {processor.py:186} INFO - Started process (PID=437) to work on /opt/airflow/dags/local_to_gcs.py
[2024-12-30T06:25:46.471+0000] {processor.py:914} INFO - Processing file /opt/airflow/dags/local_to_gcs.py for tasks to queue
[2024-12-30T06:25:46.474+0000] {logging_mixin.py:190} INFO - [2024-12-30T06:25:46.473+0000] {dagbag.py:588} INFO - Filling up the DagBag from /opt/airflow/dags/local_to_gcs.py
[2024-12-30T06:25:46.522+0000] {logging_mixin.py:190} INFO - [2024-12-30T06:25:46.516+0000] {dagbag.py:387} ERROR - Failed to import: /opt/airflow/dags/local_to_gcs.py
Traceback (most recent call last):
  File "/home/airflow/.local/lib/python3.12/site-packages/airflow/models/dagbag.py", line 383, in parse
    loader.exec_module(new_module)
  File "<frozen importlib._bootstrap_external>", line 999, in exec_module
  File "<frozen importlib._bootstrap>", line 488, in _call_with_frames_removed
  File "/opt/airflow/dags/local_to_gcs.py", line 66, in <module>
    retail_dag = retail()  # Instantiate the DAG
                 ^^^^^^^^
  File "/home/airflow/.local/lib/python3.12/site-packages/airflow/models/dag.py", line 4307, in factory
    f(**f_kwargs)
  File "/opt/airflow/dags/local_to_gcs.py", line 31, in retail
    csv_files = [f for f in os.listdir(dataset_folder) if f.endswith(".csv")]
                            ^^^^^^^^^^^^^^^^^^^^^^^^^^
FileNotFoundError: [Errno 2] No such file or directory: 'include/dataset/'
[2024-12-30T06:25:46.524+0000] {processor.py:927} WARNING - No viable dags retrieved from /opt/airflow/dags/local_to_gcs.py
[2024-12-30T06:25:46.604+0000] {processor.py:208} INFO - Processing /opt/airflow/dags/local_to_gcs.py took 0.146 seconds
[2024-12-30T06:26:16.864+0000] {processor.py:186} INFO - Started process (PID=503) to work on /opt/airflow/dags/local_to_gcs.py
[2024-12-30T06:26:16.866+0000] {processor.py:914} INFO - Processing file /opt/airflow/dags/local_to_gcs.py for tasks to queue
[2024-12-30T06:26:16.868+0000] {logging_mixin.py:190} INFO - [2024-12-30T06:26:16.867+0000] {dagbag.py:588} INFO - Filling up the DagBag from /opt/airflow/dags/local_to_gcs.py
[2024-12-30T06:26:16.908+0000] {logging_mixin.py:190} INFO - [2024-12-30T06:26:16.898+0000] {dagbag.py:387} ERROR - Failed to import: /opt/airflow/dags/local_to_gcs.py
Traceback (most recent call last):
  File "/home/airflow/.local/lib/python3.12/site-packages/airflow/models/dagbag.py", line 383, in parse
    loader.exec_module(new_module)
  File "<frozen importlib._bootstrap_external>", line 999, in exec_module
  File "<frozen importlib._bootstrap>", line 488, in _call_with_frames_removed
  File "/opt/airflow/dags/local_to_gcs.py", line 66, in <module>
    retail_dag = retail()  # Instantiate the DAG
                 ^^^^^^^^
  File "/home/airflow/.local/lib/python3.12/site-packages/airflow/models/dag.py", line 4307, in factory
    f(**f_kwargs)
  File "/opt/airflow/dags/local_to_gcs.py", line 31, in retail
    csv_files = [f for f in os.listdir(dataset_folder) if f.endswith(".csv")]
                            ^^^^^^^^^^^^^^^^^^^^^^^^^^
FileNotFoundError: [Errno 2] No such file or directory: 'include/dataset/'
[2024-12-30T06:26:16.910+0000] {processor.py:927} WARNING - No viable dags retrieved from /opt/airflow/dags/local_to_gcs.py
[2024-12-30T06:26:16.942+0000] {processor.py:208} INFO - Processing /opt/airflow/dags/local_to_gcs.py took 0.088 seconds
[2024-12-30T06:26:47.697+0000] {processor.py:186} INFO - Started process (PID=569) to work on /opt/airflow/dags/local_to_gcs.py
[2024-12-30T06:26:47.699+0000] {processor.py:914} INFO - Processing file /opt/airflow/dags/local_to_gcs.py for tasks to queue
[2024-12-30T06:26:47.702+0000] {logging_mixin.py:190} INFO - [2024-12-30T06:26:47.701+0000] {dagbag.py:588} INFO - Filling up the DagBag from /opt/airflow/dags/local_to_gcs.py
[2024-12-30T06:26:47.746+0000] {logging_mixin.py:190} INFO - [2024-12-30T06:26:47.735+0000] {dagbag.py:387} ERROR - Failed to import: /opt/airflow/dags/local_to_gcs.py
Traceback (most recent call last):
  File "/home/airflow/.local/lib/python3.12/site-packages/airflow/models/dagbag.py", line 383, in parse
    loader.exec_module(new_module)
  File "<frozen importlib._bootstrap_external>", line 999, in exec_module
  File "<frozen importlib._bootstrap>", line 488, in _call_with_frames_removed
  File "/opt/airflow/dags/local_to_gcs.py", line 66, in <module>
    retail_dag = retail()  # Instantiate the DAG
                 ^^^^^^^^
  File "/home/airflow/.local/lib/python3.12/site-packages/airflow/models/dag.py", line 4307, in factory
    f(**f_kwargs)
  File "/opt/airflow/dags/local_to_gcs.py", line 31, in retail
    csv_files = [f for f in os.listdir(dataset_folder) if f.endswith(".csv")]
                            ^^^^^^^^^^^^^^^^^^^^^^^^^^
FileNotFoundError: [Errno 2] No such file or directory: 'include/dataset/'
[2024-12-30T06:26:47.749+0000] {processor.py:927} WARNING - No viable dags retrieved from /opt/airflow/dags/local_to_gcs.py
[2024-12-30T06:26:47.794+0000] {processor.py:208} INFO - Processing /opt/airflow/dags/local_to_gcs.py took 0.108 seconds
[2024-12-30T06:27:18.556+0000] {processor.py:186} INFO - Started process (PID=634) to work on /opt/airflow/dags/local_to_gcs.py
[2024-12-30T06:27:18.558+0000] {processor.py:914} INFO - Processing file /opt/airflow/dags/local_to_gcs.py for tasks to queue
[2024-12-30T06:27:18.561+0000] {logging_mixin.py:190} INFO - [2024-12-30T06:27:18.561+0000] {dagbag.py:588} INFO - Filling up the DagBag from /opt/airflow/dags/local_to_gcs.py
[2024-12-30T06:27:18.600+0000] {logging_mixin.py:190} INFO - [2024-12-30T06:27:18.592+0000] {dagbag.py:387} ERROR - Failed to import: /opt/airflow/dags/local_to_gcs.py
Traceback (most recent call last):
  File "/home/airflow/.local/lib/python3.12/site-packages/airflow/models/dagbag.py", line 383, in parse
    loader.exec_module(new_module)
  File "<frozen importlib._bootstrap_external>", line 999, in exec_module
  File "<frozen importlib._bootstrap>", line 488, in _call_with_frames_removed
  File "/opt/airflow/dags/local_to_gcs.py", line 66, in <module>
    retail_dag = retail()  # Instantiate the DAG
                 ^^^^^^^^
  File "/home/airflow/.local/lib/python3.12/site-packages/airflow/models/dag.py", line 4307, in factory
    f(**f_kwargs)
  File "/opt/airflow/dags/local_to_gcs.py", line 31, in retail
    csv_files = [f for f in os.listdir(dataset_folder) if f.endswith(".csv")]
                            ^^^^^^^^^^^^^^^^^^^^^^^^^^
FileNotFoundError: [Errno 2] No such file or directory: 'include/dataset/'
[2024-12-30T06:27:18.603+0000] {processor.py:927} WARNING - No viable dags retrieved from /opt/airflow/dags/local_to_gcs.py
[2024-12-30T06:27:18.634+0000] {processor.py:208} INFO - Processing /opt/airflow/dags/local_to_gcs.py took 0.088 seconds
[2024-12-30T06:27:49.143+0000] {processor.py:186} INFO - Started process (PID=700) to work on /opt/airflow/dags/local_to_gcs.py
[2024-12-30T06:27:49.144+0000] {processor.py:914} INFO - Processing file /opt/airflow/dags/local_to_gcs.py for tasks to queue
[2024-12-30T06:27:49.148+0000] {logging_mixin.py:190} INFO - [2024-12-30T06:27:49.147+0000] {dagbag.py:588} INFO - Filling up the DagBag from /opt/airflow/dags/local_to_gcs.py
[2024-12-30T06:27:49.186+0000] {logging_mixin.py:190} INFO - [2024-12-30T06:27:49.178+0000] {dagbag.py:387} ERROR - Failed to import: /opt/airflow/dags/local_to_gcs.py
Traceback (most recent call last):
  File "/home/airflow/.local/lib/python3.12/site-packages/airflow/models/dagbag.py", line 383, in parse
    loader.exec_module(new_module)
  File "<frozen importlib._bootstrap_external>", line 999, in exec_module
  File "<frozen importlib._bootstrap>", line 488, in _call_with_frames_removed
  File "/opt/airflow/dags/local_to_gcs.py", line 66, in <module>
    retail_dag = retail()  # Instantiate the DAG
                 ^^^^^^^^
  File "/home/airflow/.local/lib/python3.12/site-packages/airflow/models/dag.py", line 4307, in factory
    f(**f_kwargs)
  File "/opt/airflow/dags/local_to_gcs.py", line 31, in retail
    csv_files = [f for f in os.listdir(dataset_folder) if f.endswith(".csv")]
                            ^^^^^^^^^^^^^^^^^^^^^^^^^^
FileNotFoundError: [Errno 2] No such file or directory: 'include/dataset/'
[2024-12-30T06:27:49.190+0000] {processor.py:927} WARNING - No viable dags retrieved from /opt/airflow/dags/local_to_gcs.py
[2024-12-30T06:27:49.229+0000] {processor.py:208} INFO - Processing /opt/airflow/dags/local_to_gcs.py took 0.100 seconds
[2024-12-30T06:28:19.867+0000] {processor.py:186} INFO - Started process (PID=766) to work on /opt/airflow/dags/local_to_gcs.py
[2024-12-30T06:28:19.870+0000] {processor.py:914} INFO - Processing file /opt/airflow/dags/local_to_gcs.py for tasks to queue
[2024-12-30T06:28:19.883+0000] {logging_mixin.py:190} INFO - [2024-12-30T06:28:19.881+0000] {dagbag.py:588} INFO - Filling up the DagBag from /opt/airflow/dags/local_to_gcs.py
[2024-12-30T06:28:20.282+0000] {logging_mixin.py:190} INFO - [2024-12-30T06:28:20.252+0000] {dagbag.py:387} ERROR - Failed to import: /opt/airflow/dags/local_to_gcs.py
Traceback (most recent call last):
  File "/home/airflow/.local/lib/python3.12/site-packages/airflow/models/dagbag.py", line 383, in parse
    loader.exec_module(new_module)
  File "<frozen importlib._bootstrap_external>", line 999, in exec_module
  File "<frozen importlib._bootstrap>", line 488, in _call_with_frames_removed
  File "/opt/airflow/dags/local_to_gcs.py", line 66, in <module>
    retail_dag = retail()  # Instantiate the DAG
                 ^^^^^^^^
  File "/home/airflow/.local/lib/python3.12/site-packages/airflow/models/dag.py", line 4307, in factory
    f(**f_kwargs)
  File "/opt/airflow/dags/local_to_gcs.py", line 31, in retail
    csv_files = [f for f in os.listdir(dataset_folder) if f.endswith(".csv")]
                            ^^^^^^^^^^^^^^^^^^^^^^^^^^
FileNotFoundError: [Errno 2] No such file or directory: 'include/dataset/'
[2024-12-30T06:28:20.285+0000] {processor.py:927} WARNING - No viable dags retrieved from /opt/airflow/dags/local_to_gcs.py
[2024-12-30T06:28:20.501+0000] {processor.py:208} INFO - Processing /opt/airflow/dags/local_to_gcs.py took 0.671 seconds
[2024-12-30T06:28:50.683+0000] {processor.py:186} INFO - Started process (PID=831) to work on /opt/airflow/dags/local_to_gcs.py
[2024-12-30T06:28:50.690+0000] {processor.py:914} INFO - Processing file /opt/airflow/dags/local_to_gcs.py for tasks to queue
[2024-12-30T06:28:50.697+0000] {logging_mixin.py:190} INFO - [2024-12-30T06:28:50.696+0000] {dagbag.py:588} INFO - Filling up the DagBag from /opt/airflow/dags/local_to_gcs.py
[2024-12-30T06:28:50.767+0000] {logging_mixin.py:190} INFO - [2024-12-30T06:28:50.753+0000] {dagbag.py:387} ERROR - Failed to import: /opt/airflow/dags/local_to_gcs.py
Traceback (most recent call last):
  File "/home/airflow/.local/lib/python3.12/site-packages/airflow/models/dagbag.py", line 383, in parse
    loader.exec_module(new_module)
  File "<frozen importlib._bootstrap_external>", line 999, in exec_module
  File "<frozen importlib._bootstrap>", line 488, in _call_with_frames_removed
  File "/opt/airflow/dags/local_to_gcs.py", line 66, in <module>
    retail_dag = retail()  # Instantiate the DAG
                 ^^^^^^^^
  File "/home/airflow/.local/lib/python3.12/site-packages/airflow/models/dag.py", line 4307, in factory
    f(**f_kwargs)
  File "/opt/airflow/dags/local_to_gcs.py", line 31, in retail
    csv_files = [f for f in os.listdir(dataset_folder) if f.endswith(".csv")]
                            ^^^^^^^^^^^^^^^^^^^^^^^^^^
FileNotFoundError: [Errno 2] No such file or directory: 'include/dataset/'
[2024-12-30T06:28:50.770+0000] {processor.py:927} WARNING - No viable dags retrieved from /opt/airflow/dags/local_to_gcs.py
[2024-12-30T06:28:50.846+0000] {processor.py:208} INFO - Processing /opt/airflow/dags/local_to_gcs.py took 0.180 seconds
[2024-12-30T06:29:21.850+0000] {processor.py:186} INFO - Started process (PID=896) to work on /opt/airflow/dags/local_to_gcs.py
[2024-12-30T06:29:21.853+0000] {processor.py:914} INFO - Processing file /opt/airflow/dags/local_to_gcs.py for tasks to queue
[2024-12-30T06:29:21.857+0000] {logging_mixin.py:190} INFO - [2024-12-30T06:29:21.857+0000] {dagbag.py:588} INFO - Filling up the DagBag from /opt/airflow/dags/local_to_gcs.py
[2024-12-30T06:29:21.923+0000] {logging_mixin.py:190} INFO - [2024-12-30T06:29:21.913+0000] {dagbag.py:387} ERROR - Failed to import: /opt/airflow/dags/local_to_gcs.py
Traceback (most recent call last):
  File "/home/airflow/.local/lib/python3.12/site-packages/airflow/models/dagbag.py", line 383, in parse
    loader.exec_module(new_module)
  File "<frozen importlib._bootstrap_external>", line 999, in exec_module
  File "<frozen importlib._bootstrap>", line 488, in _call_with_frames_removed
  File "/opt/airflow/dags/local_to_gcs.py", line 66, in <module>
    retail_dag = retail()  # Instantiate the DAG
                 ^^^^^^^^
  File "/home/airflow/.local/lib/python3.12/site-packages/airflow/models/dag.py", line 4307, in factory
    f(**f_kwargs)
  File "/opt/airflow/dags/local_to_gcs.py", line 31, in retail
    csv_files = [f for f in os.listdir(dataset_folder) if f.endswith(".csv")]
                            ^^^^^^^^^^^^^^^^^^^^^^^^^^
FileNotFoundError: [Errno 2] No such file or directory: 'include/dataset/'
[2024-12-30T06:29:21.927+0000] {processor.py:927} WARNING - No viable dags retrieved from /opt/airflow/dags/local_to_gcs.py
[2024-12-30T06:29:21.982+0000] {processor.py:208} INFO - Processing /opt/airflow/dags/local_to_gcs.py took 0.149 seconds
[2024-12-30T06:29:52.833+0000] {processor.py:186} INFO - Started process (PID=962) to work on /opt/airflow/dags/local_to_gcs.py
[2024-12-30T06:29:52.837+0000] {processor.py:914} INFO - Processing file /opt/airflow/dags/local_to_gcs.py for tasks to queue
[2024-12-30T06:29:52.842+0000] {logging_mixin.py:190} INFO - [2024-12-30T06:29:52.840+0000] {dagbag.py:588} INFO - Filling up the DagBag from /opt/airflow/dags/local_to_gcs.py
[2024-12-30T06:29:52.916+0000] {logging_mixin.py:190} INFO - [2024-12-30T06:29:52.905+0000] {dagbag.py:387} ERROR - Failed to import: /opt/airflow/dags/local_to_gcs.py
Traceback (most recent call last):
  File "/home/airflow/.local/lib/python3.12/site-packages/airflow/models/dagbag.py", line 383, in parse
    loader.exec_module(new_module)
  File "<frozen importlib._bootstrap_external>", line 999, in exec_module
  File "<frozen importlib._bootstrap>", line 488, in _call_with_frames_removed
  File "/opt/airflow/dags/local_to_gcs.py", line 66, in <module>
    retail_dag = retail()  # Instantiate the DAG
                 ^^^^^^^^
  File "/home/airflow/.local/lib/python3.12/site-packages/airflow/models/dag.py", line 4307, in factory
    f(**f_kwargs)
  File "/opt/airflow/dags/local_to_gcs.py", line 31, in retail
    csv_files = [f for f in os.listdir(dataset_folder) if f.endswith(".csv")]
                            ^^^^^^^^^^^^^^^^^^^^^^^^^^
FileNotFoundError: [Errno 2] No such file or directory: 'include/dataset/'
[2024-12-30T06:29:52.921+0000] {processor.py:927} WARNING - No viable dags retrieved from /opt/airflow/dags/local_to_gcs.py
[2024-12-30T06:29:52.972+0000] {processor.py:208} INFO - Processing /opt/airflow/dags/local_to_gcs.py took 0.153 seconds
[2024-12-30T06:30:23.835+0000] {processor.py:186} INFO - Started process (PID=1027) to work on /opt/airflow/dags/local_to_gcs.py
[2024-12-30T06:30:23.838+0000] {processor.py:914} INFO - Processing file /opt/airflow/dags/local_to_gcs.py for tasks to queue
[2024-12-30T06:30:23.843+0000] {logging_mixin.py:190} INFO - [2024-12-30T06:30:23.842+0000] {dagbag.py:588} INFO - Filling up the DagBag from /opt/airflow/dags/local_to_gcs.py
[2024-12-30T06:30:23.929+0000] {logging_mixin.py:190} INFO - [2024-12-30T06:30:23.912+0000] {dagbag.py:387} ERROR - Failed to import: /opt/airflow/dags/local_to_gcs.py
Traceback (most recent call last):
  File "/home/airflow/.local/lib/python3.12/site-packages/airflow/models/dagbag.py", line 383, in parse
    loader.exec_module(new_module)
  File "<frozen importlib._bootstrap_external>", line 999, in exec_module
  File "<frozen importlib._bootstrap>", line 488, in _call_with_frames_removed
  File "/opt/airflow/dags/local_to_gcs.py", line 66, in <module>
    retail_dag = retail()  # Instantiate the DAG
                 ^^^^^^^^
  File "/home/airflow/.local/lib/python3.12/site-packages/airflow/models/dag.py", line 4307, in factory
    f(**f_kwargs)
  File "/opt/airflow/dags/local_to_gcs.py", line 31, in retail
    csv_files = [f for f in os.listdir(dataset_folder) if f.endswith(".csv")]
                            ^^^^^^^^^^^^^^^^^^^^^^^^^^
FileNotFoundError: [Errno 2] No such file or directory: 'include/dataset/'
[2024-12-30T06:30:23.948+0000] {processor.py:927} WARNING - No viable dags retrieved from /opt/airflow/dags/local_to_gcs.py
[2024-12-30T06:30:24.046+0000] {processor.py:208} INFO - Processing /opt/airflow/dags/local_to_gcs.py took 0.226 seconds
[2024-12-30T06:30:54.344+0000] {processor.py:186} INFO - Started process (PID=1093) to work on /opt/airflow/dags/local_to_gcs.py
[2024-12-30T06:30:54.352+0000] {processor.py:914} INFO - Processing file /opt/airflow/dags/local_to_gcs.py for tasks to queue
[2024-12-30T06:30:54.370+0000] {logging_mixin.py:190} INFO - [2024-12-30T06:30:54.369+0000] {dagbag.py:588} INFO - Filling up the DagBag from /opt/airflow/dags/local_to_gcs.py
[2024-12-30T06:30:54.591+0000] {logging_mixin.py:190} INFO - [2024-12-30T06:30:54.526+0000] {dagbag.py:387} ERROR - Failed to import: /opt/airflow/dags/local_to_gcs.py
Traceback (most recent call last):
  File "/home/airflow/.local/lib/python3.12/site-packages/airflow/models/dagbag.py", line 383, in parse
    loader.exec_module(new_module)
  File "<frozen importlib._bootstrap_external>", line 999, in exec_module
  File "<frozen importlib._bootstrap>", line 488, in _call_with_frames_removed
  File "/opt/airflow/dags/local_to_gcs.py", line 66, in <module>
    retail_dag = retail()  # Instantiate the DAG
                 ^^^^^^^^
  File "/home/airflow/.local/lib/python3.12/site-packages/airflow/models/dag.py", line 4307, in factory
    f(**f_kwargs)
  File "/opt/airflow/dags/local_to_gcs.py", line 31, in retail
    csv_files = [f for f in os.listdir(dataset_folder) if f.endswith(".csv")]
                            ^^^^^^^^^^^^^^^^^^^^^^^^^^
FileNotFoundError: [Errno 2] No such file or directory: 'include/dataset/'
[2024-12-30T06:30:54.601+0000] {processor.py:927} WARNING - No viable dags retrieved from /opt/airflow/dags/local_to_gcs.py
[2024-12-30T06:30:54.959+0000] {processor.py:208} INFO - Processing /opt/airflow/dags/local_to_gcs.py took 0.660 seconds
[2024-12-30T06:31:25.511+0000] {processor.py:186} INFO - Started process (PID=1165) to work on /opt/airflow/dags/local_to_gcs.py
[2024-12-30T06:31:25.513+0000] {processor.py:914} INFO - Processing file /opt/airflow/dags/local_to_gcs.py for tasks to queue
[2024-12-30T06:31:25.515+0000] {logging_mixin.py:190} INFO - [2024-12-30T06:31:25.515+0000] {dagbag.py:588} INFO - Filling up the DagBag from /opt/airflow/dags/local_to_gcs.py
[2024-12-30T06:31:25.569+0000] {logging_mixin.py:190} INFO - [2024-12-30T06:31:25.559+0000] {dagbag.py:387} ERROR - Failed to import: /opt/airflow/dags/local_to_gcs.py
Traceback (most recent call last):
  File "/home/airflow/.local/lib/python3.12/site-packages/airflow/models/dagbag.py", line 383, in parse
    loader.exec_module(new_module)
  File "<frozen importlib._bootstrap_external>", line 999, in exec_module
  File "<frozen importlib._bootstrap>", line 488, in _call_with_frames_removed
  File "/opt/airflow/dags/local_to_gcs.py", line 66, in <module>
    retail_dag = retail()  # Instantiate the DAG
                 ^^^^^^^^
  File "/home/airflow/.local/lib/python3.12/site-packages/airflow/models/dag.py", line 4307, in factory
    f(**f_kwargs)
  File "/opt/airflow/dags/local_to_gcs.py", line 31, in retail
    csv_files = [f for f in os.listdir(dataset_folder) if f.endswith(".csv")]
                            ^^^^^^^^^^^^^^^^^^^^^^^^^^
FileNotFoundError: [Errno 2] No such file or directory: 'include/dataset/'
[2024-12-30T06:31:25.572+0000] {processor.py:927} WARNING - No viable dags retrieved from /opt/airflow/dags/local_to_gcs.py
[2024-12-30T06:31:25.612+0000] {processor.py:208} INFO - Processing /opt/airflow/dags/local_to_gcs.py took 0.111 seconds
[2024-12-30T06:31:55.771+0000] {processor.py:186} INFO - Started process (PID=1232) to work on /opt/airflow/dags/local_to_gcs.py
[2024-12-30T06:31:55.772+0000] {processor.py:914} INFO - Processing file /opt/airflow/dags/local_to_gcs.py for tasks to queue
[2024-12-30T06:31:55.774+0000] {logging_mixin.py:190} INFO - [2024-12-30T06:31:55.774+0000] {dagbag.py:588} INFO - Filling up the DagBag from /opt/airflow/dags/local_to_gcs.py
[2024-12-30T06:31:55.812+0000] {logging_mixin.py:190} INFO - [2024-12-30T06:31:55.806+0000] {dagbag.py:387} ERROR - Failed to import: /opt/airflow/dags/local_to_gcs.py
Traceback (most recent call last):
  File "/home/airflow/.local/lib/python3.12/site-packages/airflow/models/dagbag.py", line 383, in parse
    loader.exec_module(new_module)
  File "<frozen importlib._bootstrap_external>", line 999, in exec_module
  File "<frozen importlib._bootstrap>", line 488, in _call_with_frames_removed
  File "/opt/airflow/dags/local_to_gcs.py", line 66, in <module>
    retail_dag = retail()  # Instantiate the DAG
                 ^^^^^^^^
  File "/home/airflow/.local/lib/python3.12/site-packages/airflow/models/dag.py", line 4307, in factory
    f(**f_kwargs)
  File "/opt/airflow/dags/local_to_gcs.py", line 31, in retail
    csv_files = [f for f in os.listdir(dataset_folder) if f.endswith(".csv")]
                            ^^^^^^^^^^^^^^^^^^^^^^^^^^
FileNotFoundError: [Errno 2] No such file or directory: 'include/dataset/'
[2024-12-30T06:31:55.814+0000] {processor.py:927} WARNING - No viable dags retrieved from /opt/airflow/dags/local_to_gcs.py
[2024-12-30T06:31:55.844+0000] {processor.py:208} INFO - Processing /opt/airflow/dags/local_to_gcs.py took 0.082 seconds
[2024-12-30T06:32:26.238+0000] {processor.py:186} INFO - Started process (PID=1297) to work on /opt/airflow/dags/local_to_gcs.py
[2024-12-30T06:32:26.240+0000] {processor.py:914} INFO - Processing file /opt/airflow/dags/local_to_gcs.py for tasks to queue
[2024-12-30T06:32:26.242+0000] {logging_mixin.py:190} INFO - [2024-12-30T06:32:26.242+0000] {dagbag.py:588} INFO - Filling up the DagBag from /opt/airflow/dags/local_to_gcs.py
[2024-12-30T06:32:26.283+0000] {logging_mixin.py:190} INFO - [2024-12-30T06:32:26.276+0000] {dagbag.py:387} ERROR - Failed to import: /opt/airflow/dags/local_to_gcs.py
Traceback (most recent call last):
  File "/home/airflow/.local/lib/python3.12/site-packages/airflow/models/dagbag.py", line 383, in parse
    loader.exec_module(new_module)
  File "<frozen importlib._bootstrap_external>", line 999, in exec_module
  File "<frozen importlib._bootstrap>", line 488, in _call_with_frames_removed
  File "/opt/airflow/dags/local_to_gcs.py", line 66, in <module>
    retail_dag = retail()  # Instantiate the DAG
                 ^^^^^^^^
  File "/home/airflow/.local/lib/python3.12/site-packages/airflow/models/dag.py", line 4307, in factory
    f(**f_kwargs)
  File "/opt/airflow/dags/local_to_gcs.py", line 31, in retail
    csv_files = [f for f in os.listdir(dataset_folder) if f.endswith(".csv")]
                            ^^^^^^^^^^^^^^^^^^^^^^^^^^
FileNotFoundError: [Errno 2] No such file or directory: 'include/dataset/'
[2024-12-30T06:32:26.286+0000] {processor.py:927} WARNING - No viable dags retrieved from /opt/airflow/dags/local_to_gcs.py
[2024-12-30T06:32:26.316+0000] {processor.py:208} INFO - Processing /opt/airflow/dags/local_to_gcs.py took 0.086 seconds
[2024-12-30T06:32:56.865+0000] {processor.py:186} INFO - Started process (PID=1363) to work on /opt/airflow/dags/local_to_gcs.py
[2024-12-30T06:32:56.866+0000] {processor.py:914} INFO - Processing file /opt/airflow/dags/local_to_gcs.py for tasks to queue
[2024-12-30T06:32:56.868+0000] {logging_mixin.py:190} INFO - [2024-12-30T06:32:56.868+0000] {dagbag.py:588} INFO - Filling up the DagBag from /opt/airflow/dags/local_to_gcs.py
[2024-12-30T06:32:56.903+0000] {logging_mixin.py:190} INFO - [2024-12-30T06:32:56.897+0000] {dagbag.py:387} ERROR - Failed to import: /opt/airflow/dags/local_to_gcs.py
Traceback (most recent call last):
  File "/home/airflow/.local/lib/python3.12/site-packages/airflow/models/dagbag.py", line 383, in parse
    loader.exec_module(new_module)
  File "<frozen importlib._bootstrap_external>", line 999, in exec_module
  File "<frozen importlib._bootstrap>", line 488, in _call_with_frames_removed
  File "/opt/airflow/dags/local_to_gcs.py", line 66, in <module>
    retail_dag = retail()  # Instantiate the DAG
                 ^^^^^^^^
  File "/home/airflow/.local/lib/python3.12/site-packages/airflow/models/dag.py", line 4307, in factory
    f(**f_kwargs)
  File "/opt/airflow/dags/local_to_gcs.py", line 31, in retail
    csv_files = [f for f in os.listdir(dataset_folder) if f.endswith(".csv")]
                            ^^^^^^^^^^^^^^^^^^^^^^^^^^
FileNotFoundError: [Errno 2] No such file or directory: 'include/dataset/'
[2024-12-30T06:32:56.905+0000] {processor.py:927} WARNING - No viable dags retrieved from /opt/airflow/dags/local_to_gcs.py
[2024-12-30T06:32:56.939+0000] {processor.py:208} INFO - Processing /opt/airflow/dags/local_to_gcs.py took 0.083 seconds
[2024-12-30T06:33:27.513+0000] {processor.py:186} INFO - Started process (PID=1429) to work on /opt/airflow/dags/local_to_gcs.py
[2024-12-30T06:33:27.515+0000] {processor.py:914} INFO - Processing file /opt/airflow/dags/local_to_gcs.py for tasks to queue
[2024-12-30T06:33:27.517+0000] {logging_mixin.py:190} INFO - [2024-12-30T06:33:27.517+0000] {dagbag.py:588} INFO - Filling up the DagBag from /opt/airflow/dags/local_to_gcs.py
[2024-12-30T06:33:27.581+0000] {logging_mixin.py:190} INFO - [2024-12-30T06:33:27.567+0000] {dagbag.py:387} ERROR - Failed to import: /opt/airflow/dags/local_to_gcs.py
Traceback (most recent call last):
  File "/home/airflow/.local/lib/python3.12/site-packages/airflow/models/dagbag.py", line 383, in parse
    loader.exec_module(new_module)
  File "<frozen importlib._bootstrap_external>", line 999, in exec_module
  File "<frozen importlib._bootstrap>", line 488, in _call_with_frames_removed
  File "/opt/airflow/dags/local_to_gcs.py", line 66, in <module>
    retail_dag = retail()  # Instantiate the DAG
                 ^^^^^^^^
  File "/home/airflow/.local/lib/python3.12/site-packages/airflow/models/dag.py", line 4307, in factory
    f(**f_kwargs)
  File "/opt/airflow/dags/local_to_gcs.py", line 31, in retail
    csv_files = [f for f in os.listdir(dataset_folder) if f.endswith(".csv")]
                            ^^^^^^^^^^^^^^^^^^^^^^^^^^
FileNotFoundError: [Errno 2] No such file or directory: 'include/dataset/'
[2024-12-30T06:33:27.585+0000] {processor.py:927} WARNING - No viable dags retrieved from /opt/airflow/dags/local_to_gcs.py
[2024-12-30T06:33:27.622+0000] {processor.py:208} INFO - Processing /opt/airflow/dags/local_to_gcs.py took 0.119 seconds
[2024-12-30T06:33:57.732+0000] {processor.py:186} INFO - Started process (PID=1495) to work on /opt/airflow/dags/local_to_gcs.py
[2024-12-30T06:33:57.737+0000] {processor.py:914} INFO - Processing file /opt/airflow/dags/local_to_gcs.py for tasks to queue
[2024-12-30T06:33:57.741+0000] {logging_mixin.py:190} INFO - [2024-12-30T06:33:57.740+0000] {dagbag.py:588} INFO - Filling up the DagBag from /opt/airflow/dags/local_to_gcs.py
[2024-12-30T06:33:57.807+0000] {logging_mixin.py:190} INFO - [2024-12-30T06:33:57.793+0000] {dagbag.py:387} ERROR - Failed to import: /opt/airflow/dags/local_to_gcs.py
Traceback (most recent call last):
  File "/home/airflow/.local/lib/python3.12/site-packages/airflow/models/dagbag.py", line 383, in parse
    loader.exec_module(new_module)
  File "<frozen importlib._bootstrap_external>", line 999, in exec_module
  File "<frozen importlib._bootstrap>", line 488, in _call_with_frames_removed
  File "/opt/airflow/dags/local_to_gcs.py", line 66, in <module>
    retail_dag = retail()  # Instantiate the DAG
                 ^^^^^^^^
  File "/home/airflow/.local/lib/python3.12/site-packages/airflow/models/dag.py", line 4307, in factory
    f(**f_kwargs)
  File "/opt/airflow/dags/local_to_gcs.py", line 31, in retail
    csv_files = [f for f in os.listdir(dataset_folder) if f.endswith(".csv")]
                            ^^^^^^^^^^^^^^^^^^^^^^^^^^
FileNotFoundError: [Errno 2] No such file or directory: 'include/dataset/'
[2024-12-30T06:33:57.810+0000] {processor.py:927} WARNING - No viable dags retrieved from /opt/airflow/dags/local_to_gcs.py
[2024-12-30T06:33:57.866+0000] {processor.py:208} INFO - Processing /opt/airflow/dags/local_to_gcs.py took 0.147 seconds
[2024-12-30T06:34:28.006+0000] {processor.py:186} INFO - Started process (PID=1561) to work on /opt/airflow/dags/local_to_gcs.py
[2024-12-30T06:34:28.008+0000] {processor.py:914} INFO - Processing file /opt/airflow/dags/local_to_gcs.py for tasks to queue
[2024-12-30T06:34:28.012+0000] {logging_mixin.py:190} INFO - [2024-12-30T06:34:28.011+0000] {dagbag.py:588} INFO - Filling up the DagBag from /opt/airflow/dags/local_to_gcs.py
[2024-12-30T06:34:28.083+0000] {logging_mixin.py:190} INFO - [2024-12-30T06:34:28.073+0000] {dagbag.py:387} ERROR - Failed to import: /opt/airflow/dags/local_to_gcs.py
Traceback (most recent call last):
  File "/home/airflow/.local/lib/python3.12/site-packages/airflow/models/dagbag.py", line 383, in parse
    loader.exec_module(new_module)
  File "<frozen importlib._bootstrap_external>", line 999, in exec_module
  File "<frozen importlib._bootstrap>", line 488, in _call_with_frames_removed
  File "/opt/airflow/dags/local_to_gcs.py", line 66, in <module>
    retail_dag = retail()  # Instantiate the DAG
                 ^^^^^^^^
  File "/home/airflow/.local/lib/python3.12/site-packages/airflow/models/dag.py", line 4307, in factory
    f(**f_kwargs)
  File "/opt/airflow/dags/local_to_gcs.py", line 31, in retail
    csv_files = [f for f in os.listdir(dataset_folder) if f.endswith(".csv")]
                            ^^^^^^^^^^^^^^^^^^^^^^^^^^
FileNotFoundError: [Errno 2] No such file or directory: 'include/dataset/'
[2024-12-30T06:34:28.086+0000] {processor.py:927} WARNING - No viable dags retrieved from /opt/airflow/dags/local_to_gcs.py
[2024-12-30T06:34:28.133+0000] {processor.py:208} INFO - Processing /opt/airflow/dags/local_to_gcs.py took 0.136 seconds
[2024-12-30T06:34:58.425+0000] {processor.py:186} INFO - Started process (PID=1627) to work on /opt/airflow/dags/local_to_gcs.py
[2024-12-30T06:34:58.427+0000] {processor.py:914} INFO - Processing file /opt/airflow/dags/local_to_gcs.py for tasks to queue
[2024-12-30T06:34:58.433+0000] {logging_mixin.py:190} INFO - [2024-12-30T06:34:58.430+0000] {dagbag.py:588} INFO - Filling up the DagBag from /opt/airflow/dags/local_to_gcs.py
[2024-12-30T06:34:58.480+0000] {logging_mixin.py:190} INFO - [2024-12-30T06:34:58.470+0000] {dagbag.py:387} ERROR - Failed to import: /opt/airflow/dags/local_to_gcs.py
Traceback (most recent call last):
  File "/home/airflow/.local/lib/python3.12/site-packages/airflow/models/dagbag.py", line 383, in parse
    loader.exec_module(new_module)
  File "<frozen importlib._bootstrap_external>", line 999, in exec_module
  File "<frozen importlib._bootstrap>", line 488, in _call_with_frames_removed
  File "/opt/airflow/dags/local_to_gcs.py", line 66, in <module>
    retail_dag = retail()  # Instantiate the DAG
                 ^^^^^^^^
  File "/home/airflow/.local/lib/python3.12/site-packages/airflow/models/dag.py", line 4307, in factory
    f(**f_kwargs)
  File "/opt/airflow/dags/local_to_gcs.py", line 31, in retail
    csv_files = [f for f in os.listdir(dataset_folder) if f.endswith(".csv")]
                            ^^^^^^^^^^^^^^^^^^^^^^^^^^
FileNotFoundError: [Errno 2] No such file or directory: 'include/dataset/'
[2024-12-30T06:34:58.482+0000] {processor.py:927} WARNING - No viable dags retrieved from /opt/airflow/dags/local_to_gcs.py
[2024-12-30T06:34:58.516+0000] {processor.py:208} INFO - Processing /opt/airflow/dags/local_to_gcs.py took 0.099 seconds
[2024-12-30T06:35:29.293+0000] {processor.py:186} INFO - Started process (PID=1694) to work on /opt/airflow/dags/local_to_gcs.py
[2024-12-30T06:35:29.296+0000] {processor.py:914} INFO - Processing file /opt/airflow/dags/local_to_gcs.py for tasks to queue
[2024-12-30T06:35:29.300+0000] {logging_mixin.py:190} INFO - [2024-12-30T06:35:29.299+0000] {dagbag.py:588} INFO - Filling up the DagBag from /opt/airflow/dags/local_to_gcs.py
[2024-12-30T06:35:29.382+0000] {logging_mixin.py:190} INFO - [2024-12-30T06:35:29.362+0000] {dagbag.py:387} ERROR - Failed to import: /opt/airflow/dags/local_to_gcs.py
Traceback (most recent call last):
  File "/home/airflow/.local/lib/python3.12/site-packages/airflow/models/dagbag.py", line 383, in parse
    loader.exec_module(new_module)
  File "<frozen importlib._bootstrap_external>", line 999, in exec_module
  File "<frozen importlib._bootstrap>", line 488, in _call_with_frames_removed
  File "/opt/airflow/dags/local_to_gcs.py", line 66, in <module>
    retail_dag = retail()  # Instantiate the DAG
                 ^^^^^^^^
  File "/home/airflow/.local/lib/python3.12/site-packages/airflow/models/dag.py", line 4307, in factory
    f(**f_kwargs)
  File "/opt/airflow/dags/local_to_gcs.py", line 31, in retail
    csv_files = [f for f in os.listdir(dataset_folder) if f.endswith(".csv")]
                            ^^^^^^^^^^^^^^^^^^^^^^^^^^
FileNotFoundError: [Errno 2] No such file or directory: 'include/dataset/'
[2024-12-30T06:35:29.386+0000] {processor.py:927} WARNING - No viable dags retrieved from /opt/airflow/dags/local_to_gcs.py
[2024-12-30T06:35:29.451+0000] {processor.py:208} INFO - Processing /opt/airflow/dags/local_to_gcs.py took 0.179 seconds
[2024-12-30T06:36:00.885+0000] {processor.py:186} INFO - Started process (PID=1761) to work on /opt/airflow/dags/local_to_gcs.py
[2024-12-30T06:36:00.891+0000] {processor.py:914} INFO - Processing file /opt/airflow/dags/local_to_gcs.py for tasks to queue
[2024-12-30T06:36:00.972+0000] {logging_mixin.py:190} INFO - [2024-12-30T06:36:00.969+0000] {dagbag.py:588} INFO - Filling up the DagBag from /opt/airflow/dags/local_to_gcs.py
[2024-12-30T06:36:01.145+0000] {logging_mixin.py:190} INFO - [2024-12-30T06:36:01.115+0000] {dagbag.py:387} ERROR - Failed to import: /opt/airflow/dags/local_to_gcs.py
Traceback (most recent call last):
  File "/home/airflow/.local/lib/python3.12/site-packages/airflow/models/dagbag.py", line 383, in parse
    loader.exec_module(new_module)
  File "<frozen importlib._bootstrap_external>", line 999, in exec_module
  File "<frozen importlib._bootstrap>", line 488, in _call_with_frames_removed
  File "/opt/airflow/dags/local_to_gcs.py", line 66, in <module>
    retail_dag = retail()  # Instantiate the DAG
                 ^^^^^^^^
  File "/home/airflow/.local/lib/python3.12/site-packages/airflow/models/dag.py", line 4307, in factory
    f(**f_kwargs)
  File "/opt/airflow/dags/local_to_gcs.py", line 31, in retail
    csv_files = [f for f in os.listdir(dataset_folder) if f.endswith(".csv")]
                            ^^^^^^^^^^^^^^^^^^^^^^^^^^
FileNotFoundError: [Errno 2] No such file or directory: 'include/dataset/'
[2024-12-30T06:36:01.149+0000] {processor.py:927} WARNING - No viable dags retrieved from /opt/airflow/dags/local_to_gcs.py
[2024-12-30T06:36:01.300+0000] {processor.py:208} INFO - Processing /opt/airflow/dags/local_to_gcs.py took 1.053 seconds
[2024-12-30T06:36:31.549+0000] {processor.py:186} INFO - Started process (PID=1827) to work on /opt/airflow/dags/local_to_gcs.py
[2024-12-30T06:36:31.551+0000] {processor.py:914} INFO - Processing file /opt/airflow/dags/local_to_gcs.py for tasks to queue
[2024-12-30T06:36:31.554+0000] {logging_mixin.py:190} INFO - [2024-12-30T06:36:31.552+0000] {dagbag.py:588} INFO - Filling up the DagBag from /opt/airflow/dags/local_to_gcs.py
[2024-12-30T06:36:31.599+0000] {logging_mixin.py:190} INFO - [2024-12-30T06:36:31.591+0000] {dagbag.py:387} ERROR - Failed to import: /opt/airflow/dags/local_to_gcs.py
Traceback (most recent call last):
  File "/home/airflow/.local/lib/python3.12/site-packages/airflow/models/dagbag.py", line 383, in parse
    loader.exec_module(new_module)
  File "<frozen importlib._bootstrap_external>", line 999, in exec_module
  File "<frozen importlib._bootstrap>", line 488, in _call_with_frames_removed
  File "/opt/airflow/dags/local_to_gcs.py", line 66, in <module>
    retail_dag = retail()  # Instantiate the DAG
                 ^^^^^^^^
  File "/home/airflow/.local/lib/python3.12/site-packages/airflow/models/dag.py", line 4307, in factory
    f(**f_kwargs)
  File "/opt/airflow/dags/local_to_gcs.py", line 31, in retail
    csv_files = [f for f in os.listdir(dataset_folder) if f.endswith(".csv")]
                            ^^^^^^^^^^^^^^^^^^^^^^^^^^
FileNotFoundError: [Errno 2] No such file or directory: 'include/dataset/'
[2024-12-30T06:36:31.602+0000] {processor.py:927} WARNING - No viable dags retrieved from /opt/airflow/dags/local_to_gcs.py
[2024-12-30T06:36:31.634+0000] {processor.py:208} INFO - Processing /opt/airflow/dags/local_to_gcs.py took 0.092 seconds
[2024-12-30T06:37:02.230+0000] {processor.py:186} INFO - Started process (PID=1892) to work on /opt/airflow/dags/local_to_gcs.py
[2024-12-30T06:37:02.232+0000] {processor.py:914} INFO - Processing file /opt/airflow/dags/local_to_gcs.py for tasks to queue
[2024-12-30T06:37:02.235+0000] {logging_mixin.py:190} INFO - [2024-12-30T06:37:02.234+0000] {dagbag.py:588} INFO - Filling up the DagBag from /opt/airflow/dags/local_to_gcs.py
[2024-12-30T06:37:02.276+0000] {logging_mixin.py:190} INFO - [2024-12-30T06:37:02.269+0000] {dagbag.py:387} ERROR - Failed to import: /opt/airflow/dags/local_to_gcs.py
Traceback (most recent call last):
  File "/home/airflow/.local/lib/python3.12/site-packages/airflow/models/dagbag.py", line 383, in parse
    loader.exec_module(new_module)
  File "<frozen importlib._bootstrap_external>", line 999, in exec_module
  File "<frozen importlib._bootstrap>", line 488, in _call_with_frames_removed
  File "/opt/airflow/dags/local_to_gcs.py", line 66, in <module>
    retail_dag = retail()  # Instantiate the DAG
                 ^^^^^^^^
  File "/home/airflow/.local/lib/python3.12/site-packages/airflow/models/dag.py", line 4307, in factory
    f(**f_kwargs)
  File "/opt/airflow/dags/local_to_gcs.py", line 31, in retail
    csv_files = [f for f in os.listdir(dataset_folder) if f.endswith(".csv")]
                            ^^^^^^^^^^^^^^^^^^^^^^^^^^
FileNotFoundError: [Errno 2] No such file or directory: 'include/dataset/'
[2024-12-30T06:37:02.279+0000] {processor.py:927} WARNING - No viable dags retrieved from /opt/airflow/dags/local_to_gcs.py
[2024-12-30T06:37:02.307+0000] {processor.py:208} INFO - Processing /opt/airflow/dags/local_to_gcs.py took 0.086 seconds
[2024-12-30T06:37:32.643+0000] {processor.py:186} INFO - Started process (PID=1958) to work on /opt/airflow/dags/local_to_gcs.py
[2024-12-30T06:37:32.646+0000] {processor.py:914} INFO - Processing file /opt/airflow/dags/local_to_gcs.py for tasks to queue
[2024-12-30T06:37:32.649+0000] {logging_mixin.py:190} INFO - [2024-12-30T06:37:32.649+0000] {dagbag.py:588} INFO - Filling up the DagBag from /opt/airflow/dags/local_to_gcs.py
[2024-12-30T06:37:32.694+0000] {logging_mixin.py:190} INFO - [2024-12-30T06:37:32.686+0000] {dagbag.py:387} ERROR - Failed to import: /opt/airflow/dags/local_to_gcs.py
Traceback (most recent call last):
  File "/home/airflow/.local/lib/python3.12/site-packages/airflow/models/dagbag.py", line 383, in parse
    loader.exec_module(new_module)
  File "<frozen importlib._bootstrap_external>", line 999, in exec_module
  File "<frozen importlib._bootstrap>", line 488, in _call_with_frames_removed
  File "/opt/airflow/dags/local_to_gcs.py", line 66, in <module>
    retail_dag = retail()  # Instantiate the DAG
                 ^^^^^^^^
  File "/home/airflow/.local/lib/python3.12/site-packages/airflow/models/dag.py", line 4307, in factory
    f(**f_kwargs)
  File "/opt/airflow/dags/local_to_gcs.py", line 31, in retail
    csv_files = [f for f in os.listdir(dataset_folder) if f.endswith(".csv")]
                            ^^^^^^^^^^^^^^^^^^^^^^^^^^
FileNotFoundError: [Errno 2] No such file or directory: 'include/dataset/'
[2024-12-30T06:37:32.696+0000] {processor.py:927} WARNING - No viable dags retrieved from /opt/airflow/dags/local_to_gcs.py
[2024-12-30T06:37:32.733+0000] {processor.py:208} INFO - Processing /opt/airflow/dags/local_to_gcs.py took 0.100 seconds
[2024-12-30T06:38:02.935+0000] {processor.py:186} INFO - Started process (PID=2024) to work on /opt/airflow/dags/local_to_gcs.py
[2024-12-30T06:38:02.936+0000] {processor.py:914} INFO - Processing file /opt/airflow/dags/local_to_gcs.py for tasks to queue
[2024-12-30T06:38:02.944+0000] {logging_mixin.py:190} INFO - [2024-12-30T06:38:02.944+0000] {dagbag.py:588} INFO - Filling up the DagBag from /opt/airflow/dags/local_to_gcs.py
[2024-12-30T06:38:02.983+0000] {logging_mixin.py:190} INFO - [2024-12-30T06:38:02.976+0000] {dagbag.py:387} ERROR - Failed to import: /opt/airflow/dags/local_to_gcs.py
Traceback (most recent call last):
  File "/home/airflow/.local/lib/python3.12/site-packages/airflow/models/dagbag.py", line 383, in parse
    loader.exec_module(new_module)
  File "<frozen importlib._bootstrap_external>", line 999, in exec_module
  File "<frozen importlib._bootstrap>", line 488, in _call_with_frames_removed
  File "/opt/airflow/dags/local_to_gcs.py", line 66, in <module>
    retail_dag = retail()  # Instantiate the DAG
                 ^^^^^^^^
  File "/home/airflow/.local/lib/python3.12/site-packages/airflow/models/dag.py", line 4307, in factory
    f(**f_kwargs)
  File "/opt/airflow/dags/local_to_gcs.py", line 31, in retail
    csv_files = [f for f in os.listdir(dataset_folder) if f.endswith(".csv")]
                            ^^^^^^^^^^^^^^^^^^^^^^^^^^
FileNotFoundError: [Errno 2] No such file or directory: 'include/dataset/'
[2024-12-30T06:38:02.985+0000] {processor.py:927} WARNING - No viable dags retrieved from /opt/airflow/dags/local_to_gcs.py
[2024-12-30T06:38:03.018+0000] {processor.py:208} INFO - Processing /opt/airflow/dags/local_to_gcs.py took 0.092 seconds
[2024-12-30T06:38:33.089+0000] {processor.py:186} INFO - Started process (PID=2090) to work on /opt/airflow/dags/local_to_gcs.py
[2024-12-30T06:38:33.091+0000] {processor.py:914} INFO - Processing file /opt/airflow/dags/local_to_gcs.py for tasks to queue
[2024-12-30T06:38:33.093+0000] {logging_mixin.py:190} INFO - [2024-12-30T06:38:33.093+0000] {dagbag.py:588} INFO - Filling up the DagBag from /opt/airflow/dags/local_to_gcs.py
[2024-12-30T06:38:33.132+0000] {logging_mixin.py:190} INFO - [2024-12-30T06:38:33.124+0000] {dagbag.py:387} ERROR - Failed to import: /opt/airflow/dags/local_to_gcs.py
Traceback (most recent call last):
  File "/home/airflow/.local/lib/python3.12/site-packages/airflow/models/dagbag.py", line 383, in parse
    loader.exec_module(new_module)
  File "<frozen importlib._bootstrap_external>", line 999, in exec_module
  File "<frozen importlib._bootstrap>", line 488, in _call_with_frames_removed
  File "/opt/airflow/dags/local_to_gcs.py", line 66, in <module>
    retail_dag = retail()  # Instantiate the DAG
                 ^^^^^^^^
  File "/home/airflow/.local/lib/python3.12/site-packages/airflow/models/dag.py", line 4307, in factory
    f(**f_kwargs)
  File "/opt/airflow/dags/local_to_gcs.py", line 31, in retail
    csv_files = [f for f in os.listdir(dataset_folder) if f.endswith(".csv")]
                            ^^^^^^^^^^^^^^^^^^^^^^^^^^
FileNotFoundError: [Errno 2] No such file or directory: 'include/dataset/'
[2024-12-30T06:38:33.136+0000] {processor.py:927} WARNING - No viable dags retrieved from /opt/airflow/dags/local_to_gcs.py
[2024-12-30T06:38:33.173+0000] {processor.py:208} INFO - Processing /opt/airflow/dags/local_to_gcs.py took 0.093 seconds
[2024-12-30T06:39:03.520+0000] {processor.py:186} INFO - Started process (PID=2156) to work on /opt/airflow/dags/local_to_gcs.py
[2024-12-30T06:39:03.522+0000] {processor.py:914} INFO - Processing file /opt/airflow/dags/local_to_gcs.py for tasks to queue
[2024-12-30T06:39:03.524+0000] {logging_mixin.py:190} INFO - [2024-12-30T06:39:03.524+0000] {dagbag.py:588} INFO - Filling up the DagBag from /opt/airflow/dags/local_to_gcs.py
[2024-12-30T06:39:03.578+0000] {logging_mixin.py:190} INFO - [2024-12-30T06:39:03.566+0000] {dagbag.py:387} ERROR - Failed to import: /opt/airflow/dags/local_to_gcs.py
Traceback (most recent call last):
  File "/home/airflow/.local/lib/python3.12/site-packages/airflow/models/dagbag.py", line 383, in parse
    loader.exec_module(new_module)
  File "<frozen importlib._bootstrap_external>", line 999, in exec_module
  File "<frozen importlib._bootstrap>", line 488, in _call_with_frames_removed
  File "/opt/airflow/dags/local_to_gcs.py", line 66, in <module>
    retail_dag = retail()  # Instantiate the DAG
                 ^^^^^^^^
  File "/home/airflow/.local/lib/python3.12/site-packages/airflow/models/dag.py", line 4307, in factory
    f(**f_kwargs)
  File "/opt/airflow/dags/local_to_gcs.py", line 31, in retail
    csv_files = [f for f in os.listdir(dataset_folder) if f.endswith(".csv")]
                            ^^^^^^^^^^^^^^^^^^^^^^^^^^
FileNotFoundError: [Errno 2] No such file or directory: 'include/dataset/'
[2024-12-30T06:39:03.582+0000] {processor.py:927} WARNING - No viable dags retrieved from /opt/airflow/dags/local_to_gcs.py
[2024-12-30T06:39:03.621+0000] {processor.py:208} INFO - Processing /opt/airflow/dags/local_to_gcs.py took 0.111 seconds
[2024-12-30T06:39:33.893+0000] {processor.py:186} INFO - Started process (PID=2222) to work on /opt/airflow/dags/local_to_gcs.py
[2024-12-30T06:39:33.896+0000] {processor.py:914} INFO - Processing file /opt/airflow/dags/local_to_gcs.py for tasks to queue
[2024-12-30T06:39:33.900+0000] {logging_mixin.py:190} INFO - [2024-12-30T06:39:33.899+0000] {dagbag.py:588} INFO - Filling up the DagBag from /opt/airflow/dags/local_to_gcs.py
[2024-12-30T06:39:33.956+0000] {logging_mixin.py:190} INFO - [2024-12-30T06:39:33.948+0000] {dagbag.py:387} ERROR - Failed to import: /opt/airflow/dags/local_to_gcs.py
Traceback (most recent call last):
  File "/home/airflow/.local/lib/python3.12/site-packages/airflow/models/dagbag.py", line 383, in parse
    loader.exec_module(new_module)
  File "<frozen importlib._bootstrap_external>", line 999, in exec_module
  File "<frozen importlib._bootstrap>", line 488, in _call_with_frames_removed
  File "/opt/airflow/dags/local_to_gcs.py", line 66, in <module>
    retail_dag = retail()  # Instantiate the DAG
                 ^^^^^^^^
  File "/home/airflow/.local/lib/python3.12/site-packages/airflow/models/dag.py", line 4307, in factory
    f(**f_kwargs)
  File "/opt/airflow/dags/local_to_gcs.py", line 31, in retail
    csv_files = [f for f in os.listdir(dataset_folder) if f.endswith(".csv")]
                            ^^^^^^^^^^^^^^^^^^^^^^^^^^
FileNotFoundError: [Errno 2] No such file or directory: 'include/dataset/'
[2024-12-30T06:39:33.959+0000] {processor.py:927} WARNING - No viable dags retrieved from /opt/airflow/dags/local_to_gcs.py
[2024-12-30T06:39:33.998+0000] {processor.py:208} INFO - Processing /opt/airflow/dags/local_to_gcs.py took 0.120 seconds
[2024-12-30T06:40:04.446+0000] {processor.py:186} INFO - Started process (PID=2288) to work on /opt/airflow/dags/local_to_gcs.py
[2024-12-30T06:40:04.448+0000] {processor.py:914} INFO - Processing file /opt/airflow/dags/local_to_gcs.py for tasks to queue
[2024-12-30T06:40:04.451+0000] {logging_mixin.py:190} INFO - [2024-12-30T06:40:04.450+0000] {dagbag.py:588} INFO - Filling up the DagBag from /opt/airflow/dags/local_to_gcs.py
[2024-12-30T06:40:04.511+0000] {logging_mixin.py:190} INFO - [2024-12-30T06:40:04.493+0000] {dagbag.py:387} ERROR - Failed to import: /opt/airflow/dags/local_to_gcs.py
Traceback (most recent call last):
  File "/home/airflow/.local/lib/python3.12/site-packages/airflow/models/dagbag.py", line 383, in parse
    loader.exec_module(new_module)
  File "<frozen importlib._bootstrap_external>", line 999, in exec_module
  File "<frozen importlib._bootstrap>", line 488, in _call_with_frames_removed
  File "/opt/airflow/dags/local_to_gcs.py", line 66, in <module>
    retail_dag = retail()  # Instantiate the DAG
                 ^^^^^^^^
  File "/home/airflow/.local/lib/python3.12/site-packages/airflow/models/dag.py", line 4307, in factory
    f(**f_kwargs)
  File "/opt/airflow/dags/local_to_gcs.py", line 31, in retail
    csv_files = [f for f in os.listdir(dataset_folder) if f.endswith(".csv")]
                            ^^^^^^^^^^^^^^^^^^^^^^^^^^
FileNotFoundError: [Errno 2] No such file or directory: 'include/dataset/'
[2024-12-30T06:40:04.515+0000] {processor.py:927} WARNING - No viable dags retrieved from /opt/airflow/dags/local_to_gcs.py
[2024-12-30T06:40:04.572+0000] {processor.py:208} INFO - Processing /opt/airflow/dags/local_to_gcs.py took 0.135 seconds
[2024-12-30T06:40:34.746+0000] {processor.py:186} INFO - Started process (PID=2354) to work on /opt/airflow/dags/local_to_gcs.py
[2024-12-30T06:40:34.748+0000] {processor.py:914} INFO - Processing file /opt/airflow/dags/local_to_gcs.py for tasks to queue
[2024-12-30T06:40:34.752+0000] {logging_mixin.py:190} INFO - [2024-12-30T06:40:34.751+0000] {dagbag.py:588} INFO - Filling up the DagBag from /opt/airflow/dags/local_to_gcs.py
[2024-12-30T06:40:34.789+0000] {logging_mixin.py:190} INFO - [2024-12-30T06:40:34.782+0000] {dagbag.py:387} ERROR - Failed to import: /opt/airflow/dags/local_to_gcs.py
Traceback (most recent call last):
  File "/home/airflow/.local/lib/python3.12/site-packages/airflow/models/dagbag.py", line 383, in parse
    loader.exec_module(new_module)
  File "<frozen importlib._bootstrap_external>", line 999, in exec_module
  File "<frozen importlib._bootstrap>", line 488, in _call_with_frames_removed
  File "/opt/airflow/dags/local_to_gcs.py", line 66, in <module>
    retail_dag = retail()  # Instantiate the DAG
                 ^^^^^^^^
  File "/home/airflow/.local/lib/python3.12/site-packages/airflow/models/dag.py", line 4307, in factory
    f(**f_kwargs)
  File "/opt/airflow/dags/local_to_gcs.py", line 31, in retail
    csv_files = [f for f in os.listdir(dataset_folder) if f.endswith(".csv")]
                            ^^^^^^^^^^^^^^^^^^^^^^^^^^
FileNotFoundError: [Errno 2] No such file or directory: 'include/dataset/'
[2024-12-30T06:40:34.790+0000] {processor.py:927} WARNING - No viable dags retrieved from /opt/airflow/dags/local_to_gcs.py
[2024-12-30T06:40:34.819+0000] {processor.py:208} INFO - Processing /opt/airflow/dags/local_to_gcs.py took 0.087 seconds
[2024-12-30T06:41:05.557+0000] {processor.py:186} INFO - Started process (PID=2420) to work on /opt/airflow/dags/local_to_gcs.py
[2024-12-30T06:41:05.560+0000] {processor.py:914} INFO - Processing file /opt/airflow/dags/local_to_gcs.py for tasks to queue
[2024-12-30T06:41:05.563+0000] {logging_mixin.py:190} INFO - [2024-12-30T06:41:05.562+0000] {dagbag.py:588} INFO - Filling up the DagBag from /opt/airflow/dags/local_to_gcs.py
[2024-12-30T06:41:05.605+0000] {logging_mixin.py:190} INFO - [2024-12-30T06:41:05.598+0000] {dagbag.py:387} ERROR - Failed to import: /opt/airflow/dags/local_to_gcs.py
Traceback (most recent call last):
  File "/home/airflow/.local/lib/python3.12/site-packages/airflow/models/dagbag.py", line 383, in parse
    loader.exec_module(new_module)
  File "<frozen importlib._bootstrap_external>", line 999, in exec_module
  File "<frozen importlib._bootstrap>", line 488, in _call_with_frames_removed
  File "/opt/airflow/dags/local_to_gcs.py", line 66, in <module>
    retail_dag = retail()  # Instantiate the DAG
                 ^^^^^^^^
  File "/home/airflow/.local/lib/python3.12/site-packages/airflow/models/dag.py", line 4307, in factory
    f(**f_kwargs)
  File "/opt/airflow/dags/local_to_gcs.py", line 31, in retail
    csv_files = [f for f in os.listdir(dataset_folder) if f.endswith(".csv")]
                            ^^^^^^^^^^^^^^^^^^^^^^^^^^
FileNotFoundError: [Errno 2] No such file or directory: 'include/dataset/'
[2024-12-30T06:41:05.609+0000] {processor.py:927} WARNING - No viable dags retrieved from /opt/airflow/dags/local_to_gcs.py
[2024-12-30T06:41:05.658+0000] {processor.py:208} INFO - Processing /opt/airflow/dags/local_to_gcs.py took 0.109 seconds
[2024-12-30T06:41:36.183+0000] {processor.py:186} INFO - Started process (PID=2486) to work on /opt/airflow/dags/local_to_gcs.py
[2024-12-30T06:41:36.185+0000] {processor.py:914} INFO - Processing file /opt/airflow/dags/local_to_gcs.py for tasks to queue
[2024-12-30T06:41:36.188+0000] {logging_mixin.py:190} INFO - [2024-12-30T06:41:36.187+0000] {dagbag.py:588} INFO - Filling up the DagBag from /opt/airflow/dags/local_to_gcs.py
[2024-12-30T06:41:36.224+0000] {logging_mixin.py:190} INFO - [2024-12-30T06:41:36.217+0000] {dagbag.py:387} ERROR - Failed to import: /opt/airflow/dags/local_to_gcs.py
Traceback (most recent call last):
  File "/home/airflow/.local/lib/python3.12/site-packages/airflow/models/dagbag.py", line 383, in parse
    loader.exec_module(new_module)
  File "<frozen importlib._bootstrap_external>", line 999, in exec_module
  File "<frozen importlib._bootstrap>", line 488, in _call_with_frames_removed
  File "/opt/airflow/dags/local_to_gcs.py", line 66, in <module>
    retail_dag = retail()  # Instantiate the DAG
                 ^^^^^^^^
  File "/home/airflow/.local/lib/python3.12/site-packages/airflow/models/dag.py", line 4307, in factory
    f(**f_kwargs)
  File "/opt/airflow/dags/local_to_gcs.py", line 31, in retail
    csv_files = [f for f in os.listdir(dataset_folder) if f.endswith(".csv")]
                            ^^^^^^^^^^^^^^^^^^^^^^^^^^
FileNotFoundError: [Errno 2] No such file or directory: 'include/dataset/'
[2024-12-30T06:41:36.226+0000] {processor.py:927} WARNING - No viable dags retrieved from /opt/airflow/dags/local_to_gcs.py
[2024-12-30T06:41:36.252+0000] {processor.py:208} INFO - Processing /opt/airflow/dags/local_to_gcs.py took 0.077 seconds
[2024-12-30T06:42:06.991+0000] {processor.py:186} INFO - Started process (PID=2552) to work on /opt/airflow/dags/local_to_gcs.py
[2024-12-30T06:42:06.993+0000] {processor.py:914} INFO - Processing file /opt/airflow/dags/local_to_gcs.py for tasks to queue
[2024-12-30T06:42:06.997+0000] {logging_mixin.py:190} INFO - [2024-12-30T06:42:06.996+0000] {dagbag.py:588} INFO - Filling up the DagBag from /opt/airflow/dags/local_to_gcs.py
[2024-12-30T06:42:07.048+0000] {logging_mixin.py:190} INFO - [2024-12-30T06:42:07.037+0000] {dagbag.py:387} ERROR - Failed to import: /opt/airflow/dags/local_to_gcs.py
Traceback (most recent call last):
  File "/home/airflow/.local/lib/python3.12/site-packages/airflow/models/dagbag.py", line 383, in parse
    loader.exec_module(new_module)
  File "<frozen importlib._bootstrap_external>", line 999, in exec_module
  File "<frozen importlib._bootstrap>", line 488, in _call_with_frames_removed
  File "/opt/airflow/dags/local_to_gcs.py", line 66, in <module>
    retail_dag = retail()  # Instantiate the DAG
                 ^^^^^^^^
  File "/home/airflow/.local/lib/python3.12/site-packages/airflow/models/dag.py", line 4307, in factory
    f(**f_kwargs)
  File "/opt/airflow/dags/local_to_gcs.py", line 31, in retail
    csv_files = [f for f in os.listdir(dataset_folder) if f.endswith(".csv")]
                            ^^^^^^^^^^^^^^^^^^^^^^^^^^
FileNotFoundError: [Errno 2] No such file or directory: 'include/dataset/'
[2024-12-30T06:42:07.053+0000] {processor.py:927} WARNING - No viable dags retrieved from /opt/airflow/dags/local_to_gcs.py
[2024-12-30T06:42:07.099+0000] {processor.py:208} INFO - Processing /opt/airflow/dags/local_to_gcs.py took 0.120 seconds
[2024-12-30T06:42:37.872+0000] {processor.py:186} INFO - Started process (PID=2618) to work on /opt/airflow/dags/local_to_gcs.py
[2024-12-30T06:42:37.874+0000] {processor.py:914} INFO - Processing file /opt/airflow/dags/local_to_gcs.py for tasks to queue
[2024-12-30T06:42:37.878+0000] {logging_mixin.py:190} INFO - [2024-12-30T06:42:37.876+0000] {dagbag.py:588} INFO - Filling up the DagBag from /opt/airflow/dags/local_to_gcs.py
[2024-12-30T06:42:37.924+0000] {logging_mixin.py:190} INFO - [2024-12-30T06:42:37.916+0000] {dagbag.py:387} ERROR - Failed to import: /opt/airflow/dags/local_to_gcs.py
Traceback (most recent call last):
  File "/home/airflow/.local/lib/python3.12/site-packages/airflow/models/dagbag.py", line 383, in parse
    loader.exec_module(new_module)
  File "<frozen importlib._bootstrap_external>", line 999, in exec_module
  File "<frozen importlib._bootstrap>", line 488, in _call_with_frames_removed
  File "/opt/airflow/dags/local_to_gcs.py", line 66, in <module>
    retail_dag = retail()  # Instantiate the DAG
                 ^^^^^^^^
  File "/home/airflow/.local/lib/python3.12/site-packages/airflow/models/dag.py", line 4307, in factory
    f(**f_kwargs)
  File "/opt/airflow/dags/local_to_gcs.py", line 31, in retail
    csv_files = [f for f in os.listdir(dataset_folder) if f.endswith(".csv")]
                            ^^^^^^^^^^^^^^^^^^^^^^^^^^
FileNotFoundError: [Errno 2] No such file or directory: 'include/dataset/'
[2024-12-30T06:42:37.926+0000] {processor.py:927} WARNING - No viable dags retrieved from /opt/airflow/dags/local_to_gcs.py
[2024-12-30T06:42:37.962+0000] {processor.py:208} INFO - Processing /opt/airflow/dags/local_to_gcs.py took 0.101 seconds
[2024-12-30T06:43:08.588+0000] {processor.py:186} INFO - Started process (PID=2684) to work on /opt/airflow/dags/local_to_gcs.py
[2024-12-30T06:43:08.589+0000] {processor.py:914} INFO - Processing file /opt/airflow/dags/local_to_gcs.py for tasks to queue
[2024-12-30T06:43:08.591+0000] {logging_mixin.py:190} INFO - [2024-12-30T06:43:08.590+0000] {dagbag.py:588} INFO - Filling up the DagBag from /opt/airflow/dags/local_to_gcs.py
[2024-12-30T06:43:08.627+0000] {logging_mixin.py:190} INFO - [2024-12-30T06:43:08.621+0000] {dagbag.py:387} ERROR - Failed to import: /opt/airflow/dags/local_to_gcs.py
Traceback (most recent call last):
  File "/home/airflow/.local/lib/python3.12/site-packages/airflow/models/dagbag.py", line 383, in parse
    loader.exec_module(new_module)
  File "<frozen importlib._bootstrap_external>", line 999, in exec_module
  File "<frozen importlib._bootstrap>", line 488, in _call_with_frames_removed
  File "/opt/airflow/dags/local_to_gcs.py", line 66, in <module>
    retail_dag = retail()  # Instantiate the DAG
                 ^^^^^^^^
  File "/home/airflow/.local/lib/python3.12/site-packages/airflow/models/dag.py", line 4307, in factory
    f(**f_kwargs)
  File "/opt/airflow/dags/local_to_gcs.py", line 31, in retail
    csv_files = [f for f in os.listdir(dataset_folder) if f.endswith(".csv")]
                            ^^^^^^^^^^^^^^^^^^^^^^^^^^
FileNotFoundError: [Errno 2] No such file or directory: 'include/dataset/'
[2024-12-30T06:43:08.629+0000] {processor.py:927} WARNING - No viable dags retrieved from /opt/airflow/dags/local_to_gcs.py
[2024-12-30T06:43:08.659+0000] {processor.py:208} INFO - Processing /opt/airflow/dags/local_to_gcs.py took 0.079 seconds
[2024-12-30T06:43:39.126+0000] {processor.py:186} INFO - Started process (PID=2750) to work on /opt/airflow/dags/local_to_gcs.py
[2024-12-30T06:43:39.128+0000] {processor.py:914} INFO - Processing file /opt/airflow/dags/local_to_gcs.py for tasks to queue
[2024-12-30T06:43:39.130+0000] {logging_mixin.py:190} INFO - [2024-12-30T06:43:39.130+0000] {dagbag.py:588} INFO - Filling up the DagBag from /opt/airflow/dags/local_to_gcs.py
[2024-12-30T06:43:39.177+0000] {logging_mixin.py:190} INFO - [2024-12-30T06:43:39.170+0000] {dagbag.py:387} ERROR - Failed to import: /opt/airflow/dags/local_to_gcs.py
Traceback (most recent call last):
  File "/home/airflow/.local/lib/python3.12/site-packages/airflow/models/dagbag.py", line 383, in parse
    loader.exec_module(new_module)
  File "<frozen importlib._bootstrap_external>", line 999, in exec_module
  File "<frozen importlib._bootstrap>", line 488, in _call_with_frames_removed
  File "/opt/airflow/dags/local_to_gcs.py", line 66, in <module>
    retail_dag = retail()  # Instantiate the DAG
                 ^^^^^^^^
  File "/home/airflow/.local/lib/python3.12/site-packages/airflow/models/dag.py", line 4307, in factory
    f(**f_kwargs)
  File "/opt/airflow/dags/local_to_gcs.py", line 31, in retail
    csv_files = [f for f in os.listdir(dataset_folder) if f.endswith(".csv")]
                            ^^^^^^^^^^^^^^^^^^^^^^^^^^
FileNotFoundError: [Errno 2] No such file or directory: 'include/dataset/'
[2024-12-30T06:43:39.179+0000] {processor.py:927} WARNING - No viable dags retrieved from /opt/airflow/dags/local_to_gcs.py
[2024-12-30T06:43:39.208+0000] {processor.py:208} INFO - Processing /opt/airflow/dags/local_to_gcs.py took 0.091 seconds
[2024-12-30T06:44:09.684+0000] {processor.py:186} INFO - Started process (PID=2816) to work on /opt/airflow/dags/local_to_gcs.py
[2024-12-30T06:44:09.686+0000] {processor.py:914} INFO - Processing file /opt/airflow/dags/local_to_gcs.py for tasks to queue
[2024-12-30T06:44:09.687+0000] {logging_mixin.py:190} INFO - [2024-12-30T06:44:09.687+0000] {dagbag.py:588} INFO - Filling up the DagBag from /opt/airflow/dags/local_to_gcs.py
[2024-12-30T06:44:09.721+0000] {logging_mixin.py:190} INFO - [2024-12-30T06:44:09.715+0000] {dagbag.py:387} ERROR - Failed to import: /opt/airflow/dags/local_to_gcs.py
Traceback (most recent call last):
  File "/home/airflow/.local/lib/python3.12/site-packages/airflow/models/dagbag.py", line 383, in parse
    loader.exec_module(new_module)
  File "<frozen importlib._bootstrap_external>", line 999, in exec_module
  File "<frozen importlib._bootstrap>", line 488, in _call_with_frames_removed
  File "/opt/airflow/dags/local_to_gcs.py", line 66, in <module>
    retail_dag = retail()  # Instantiate the DAG
                 ^^^^^^^^
  File "/home/airflow/.local/lib/python3.12/site-packages/airflow/models/dag.py", line 4307, in factory
    f(**f_kwargs)
  File "/opt/airflow/dags/local_to_gcs.py", line 31, in retail
    csv_files = [f for f in os.listdir(dataset_folder) if f.endswith(".csv")]
                            ^^^^^^^^^^^^^^^^^^^^^^^^^^
FileNotFoundError: [Errno 2] No such file or directory: 'include/dataset/'
[2024-12-30T06:44:09.723+0000] {processor.py:927} WARNING - No viable dags retrieved from /opt/airflow/dags/local_to_gcs.py
[2024-12-30T06:44:09.754+0000] {processor.py:208} INFO - Processing /opt/airflow/dags/local_to_gcs.py took 0.078 seconds
[2024-12-30T06:44:40.467+0000] {processor.py:186} INFO - Started process (PID=2882) to work on /opt/airflow/dags/local_to_gcs.py
[2024-12-30T06:44:40.469+0000] {processor.py:914} INFO - Processing file /opt/airflow/dags/local_to_gcs.py for tasks to queue
[2024-12-30T06:44:40.472+0000] {logging_mixin.py:190} INFO - [2024-12-30T06:44:40.472+0000] {dagbag.py:588} INFO - Filling up the DagBag from /opt/airflow/dags/local_to_gcs.py
[2024-12-30T06:44:40.515+0000] {logging_mixin.py:190} INFO - [2024-12-30T06:44:40.506+0000] {dagbag.py:387} ERROR - Failed to import: /opt/airflow/dags/local_to_gcs.py
Traceback (most recent call last):
  File "/home/airflow/.local/lib/python3.12/site-packages/airflow/models/dagbag.py", line 383, in parse
    loader.exec_module(new_module)
  File "<frozen importlib._bootstrap_external>", line 999, in exec_module
  File "<frozen importlib._bootstrap>", line 488, in _call_with_frames_removed
  File "/opt/airflow/dags/local_to_gcs.py", line 66, in <module>
    retail_dag = retail()  # Instantiate the DAG
                 ^^^^^^^^
  File "/home/airflow/.local/lib/python3.12/site-packages/airflow/models/dag.py", line 4307, in factory
    f(**f_kwargs)
  File "/opt/airflow/dags/local_to_gcs.py", line 31, in retail
    csv_files = [f for f in os.listdir(dataset_folder) if f.endswith(".csv")]
                            ^^^^^^^^^^^^^^^^^^^^^^^^^^
FileNotFoundError: [Errno 2] No such file or directory: 'include/dataset/'
[2024-12-30T06:44:40.517+0000] {processor.py:927} WARNING - No viable dags retrieved from /opt/airflow/dags/local_to_gcs.py
[2024-12-30T06:44:40.547+0000] {processor.py:208} INFO - Processing /opt/airflow/dags/local_to_gcs.py took 0.090 seconds
[2024-12-30T06:45:11.246+0000] {processor.py:186} INFO - Started process (PID=2948) to work on /opt/airflow/dags/local_to_gcs.py
[2024-12-30T06:45:11.248+0000] {processor.py:914} INFO - Processing file /opt/airflow/dags/local_to_gcs.py for tasks to queue
[2024-12-30T06:45:11.250+0000] {logging_mixin.py:190} INFO - [2024-12-30T06:45:11.250+0000] {dagbag.py:588} INFO - Filling up the DagBag from /opt/airflow/dags/local_to_gcs.py
[2024-12-30T06:45:11.298+0000] {logging_mixin.py:190} INFO - [2024-12-30T06:45:11.291+0000] {dagbag.py:387} ERROR - Failed to import: /opt/airflow/dags/local_to_gcs.py
Traceback (most recent call last):
  File "/home/airflow/.local/lib/python3.12/site-packages/airflow/models/dagbag.py", line 383, in parse
    loader.exec_module(new_module)
  File "<frozen importlib._bootstrap_external>", line 999, in exec_module
  File "<frozen importlib._bootstrap>", line 488, in _call_with_frames_removed
  File "/opt/airflow/dags/local_to_gcs.py", line 66, in <module>
    retail_dag = retail()  # Instantiate the DAG
                 ^^^^^^^^
  File "/home/airflow/.local/lib/python3.12/site-packages/airflow/models/dag.py", line 4307, in factory
    f(**f_kwargs)
  File "/opt/airflow/dags/local_to_gcs.py", line 31, in retail
    csv_files = [f for f in os.listdir(dataset_folder) if f.endswith(".csv")]
                            ^^^^^^^^^^^^^^^^^^^^^^^^^^
FileNotFoundError: [Errno 2] No such file or directory: 'include/dataset/'
[2024-12-30T06:45:11.300+0000] {processor.py:927} WARNING - No viable dags retrieved from /opt/airflow/dags/local_to_gcs.py
[2024-12-30T06:45:11.331+0000] {processor.py:208} INFO - Processing /opt/airflow/dags/local_to_gcs.py took 0.093 seconds
[2024-12-30T06:45:41.502+0000] {processor.py:186} INFO - Started process (PID=3014) to work on /opt/airflow/dags/local_to_gcs.py
[2024-12-30T06:45:41.504+0000] {processor.py:914} INFO - Processing file /opt/airflow/dags/local_to_gcs.py for tasks to queue
[2024-12-30T06:45:41.509+0000] {logging_mixin.py:190} INFO - [2024-12-30T06:45:41.509+0000] {dagbag.py:588} INFO - Filling up the DagBag from /opt/airflow/dags/local_to_gcs.py
[2024-12-30T06:45:41.551+0000] {logging_mixin.py:190} INFO - [2024-12-30T06:45:41.545+0000] {dagbag.py:387} ERROR - Failed to import: /opt/airflow/dags/local_to_gcs.py
Traceback (most recent call last):
  File "/home/airflow/.local/lib/python3.12/site-packages/airflow/models/dagbag.py", line 383, in parse
    loader.exec_module(new_module)
  File "<frozen importlib._bootstrap_external>", line 999, in exec_module
  File "<frozen importlib._bootstrap>", line 488, in _call_with_frames_removed
  File "/opt/airflow/dags/local_to_gcs.py", line 66, in <module>
    retail_dag = retail()  # Instantiate the DAG
                 ^^^^^^^^
  File "/home/airflow/.local/lib/python3.12/site-packages/airflow/models/dag.py", line 4307, in factory
    f(**f_kwargs)
  File "/opt/airflow/dags/local_to_gcs.py", line 31, in retail
    csv_files = [f for f in os.listdir(dataset_folder) if f.endswith(".csv")]
                            ^^^^^^^^^^^^^^^^^^^^^^^^^^
FileNotFoundError: [Errno 2] No such file or directory: 'include/dataset/'
[2024-12-30T06:45:41.554+0000] {processor.py:927} WARNING - No viable dags retrieved from /opt/airflow/dags/local_to_gcs.py
[2024-12-30T06:45:41.591+0000] {processor.py:208} INFO - Processing /opt/airflow/dags/local_to_gcs.py took 0.097 seconds
[2024-12-30T06:46:12.411+0000] {processor.py:186} INFO - Started process (PID=3080) to work on /opt/airflow/dags/local_to_gcs.py
[2024-12-30T06:46:12.414+0000] {processor.py:914} INFO - Processing file /opt/airflow/dags/local_to_gcs.py for tasks to queue
[2024-12-30T06:46:12.416+0000] {logging_mixin.py:190} INFO - [2024-12-30T06:46:12.416+0000] {dagbag.py:588} INFO - Filling up the DagBag from /opt/airflow/dags/local_to_gcs.py
[2024-12-30T06:46:12.460+0000] {logging_mixin.py:190} INFO - [2024-12-30T06:46:12.450+0000] {dagbag.py:387} ERROR - Failed to import: /opt/airflow/dags/local_to_gcs.py
Traceback (most recent call last):
  File "/home/airflow/.local/lib/python3.12/site-packages/airflow/models/dagbag.py", line 383, in parse
    loader.exec_module(new_module)
  File "<frozen importlib._bootstrap_external>", line 999, in exec_module
  File "<frozen importlib._bootstrap>", line 488, in _call_with_frames_removed
  File "/opt/airflow/dags/local_to_gcs.py", line 66, in <module>
    retail_dag = retail()  # Instantiate the DAG
                 ^^^^^^^^
  File "/home/airflow/.local/lib/python3.12/site-packages/airflow/models/dag.py", line 4307, in factory
    f(**f_kwargs)
  File "/opt/airflow/dags/local_to_gcs.py", line 31, in retail
    csv_files = [f for f in os.listdir(dataset_folder) if f.endswith(".csv")]
                            ^^^^^^^^^^^^^^^^^^^^^^^^^^
FileNotFoundError: [Errno 2] No such file or directory: 'include/dataset/'
[2024-12-30T06:46:12.464+0000] {processor.py:927} WARNING - No viable dags retrieved from /opt/airflow/dags/local_to_gcs.py
[2024-12-30T06:46:12.502+0000] {processor.py:208} INFO - Processing /opt/airflow/dags/local_to_gcs.py took 0.100 seconds
[2024-12-30T06:46:42.620+0000] {processor.py:186} INFO - Started process (PID=3145) to work on /opt/airflow/dags/local_to_gcs.py
[2024-12-30T06:46:42.621+0000] {processor.py:914} INFO - Processing file /opt/airflow/dags/local_to_gcs.py for tasks to queue
[2024-12-30T06:46:42.623+0000] {logging_mixin.py:190} INFO - [2024-12-30T06:46:42.622+0000] {dagbag.py:588} INFO - Filling up the DagBag from /opt/airflow/dags/local_to_gcs.py
[2024-12-30T06:46:42.659+0000] {logging_mixin.py:190} INFO - [2024-12-30T06:46:42.653+0000] {dagbag.py:387} ERROR - Failed to import: /opt/airflow/dags/local_to_gcs.py
Traceback (most recent call last):
  File "/home/airflow/.local/lib/python3.12/site-packages/airflow/models/dagbag.py", line 383, in parse
    loader.exec_module(new_module)
  File "<frozen importlib._bootstrap_external>", line 999, in exec_module
  File "<frozen importlib._bootstrap>", line 488, in _call_with_frames_removed
  File "/opt/airflow/dags/local_to_gcs.py", line 66, in <module>
    retail_dag = retail()  # Instantiate the DAG
                 ^^^^^^^^
  File "/home/airflow/.local/lib/python3.12/site-packages/airflow/models/dag.py", line 4307, in factory
    f(**f_kwargs)
  File "/opt/airflow/dags/local_to_gcs.py", line 31, in retail
    csv_files = [f for f in os.listdir(dataset_folder) if f.endswith(".csv")]
                            ^^^^^^^^^^^^^^^^^^^^^^^^^^
FileNotFoundError: [Errno 2] No such file or directory: 'include/dataset/'
[2024-12-30T06:46:42.661+0000] {processor.py:927} WARNING - No viable dags retrieved from /opt/airflow/dags/local_to_gcs.py
[2024-12-30T06:46:42.696+0000] {processor.py:208} INFO - Processing /opt/airflow/dags/local_to_gcs.py took 0.085 seconds
[2024-12-30T06:47:13.157+0000] {processor.py:186} INFO - Started process (PID=3210) to work on /opt/airflow/dags/local_to_gcs.py
[2024-12-30T06:47:13.159+0000] {processor.py:914} INFO - Processing file /opt/airflow/dags/local_to_gcs.py for tasks to queue
[2024-12-30T06:47:13.161+0000] {logging_mixin.py:190} INFO - [2024-12-30T06:47:13.160+0000] {dagbag.py:588} INFO - Filling up the DagBag from /opt/airflow/dags/local_to_gcs.py
[2024-12-30T06:47:13.199+0000] {logging_mixin.py:190} INFO - [2024-12-30T06:47:13.191+0000] {dagbag.py:387} ERROR - Failed to import: /opt/airflow/dags/local_to_gcs.py
Traceback (most recent call last):
  File "/home/airflow/.local/lib/python3.12/site-packages/airflow/models/dagbag.py", line 383, in parse
    loader.exec_module(new_module)
  File "<frozen importlib._bootstrap_external>", line 999, in exec_module
  File "<frozen importlib._bootstrap>", line 488, in _call_with_frames_removed
  File "/opt/airflow/dags/local_to_gcs.py", line 66, in <module>
    retail_dag = retail()  # Instantiate the DAG
                 ^^^^^^^^
  File "/home/airflow/.local/lib/python3.12/site-packages/airflow/models/dag.py", line 4307, in factory
    f(**f_kwargs)
  File "/opt/airflow/dags/local_to_gcs.py", line 31, in retail
    csv_files = [f for f in os.listdir(dataset_folder) if f.endswith(".csv")]
                            ^^^^^^^^^^^^^^^^^^^^^^^^^^
FileNotFoundError: [Errno 2] No such file or directory: 'include/dataset/'
[2024-12-30T06:47:13.201+0000] {processor.py:927} WARNING - No viable dags retrieved from /opt/airflow/dags/local_to_gcs.py
[2024-12-30T06:47:13.234+0000] {processor.py:208} INFO - Processing /opt/airflow/dags/local_to_gcs.py took 0.085 seconds
[2024-12-30T06:47:43.582+0000] {processor.py:186} INFO - Started process (PID=3276) to work on /opt/airflow/dags/local_to_gcs.py
[2024-12-30T06:47:43.585+0000] {processor.py:914} INFO - Processing file /opt/airflow/dags/local_to_gcs.py for tasks to queue
[2024-12-30T06:47:43.587+0000] {logging_mixin.py:190} INFO - [2024-12-30T06:47:43.586+0000] {dagbag.py:588} INFO - Filling up the DagBag from /opt/airflow/dags/local_to_gcs.py
[2024-12-30T06:47:43.642+0000] {logging_mixin.py:190} INFO - [2024-12-30T06:47:43.626+0000] {dagbag.py:387} ERROR - Failed to import: /opt/airflow/dags/local_to_gcs.py
Traceback (most recent call last):
  File "/home/airflow/.local/lib/python3.12/site-packages/airflow/models/dagbag.py", line 383, in parse
    loader.exec_module(new_module)
  File "<frozen importlib._bootstrap_external>", line 999, in exec_module
  File "<frozen importlib._bootstrap>", line 488, in _call_with_frames_removed
  File "/opt/airflow/dags/local_to_gcs.py", line 66, in <module>
    retail_dag = retail()  # Instantiate the DAG
                 ^^^^^^^^
  File "/home/airflow/.local/lib/python3.12/site-packages/airflow/models/dag.py", line 4307, in factory
    f(**f_kwargs)
  File "/opt/airflow/dags/local_to_gcs.py", line 31, in retail
    csv_files = [f for f in os.listdir(dataset_folder) if f.endswith(".csv")]
                            ^^^^^^^^^^^^^^^^^^^^^^^^^^
FileNotFoundError: [Errno 2] No such file or directory: 'include/dataset/'
[2024-12-30T06:47:43.646+0000] {processor.py:927} WARNING - No viable dags retrieved from /opt/airflow/dags/local_to_gcs.py
[2024-12-30T06:47:43.696+0000] {processor.py:208} INFO - Processing /opt/airflow/dags/local_to_gcs.py took 0.121 seconds
[2024-12-30T06:48:14.481+0000] {processor.py:186} INFO - Started process (PID=3342) to work on /opt/airflow/dags/local_to_gcs.py
[2024-12-30T06:48:14.483+0000] {processor.py:914} INFO - Processing file /opt/airflow/dags/local_to_gcs.py for tasks to queue
[2024-12-30T06:48:14.486+0000] {logging_mixin.py:190} INFO - [2024-12-30T06:48:14.485+0000] {dagbag.py:588} INFO - Filling up the DagBag from /opt/airflow/dags/local_to_gcs.py
[2024-12-30T06:48:14.587+0000] {logging_mixin.py:190} INFO - [2024-12-30T06:48:14.575+0000] {dagbag.py:387} ERROR - Failed to import: /opt/airflow/dags/local_to_gcs.py
Traceback (most recent call last):
  File "/home/airflow/.local/lib/python3.12/site-packages/airflow/models/dagbag.py", line 383, in parse
    loader.exec_module(new_module)
  File "<frozen importlib._bootstrap_external>", line 999, in exec_module
  File "<frozen importlib._bootstrap>", line 488, in _call_with_frames_removed
  File "/opt/airflow/dags/local_to_gcs.py", line 66, in <module>
    retail_dag = retail()  # Instantiate the DAG
                 ^^^^^^^^
  File "/home/airflow/.local/lib/python3.12/site-packages/airflow/models/dag.py", line 4307, in factory
    f(**f_kwargs)
  File "/opt/airflow/dags/local_to_gcs.py", line 31, in retail
    csv_files = [f for f in os.listdir(dataset_folder) if f.endswith(".csv")]
                            ^^^^^^^^^^^^^^^^^^^^^^^^^^
FileNotFoundError: [Errno 2] No such file or directory: 'include/dataset/'
[2024-12-30T06:48:14.589+0000] {processor.py:927} WARNING - No viable dags retrieved from /opt/airflow/dags/local_to_gcs.py
[2024-12-30T06:48:14.618+0000] {processor.py:208} INFO - Processing /opt/airflow/dags/local_to_gcs.py took 0.147 seconds
[2024-12-30T06:48:44.928+0000] {processor.py:186} INFO - Started process (PID=3408) to work on /opt/airflow/dags/local_to_gcs.py
[2024-12-30T06:48:44.930+0000] {processor.py:914} INFO - Processing file /opt/airflow/dags/local_to_gcs.py for tasks to queue
[2024-12-30T06:48:44.931+0000] {logging_mixin.py:190} INFO - [2024-12-30T06:48:44.931+0000] {dagbag.py:588} INFO - Filling up the DagBag from /opt/airflow/dags/local_to_gcs.py
[2024-12-30T06:48:44.966+0000] {logging_mixin.py:190} INFO - [2024-12-30T06:48:44.960+0000] {dagbag.py:387} ERROR - Failed to import: /opt/airflow/dags/local_to_gcs.py
Traceback (most recent call last):
  File "/home/airflow/.local/lib/python3.12/site-packages/airflow/models/dagbag.py", line 383, in parse
    loader.exec_module(new_module)
  File "<frozen importlib._bootstrap_external>", line 999, in exec_module
  File "<frozen importlib._bootstrap>", line 488, in _call_with_frames_removed
  File "/opt/airflow/dags/local_to_gcs.py", line 66, in <module>
    retail_dag = retail()  # Instantiate the DAG
                 ^^^^^^^^
  File "/home/airflow/.local/lib/python3.12/site-packages/airflow/models/dag.py", line 4307, in factory
    f(**f_kwargs)
  File "/opt/airflow/dags/local_to_gcs.py", line 31, in retail
    csv_files = [f for f in os.listdir(dataset_folder) if f.endswith(".csv")]
                            ^^^^^^^^^^^^^^^^^^^^^^^^^^
FileNotFoundError: [Errno 2] No such file or directory: 'include/dataset/'
[2024-12-30T06:48:44.967+0000] {processor.py:927} WARNING - No viable dags retrieved from /opt/airflow/dags/local_to_gcs.py
[2024-12-30T06:48:44.995+0000] {processor.py:208} INFO - Processing /opt/airflow/dags/local_to_gcs.py took 0.075 seconds
[2024-12-30T06:49:15.679+0000] {processor.py:186} INFO - Started process (PID=3474) to work on /opt/airflow/dags/local_to_gcs.py
[2024-12-30T06:49:15.682+0000] {processor.py:914} INFO - Processing file /opt/airflow/dags/local_to_gcs.py for tasks to queue
[2024-12-30T06:49:15.688+0000] {logging_mixin.py:190} INFO - [2024-12-30T06:49:15.687+0000] {dagbag.py:588} INFO - Filling up the DagBag from /opt/airflow/dags/local_to_gcs.py
[2024-12-30T06:49:15.747+0000] {logging_mixin.py:190} INFO - [2024-12-30T06:49:15.739+0000] {dagbag.py:387} ERROR - Failed to import: /opt/airflow/dags/local_to_gcs.py
Traceback (most recent call last):
  File "/home/airflow/.local/lib/python3.12/site-packages/airflow/models/dagbag.py", line 383, in parse
    loader.exec_module(new_module)
  File "<frozen importlib._bootstrap_external>", line 999, in exec_module
  File "<frozen importlib._bootstrap>", line 488, in _call_with_frames_removed
  File "/opt/airflow/dags/local_to_gcs.py", line 66, in <module>
    retail_dag = retail()  # Instantiate the DAG
                 ^^^^^^^^
  File "/home/airflow/.local/lib/python3.12/site-packages/airflow/models/dag.py", line 4307, in factory
    f(**f_kwargs)
  File "/opt/airflow/dags/local_to_gcs.py", line 31, in retail
    csv_files = [f for f in os.listdir(dataset_folder) if f.endswith(".csv")]
                            ^^^^^^^^^^^^^^^^^^^^^^^^^^
FileNotFoundError: [Errno 2] No such file or directory: 'include/dataset/'
[2024-12-30T06:49:15.749+0000] {processor.py:927} WARNING - No viable dags retrieved from /opt/airflow/dags/local_to_gcs.py
[2024-12-30T06:49:15.795+0000] {processor.py:208} INFO - Processing /opt/airflow/dags/local_to_gcs.py took 0.133 seconds
[2024-12-30T06:49:46.057+0000] {processor.py:186} INFO - Started process (PID=3540) to work on /opt/airflow/dags/local_to_gcs.py
[2024-12-30T06:49:46.061+0000] {processor.py:914} INFO - Processing file /opt/airflow/dags/local_to_gcs.py for tasks to queue
[2024-12-30T06:49:46.064+0000] {logging_mixin.py:190} INFO - [2024-12-30T06:49:46.064+0000] {dagbag.py:588} INFO - Filling up the DagBag from /opt/airflow/dags/local_to_gcs.py
[2024-12-30T06:49:46.108+0000] {logging_mixin.py:190} INFO - [2024-12-30T06:49:46.101+0000] {dagbag.py:387} ERROR - Failed to import: /opt/airflow/dags/local_to_gcs.py
Traceback (most recent call last):
  File "/home/airflow/.local/lib/python3.12/site-packages/airflow/models/dagbag.py", line 383, in parse
    loader.exec_module(new_module)
  File "<frozen importlib._bootstrap_external>", line 999, in exec_module
  File "<frozen importlib._bootstrap>", line 488, in _call_with_frames_removed
  File "/opt/airflow/dags/local_to_gcs.py", line 66, in <module>
    retail_dag = retail()  # Instantiate the DAG
                 ^^^^^^^^
  File "/home/airflow/.local/lib/python3.12/site-packages/airflow/models/dag.py", line 4307, in factory
    f(**f_kwargs)
  File "/opt/airflow/dags/local_to_gcs.py", line 31, in retail
    csv_files = [f for f in os.listdir(dataset_folder) if f.endswith(".csv")]
                            ^^^^^^^^^^^^^^^^^^^^^^^^^^
FileNotFoundError: [Errno 2] No such file or directory: 'include/dataset/'
[2024-12-30T06:49:46.110+0000] {processor.py:927} WARNING - No viable dags retrieved from /opt/airflow/dags/local_to_gcs.py
[2024-12-30T06:49:46.135+0000] {processor.py:208} INFO - Processing /opt/airflow/dags/local_to_gcs.py took 0.087 seconds
[2024-12-30T06:50:16.337+0000] {processor.py:186} INFO - Started process (PID=3606) to work on /opt/airflow/dags/local_to_gcs.py
[2024-12-30T06:50:16.338+0000] {processor.py:914} INFO - Processing file /opt/airflow/dags/local_to_gcs.py for tasks to queue
[2024-12-30T06:50:16.340+0000] {logging_mixin.py:190} INFO - [2024-12-30T06:50:16.340+0000] {dagbag.py:588} INFO - Filling up the DagBag from /opt/airflow/dags/local_to_gcs.py
[2024-12-30T06:50:16.399+0000] {logging_mixin.py:190} INFO - [2024-12-30T06:50:16.388+0000] {dagbag.py:387} ERROR - Failed to import: /opt/airflow/dags/local_to_gcs.py
Traceback (most recent call last):
  File "/home/airflow/.local/lib/python3.12/site-packages/airflow/models/dagbag.py", line 383, in parse
    loader.exec_module(new_module)
  File "<frozen importlib._bootstrap_external>", line 999, in exec_module
  File "<frozen importlib._bootstrap>", line 488, in _call_with_frames_removed
  File "/opt/airflow/dags/local_to_gcs.py", line 66, in <module>
    retail_dag = retail()  # Instantiate the DAG
                 ^^^^^^^^
  File "/home/airflow/.local/lib/python3.12/site-packages/airflow/models/dag.py", line 4307, in factory
    f(**f_kwargs)
  File "/opt/airflow/dags/local_to_gcs.py", line 31, in retail
    csv_files = [f for f in os.listdir(dataset_folder) if f.endswith(".csv")]
                            ^^^^^^^^^^^^^^^^^^^^^^^^^^
FileNotFoundError: [Errno 2] No such file or directory: 'include/dataset/'
[2024-12-30T06:50:16.401+0000] {processor.py:927} WARNING - No viable dags retrieved from /opt/airflow/dags/local_to_gcs.py
[2024-12-30T06:50:16.432+0000] {processor.py:208} INFO - Processing /opt/airflow/dags/local_to_gcs.py took 0.104 seconds
[2024-12-30T06:50:46.949+0000] {processor.py:186} INFO - Started process (PID=3671) to work on /opt/airflow/dags/local_to_gcs.py
[2024-12-30T06:50:46.952+0000] {processor.py:914} INFO - Processing file /opt/airflow/dags/local_to_gcs.py for tasks to queue
[2024-12-30T06:50:46.955+0000] {logging_mixin.py:190} INFO - [2024-12-30T06:50:46.955+0000] {dagbag.py:588} INFO - Filling up the DagBag from /opt/airflow/dags/local_to_gcs.py
[2024-12-30T06:50:46.999+0000] {logging_mixin.py:190} INFO - [2024-12-30T06:50:46.993+0000] {dagbag.py:387} ERROR - Failed to import: /opt/airflow/dags/local_to_gcs.py
Traceback (most recent call last):
  File "/home/airflow/.local/lib/python3.12/site-packages/airflow/models/dagbag.py", line 383, in parse
    loader.exec_module(new_module)
  File "<frozen importlib._bootstrap_external>", line 999, in exec_module
  File "<frozen importlib._bootstrap>", line 488, in _call_with_frames_removed
  File "/opt/airflow/dags/local_to_gcs.py", line 66, in <module>
    retail_dag = retail()  # Instantiate the DAG
                 ^^^^^^^^
  File "/home/airflow/.local/lib/python3.12/site-packages/airflow/models/dag.py", line 4307, in factory
    f(**f_kwargs)
  File "/opt/airflow/dags/local_to_gcs.py", line 31, in retail
    csv_files = [f for f in os.listdir(dataset_folder) if f.endswith(".csv")]
                            ^^^^^^^^^^^^^^^^^^^^^^^^^^
FileNotFoundError: [Errno 2] No such file or directory: 'include/dataset/'
[2024-12-30T06:50:47.002+0000] {processor.py:927} WARNING - No viable dags retrieved from /opt/airflow/dags/local_to_gcs.py
[2024-12-30T06:50:47.029+0000] {processor.py:208} INFO - Processing /opt/airflow/dags/local_to_gcs.py took 0.091 seconds
[2024-12-30T06:51:17.298+0000] {processor.py:186} INFO - Started process (PID=3737) to work on /opt/airflow/dags/local_to_gcs.py
[2024-12-30T06:51:17.299+0000] {processor.py:914} INFO - Processing file /opt/airflow/dags/local_to_gcs.py for tasks to queue
[2024-12-30T06:51:17.303+0000] {logging_mixin.py:190} INFO - [2024-12-30T06:51:17.302+0000] {dagbag.py:588} INFO - Filling up the DagBag from /opt/airflow/dags/local_to_gcs.py
[2024-12-30T06:51:17.347+0000] {logging_mixin.py:190} INFO - [2024-12-30T06:51:17.339+0000] {dagbag.py:387} ERROR - Failed to import: /opt/airflow/dags/local_to_gcs.py
Traceback (most recent call last):
  File "/home/airflow/.local/lib/python3.12/site-packages/airflow/models/dagbag.py", line 383, in parse
    loader.exec_module(new_module)
  File "<frozen importlib._bootstrap_external>", line 999, in exec_module
  File "<frozen importlib._bootstrap>", line 488, in _call_with_frames_removed
  File "/opt/airflow/dags/local_to_gcs.py", line 66, in <module>
    retail_dag = retail()  # Instantiate the DAG
                 ^^^^^^^^
  File "/home/airflow/.local/lib/python3.12/site-packages/airflow/models/dag.py", line 4307, in factory
    f(**f_kwargs)
  File "/opt/airflow/dags/local_to_gcs.py", line 31, in retail
    csv_files = [f for f in os.listdir(dataset_folder) if f.endswith(".csv")]
                            ^^^^^^^^^^^^^^^^^^^^^^^^^^
FileNotFoundError: [Errno 2] No such file or directory: 'include/dataset/'
[2024-12-30T06:51:17.349+0000] {processor.py:927} WARNING - No viable dags retrieved from /opt/airflow/dags/local_to_gcs.py
[2024-12-30T06:51:17.386+0000] {processor.py:208} INFO - Processing /opt/airflow/dags/local_to_gcs.py took 0.098 seconds
[2024-12-30T06:51:47.831+0000] {processor.py:186} INFO - Started process (PID=3803) to work on /opt/airflow/dags/local_to_gcs.py
[2024-12-30T06:51:47.833+0000] {processor.py:914} INFO - Processing file /opt/airflow/dags/local_to_gcs.py for tasks to queue
[2024-12-30T06:51:47.836+0000] {logging_mixin.py:190} INFO - [2024-12-30T06:51:47.835+0000] {dagbag.py:588} INFO - Filling up the DagBag from /opt/airflow/dags/local_to_gcs.py
[2024-12-30T06:51:47.884+0000] {logging_mixin.py:190} INFO - [2024-12-30T06:51:47.876+0000] {dagbag.py:387} ERROR - Failed to import: /opt/airflow/dags/local_to_gcs.py
Traceback (most recent call last):
  File "/home/airflow/.local/lib/python3.12/site-packages/airflow/models/dagbag.py", line 383, in parse
    loader.exec_module(new_module)
  File "<frozen importlib._bootstrap_external>", line 999, in exec_module
  File "<frozen importlib._bootstrap>", line 488, in _call_with_frames_removed
  File "/opt/airflow/dags/local_to_gcs.py", line 66, in <module>
    retail_dag = retail()  # Instantiate the DAG
                 ^^^^^^^^
  File "/home/airflow/.local/lib/python3.12/site-packages/airflow/models/dag.py", line 4307, in factory
    f(**f_kwargs)
  File "/opt/airflow/dags/local_to_gcs.py", line 31, in retail
    csv_files = [f for f in os.listdir(dataset_folder) if f.endswith(".csv")]
                            ^^^^^^^^^^^^^^^^^^^^^^^^^^
FileNotFoundError: [Errno 2] No such file or directory: 'include/dataset/'
[2024-12-30T06:51:47.887+0000] {processor.py:927} WARNING - No viable dags retrieved from /opt/airflow/dags/local_to_gcs.py
[2024-12-30T06:51:47.925+0000] {processor.py:208} INFO - Processing /opt/airflow/dags/local_to_gcs.py took 0.102 seconds
[2024-12-30T06:52:18.102+0000] {processor.py:186} INFO - Started process (PID=3869) to work on /opt/airflow/dags/local_to_gcs.py
[2024-12-30T06:52:18.106+0000] {processor.py:914} INFO - Processing file /opt/airflow/dags/local_to_gcs.py for tasks to queue
[2024-12-30T06:52:18.113+0000] {logging_mixin.py:190} INFO - [2024-12-30T06:52:18.110+0000] {dagbag.py:588} INFO - Filling up the DagBag from /opt/airflow/dags/local_to_gcs.py
[2024-12-30T06:52:18.182+0000] {logging_mixin.py:190} INFO - [2024-12-30T06:52:18.171+0000] {dagbag.py:387} ERROR - Failed to import: /opt/airflow/dags/local_to_gcs.py
Traceback (most recent call last):
  File "/home/airflow/.local/lib/python3.12/site-packages/airflow/models/dagbag.py", line 383, in parse
    loader.exec_module(new_module)
  File "<frozen importlib._bootstrap_external>", line 999, in exec_module
  File "<frozen importlib._bootstrap>", line 488, in _call_with_frames_removed
  File "/opt/airflow/dags/local_to_gcs.py", line 66, in <module>
    retail_dag = retail()  # Instantiate the DAG
                 ^^^^^^^^
  File "/home/airflow/.local/lib/python3.12/site-packages/airflow/models/dag.py", line 4307, in factory
    f(**f_kwargs)
  File "/opt/airflow/dags/local_to_gcs.py", line 31, in retail
    csv_files = [f for f in os.listdir(dataset_folder) if f.endswith(".csv")]
                            ^^^^^^^^^^^^^^^^^^^^^^^^^^
FileNotFoundError: [Errno 2] No such file or directory: 'include/dataset/'
[2024-12-30T06:52:18.183+0000] {processor.py:927} WARNING - No viable dags retrieved from /opt/airflow/dags/local_to_gcs.py
[2024-12-30T06:52:18.232+0000] {processor.py:208} INFO - Processing /opt/airflow/dags/local_to_gcs.py took 0.144 seconds
[2024-12-30T06:52:48.300+0000] {processor.py:186} INFO - Started process (PID=3936) to work on /opt/airflow/dags/local_to_gcs.py
[2024-12-30T06:52:48.302+0000] {processor.py:914} INFO - Processing file /opt/airflow/dags/local_to_gcs.py for tasks to queue
[2024-12-30T06:52:48.306+0000] {logging_mixin.py:190} INFO - [2024-12-30T06:52:48.305+0000] {dagbag.py:588} INFO - Filling up the DagBag from /opt/airflow/dags/local_to_gcs.py
[2024-12-30T06:52:48.355+0000] {logging_mixin.py:190} INFO - [2024-12-30T06:52:48.347+0000] {dagbag.py:387} ERROR - Failed to import: /opt/airflow/dags/local_to_gcs.py
Traceback (most recent call last):
  File "/home/airflow/.local/lib/python3.12/site-packages/airflow/models/dagbag.py", line 383, in parse
    loader.exec_module(new_module)
  File "<frozen importlib._bootstrap_external>", line 999, in exec_module
  File "<frozen importlib._bootstrap>", line 488, in _call_with_frames_removed
  File "/opt/airflow/dags/local_to_gcs.py", line 66, in <module>
    retail_dag = retail()  # Instantiate the DAG
                 ^^^^^^^^
  File "/home/airflow/.local/lib/python3.12/site-packages/airflow/models/dag.py", line 4307, in factory
    f(**f_kwargs)
  File "/opt/airflow/dags/local_to_gcs.py", line 31, in retail
    csv_files = [f for f in os.listdir(dataset_folder) if f.endswith(".csv")]
                            ^^^^^^^^^^^^^^^^^^^^^^^^^^
FileNotFoundError: [Errno 2] No such file or directory: 'include/dataset/'
[2024-12-30T06:52:48.360+0000] {processor.py:927} WARNING - No viable dags retrieved from /opt/airflow/dags/local_to_gcs.py
[2024-12-30T06:52:48.388+0000] {processor.py:208} INFO - Processing /opt/airflow/dags/local_to_gcs.py took 0.097 seconds
[2024-12-30T06:53:19.253+0000] {processor.py:186} INFO - Started process (PID=4002) to work on /opt/airflow/dags/local_to_gcs.py
[2024-12-30T06:53:19.255+0000] {processor.py:914} INFO - Processing file /opt/airflow/dags/local_to_gcs.py for tasks to queue
[2024-12-30T06:53:19.258+0000] {logging_mixin.py:190} INFO - [2024-12-30T06:53:19.258+0000] {dagbag.py:588} INFO - Filling up the DagBag from /opt/airflow/dags/local_to_gcs.py
[2024-12-30T06:53:19.298+0000] {logging_mixin.py:190} INFO - [2024-12-30T06:53:19.289+0000] {dagbag.py:387} ERROR - Failed to import: /opt/airflow/dags/local_to_gcs.py
Traceback (most recent call last):
  File "/home/airflow/.local/lib/python3.12/site-packages/airflow/models/dagbag.py", line 383, in parse
    loader.exec_module(new_module)
  File "<frozen importlib._bootstrap_external>", line 999, in exec_module
  File "<frozen importlib._bootstrap>", line 488, in _call_with_frames_removed
  File "/opt/airflow/dags/local_to_gcs.py", line 66, in <module>
    retail_dag = retail()  # Instantiate the DAG
                 ^^^^^^^^
  File "/home/airflow/.local/lib/python3.12/site-packages/airflow/models/dag.py", line 4307, in factory
    f(**f_kwargs)
  File "/opt/airflow/dags/local_to_gcs.py", line 31, in retail
    csv_files = [f for f in os.listdir(dataset_folder) if f.endswith(".csv")]
                            ^^^^^^^^^^^^^^^^^^^^^^^^^^
FileNotFoundError: [Errno 2] No such file or directory: 'include/dataset/'
[2024-12-30T06:53:19.300+0000] {processor.py:927} WARNING - No viable dags retrieved from /opt/airflow/dags/local_to_gcs.py
[2024-12-30T06:53:19.333+0000] {processor.py:208} INFO - Processing /opt/airflow/dags/local_to_gcs.py took 0.089 seconds
[2024-12-30T06:53:49.722+0000] {processor.py:186} INFO - Started process (PID=4068) to work on /opt/airflow/dags/local_to_gcs.py
[2024-12-30T06:53:49.724+0000] {processor.py:914} INFO - Processing file /opt/airflow/dags/local_to_gcs.py for tasks to queue
[2024-12-30T06:53:49.727+0000] {logging_mixin.py:190} INFO - [2024-12-30T06:53:49.726+0000] {dagbag.py:588} INFO - Filling up the DagBag from /opt/airflow/dags/local_to_gcs.py
[2024-12-30T06:53:49.768+0000] {logging_mixin.py:190} INFO - [2024-12-30T06:53:49.761+0000] {dagbag.py:387} ERROR - Failed to import: /opt/airflow/dags/local_to_gcs.py
Traceback (most recent call last):
  File "/home/airflow/.local/lib/python3.12/site-packages/airflow/models/dagbag.py", line 383, in parse
    loader.exec_module(new_module)
  File "<frozen importlib._bootstrap_external>", line 999, in exec_module
  File "<frozen importlib._bootstrap>", line 488, in _call_with_frames_removed
  File "/opt/airflow/dags/local_to_gcs.py", line 66, in <module>
    retail_dag = retail()  # Instantiate the DAG
                 ^^^^^^^^
  File "/home/airflow/.local/lib/python3.12/site-packages/airflow/models/dag.py", line 4307, in factory
    f(**f_kwargs)
  File "/opt/airflow/dags/local_to_gcs.py", line 31, in retail
    csv_files = [f for f in os.listdir(dataset_folder) if f.endswith(".csv")]
                            ^^^^^^^^^^^^^^^^^^^^^^^^^^
FileNotFoundError: [Errno 2] No such file or directory: 'include/dataset/'
[2024-12-30T06:53:49.770+0000] {processor.py:927} WARNING - No viable dags retrieved from /opt/airflow/dags/local_to_gcs.py
[2024-12-30T06:53:49.805+0000] {processor.py:208} INFO - Processing /opt/airflow/dags/local_to_gcs.py took 0.090 seconds
[2024-12-30T06:54:20.591+0000] {processor.py:186} INFO - Started process (PID=4134) to work on /opt/airflow/dags/local_to_gcs.py
[2024-12-30T06:54:20.595+0000] {processor.py:914} INFO - Processing file /opt/airflow/dags/local_to_gcs.py for tasks to queue
[2024-12-30T06:54:20.598+0000] {logging_mixin.py:190} INFO - [2024-12-30T06:54:20.597+0000] {dagbag.py:588} INFO - Filling up the DagBag from /opt/airflow/dags/local_to_gcs.py
[2024-12-30T06:54:20.655+0000] {logging_mixin.py:190} INFO - [2024-12-30T06:54:20.642+0000] {dagbag.py:387} ERROR - Failed to import: /opt/airflow/dags/local_to_gcs.py
Traceback (most recent call last):
  File "/home/airflow/.local/lib/python3.12/site-packages/airflow/models/dagbag.py", line 383, in parse
    loader.exec_module(new_module)
  File "<frozen importlib._bootstrap_external>", line 999, in exec_module
  File "<frozen importlib._bootstrap>", line 488, in _call_with_frames_removed
  File "/opt/airflow/dags/local_to_gcs.py", line 66, in <module>
    retail_dag = retail()  # Instantiate the DAG
                 ^^^^^^^^
  File "/home/airflow/.local/lib/python3.12/site-packages/airflow/models/dag.py", line 4307, in factory
    f(**f_kwargs)
  File "/opt/airflow/dags/local_to_gcs.py", line 31, in retail
    csv_files = [f for f in os.listdir(dataset_folder) if f.endswith(".csv")]
                            ^^^^^^^^^^^^^^^^^^^^^^^^^^
FileNotFoundError: [Errno 2] No such file or directory: 'include/dataset/'
[2024-12-30T06:54:20.659+0000] {processor.py:927} WARNING - No viable dags retrieved from /opt/airflow/dags/local_to_gcs.py
[2024-12-30T06:54:20.692+0000] {processor.py:208} INFO - Processing /opt/airflow/dags/local_to_gcs.py took 0.111 seconds
[2024-12-30T06:54:51.361+0000] {processor.py:186} INFO - Started process (PID=4200) to work on /opt/airflow/dags/local_to_gcs.py
[2024-12-30T06:54:51.364+0000] {processor.py:914} INFO - Processing file /opt/airflow/dags/local_to_gcs.py for tasks to queue
[2024-12-30T06:54:51.366+0000] {logging_mixin.py:190} INFO - [2024-12-30T06:54:51.366+0000] {dagbag.py:588} INFO - Filling up the DagBag from /opt/airflow/dags/local_to_gcs.py
[2024-12-30T06:54:51.401+0000] {logging_mixin.py:190} INFO - [2024-12-30T06:54:51.394+0000] {dagbag.py:387} ERROR - Failed to import: /opt/airflow/dags/local_to_gcs.py
Traceback (most recent call last):
  File "/home/airflow/.local/lib/python3.12/site-packages/airflow/models/dagbag.py", line 383, in parse
    loader.exec_module(new_module)
  File "<frozen importlib._bootstrap_external>", line 999, in exec_module
  File "<frozen importlib._bootstrap>", line 488, in _call_with_frames_removed
  File "/opt/airflow/dags/local_to_gcs.py", line 66, in <module>
    retail_dag = retail()  # Instantiate the DAG
                 ^^^^^^^^
  File "/home/airflow/.local/lib/python3.12/site-packages/airflow/models/dag.py", line 4307, in factory
    f(**f_kwargs)
  File "/opt/airflow/dags/local_to_gcs.py", line 31, in retail
    csv_files = [f for f in os.listdir(dataset_folder) if f.endswith(".csv")]
                            ^^^^^^^^^^^^^^^^^^^^^^^^^^
FileNotFoundError: [Errno 2] No such file or directory: 'include/dataset/'
[2024-12-30T06:54:51.403+0000] {processor.py:927} WARNING - No viable dags retrieved from /opt/airflow/dags/local_to_gcs.py
[2024-12-30T06:54:51.435+0000] {processor.py:208} INFO - Processing /opt/airflow/dags/local_to_gcs.py took 0.081 seconds
[2024-12-30T06:55:21.758+0000] {processor.py:186} INFO - Started process (PID=4266) to work on /opt/airflow/dags/local_to_gcs.py
[2024-12-30T06:55:21.760+0000] {processor.py:914} INFO - Processing file /opt/airflow/dags/local_to_gcs.py for tasks to queue
[2024-12-30T06:55:21.764+0000] {logging_mixin.py:190} INFO - [2024-12-30T06:55:21.763+0000] {dagbag.py:588} INFO - Filling up the DagBag from /opt/airflow/dags/local_to_gcs.py
[2024-12-30T06:55:21.810+0000] {logging_mixin.py:190} INFO - [2024-12-30T06:55:21.802+0000] {dagbag.py:387} ERROR - Failed to import: /opt/airflow/dags/local_to_gcs.py
Traceback (most recent call last):
  File "/home/airflow/.local/lib/python3.12/site-packages/airflow/models/dagbag.py", line 383, in parse
    loader.exec_module(new_module)
  File "<frozen importlib._bootstrap_external>", line 999, in exec_module
  File "<frozen importlib._bootstrap>", line 488, in _call_with_frames_removed
  File "/opt/airflow/dags/local_to_gcs.py", line 66, in <module>
    retail_dag = retail()  # Instantiate the DAG
                 ^^^^^^^^
  File "/home/airflow/.local/lib/python3.12/site-packages/airflow/models/dag.py", line 4307, in factory
    f(**f_kwargs)
  File "/opt/airflow/dags/local_to_gcs.py", line 31, in retail
    csv_files = [f for f in os.listdir(dataset_folder) if f.endswith(".csv")]
                            ^^^^^^^^^^^^^^^^^^^^^^^^^^
FileNotFoundError: [Errno 2] No such file or directory: 'include/dataset/'
[2024-12-30T06:55:21.812+0000] {processor.py:927} WARNING - No viable dags retrieved from /opt/airflow/dags/local_to_gcs.py
[2024-12-30T06:55:21.847+0000] {processor.py:208} INFO - Processing /opt/airflow/dags/local_to_gcs.py took 0.097 seconds
[2024-12-30T06:55:52.200+0000] {processor.py:186} INFO - Started process (PID=4332) to work on /opt/airflow/dags/local_to_gcs.py
[2024-12-30T06:55:52.202+0000] {processor.py:914} INFO - Processing file /opt/airflow/dags/local_to_gcs.py for tasks to queue
[2024-12-30T06:55:52.209+0000] {logging_mixin.py:190} INFO - [2024-12-30T06:55:52.208+0000] {dagbag.py:588} INFO - Filling up the DagBag from /opt/airflow/dags/local_to_gcs.py
[2024-12-30T06:55:52.256+0000] {logging_mixin.py:190} INFO - [2024-12-30T06:55:52.242+0000] {dagbag.py:387} ERROR - Failed to import: /opt/airflow/dags/local_to_gcs.py
Traceback (most recent call last):
  File "/home/airflow/.local/lib/python3.12/site-packages/airflow/models/dagbag.py", line 383, in parse
    loader.exec_module(new_module)
  File "<frozen importlib._bootstrap_external>", line 999, in exec_module
  File "<frozen importlib._bootstrap>", line 488, in _call_with_frames_removed
  File "/opt/airflow/dags/local_to_gcs.py", line 66, in <module>
    retail_dag = retail()  # Instantiate the DAG
                 ^^^^^^^^
  File "/home/airflow/.local/lib/python3.12/site-packages/airflow/models/dag.py", line 4307, in factory
    f(**f_kwargs)
  File "/opt/airflow/dags/local_to_gcs.py", line 31, in retail
    csv_files = [f for f in os.listdir(dataset_folder) if f.endswith(".csv")]
                            ^^^^^^^^^^^^^^^^^^^^^^^^^^
FileNotFoundError: [Errno 2] No such file or directory: 'include/dataset/'
[2024-12-30T06:55:52.259+0000] {processor.py:927} WARNING - No viable dags retrieved from /opt/airflow/dags/local_to_gcs.py
[2024-12-30T06:55:52.297+0000] {processor.py:208} INFO - Processing /opt/airflow/dags/local_to_gcs.py took 0.107 seconds
[2024-12-30T06:56:22.717+0000] {processor.py:186} INFO - Started process (PID=4397) to work on /opt/airflow/dags/local_to_gcs.py
[2024-12-30T06:56:22.719+0000] {processor.py:914} INFO - Processing file /opt/airflow/dags/local_to_gcs.py for tasks to queue
[2024-12-30T06:56:22.723+0000] {logging_mixin.py:190} INFO - [2024-12-30T06:56:22.722+0000] {dagbag.py:588} INFO - Filling up the DagBag from /opt/airflow/dags/local_to_gcs.py
[2024-12-30T06:56:22.789+0000] {logging_mixin.py:190} INFO - [2024-12-30T06:56:22.778+0000] {dagbag.py:387} ERROR - Failed to import: /opt/airflow/dags/local_to_gcs.py
Traceback (most recent call last):
  File "/home/airflow/.local/lib/python3.12/site-packages/airflow/models/dagbag.py", line 383, in parse
    loader.exec_module(new_module)
  File "<frozen importlib._bootstrap_external>", line 999, in exec_module
  File "<frozen importlib._bootstrap>", line 488, in _call_with_frames_removed
  File "/opt/airflow/dags/local_to_gcs.py", line 66, in <module>
    retail_dag = retail()  # Instantiate the DAG
                 ^^^^^^^^
  File "/home/airflow/.local/lib/python3.12/site-packages/airflow/models/dag.py", line 4307, in factory
    f(**f_kwargs)
  File "/opt/airflow/dags/local_to_gcs.py", line 31, in retail
    csv_files = [f for f in os.listdir(dataset_folder) if f.endswith(".csv")]
                            ^^^^^^^^^^^^^^^^^^^^^^^^^^
FileNotFoundError: [Errno 2] No such file or directory: 'include/dataset/'
[2024-12-30T06:56:22.791+0000] {processor.py:927} WARNING - No viable dags retrieved from /opt/airflow/dags/local_to_gcs.py
[2024-12-30T06:56:22.839+0000] {processor.py:208} INFO - Processing /opt/airflow/dags/local_to_gcs.py took 0.135 seconds
[2024-12-30T06:56:53.380+0000] {processor.py:186} INFO - Started process (PID=4463) to work on /opt/airflow/dags/local_to_gcs.py
[2024-12-30T06:56:53.381+0000] {processor.py:914} INFO - Processing file /opt/airflow/dags/local_to_gcs.py for tasks to queue
[2024-12-30T06:56:53.385+0000] {logging_mixin.py:190} INFO - [2024-12-30T06:56:53.384+0000] {dagbag.py:588} INFO - Filling up the DagBag from /opt/airflow/dags/local_to_gcs.py
[2024-12-30T06:56:53.440+0000] {logging_mixin.py:190} INFO - [2024-12-30T06:56:53.432+0000] {dagbag.py:387} ERROR - Failed to import: /opt/airflow/dags/local_to_gcs.py
Traceback (most recent call last):
  File "/home/airflow/.local/lib/python3.12/site-packages/airflow/models/dagbag.py", line 383, in parse
    loader.exec_module(new_module)
  File "<frozen importlib._bootstrap_external>", line 999, in exec_module
  File "<frozen importlib._bootstrap>", line 488, in _call_with_frames_removed
  File "/opt/airflow/dags/local_to_gcs.py", line 66, in <module>
    retail_dag = retail()  # Instantiate the DAG
                 ^^^^^^^^
  File "/home/airflow/.local/lib/python3.12/site-packages/airflow/models/dag.py", line 4307, in factory
    f(**f_kwargs)
  File "/opt/airflow/dags/local_to_gcs.py", line 31, in retail
    csv_files = [f for f in os.listdir(dataset_folder) if f.endswith(".csv")]
                            ^^^^^^^^^^^^^^^^^^^^^^^^^^
FileNotFoundError: [Errno 2] No such file or directory: 'include/dataset/'
[2024-12-30T06:56:53.447+0000] {processor.py:927} WARNING - No viable dags retrieved from /opt/airflow/dags/local_to_gcs.py
[2024-12-30T06:56:53.487+0000] {processor.py:208} INFO - Processing /opt/airflow/dags/local_to_gcs.py took 0.118 seconds
[2024-12-30T06:57:23.622+0000] {processor.py:186} INFO - Started process (PID=4529) to work on /opt/airflow/dags/local_to_gcs.py
[2024-12-30T06:57:23.624+0000] {processor.py:914} INFO - Processing file /opt/airflow/dags/local_to_gcs.py for tasks to queue
[2024-12-30T06:57:23.626+0000] {logging_mixin.py:190} INFO - [2024-12-30T06:57:23.625+0000] {dagbag.py:588} INFO - Filling up the DagBag from /opt/airflow/dags/local_to_gcs.py
[2024-12-30T06:57:23.671+0000] {logging_mixin.py:190} INFO - [2024-12-30T06:57:23.661+0000] {dagbag.py:387} ERROR - Failed to import: /opt/airflow/dags/local_to_gcs.py
Traceback (most recent call last):
  File "/home/airflow/.local/lib/python3.12/site-packages/airflow/models/dagbag.py", line 383, in parse
    loader.exec_module(new_module)
  File "<frozen importlib._bootstrap_external>", line 999, in exec_module
  File "<frozen importlib._bootstrap>", line 488, in _call_with_frames_removed
  File "/opt/airflow/dags/local_to_gcs.py", line 66, in <module>
    retail_dag = retail()  # Instantiate the DAG
                 ^^^^^^^^
  File "/home/airflow/.local/lib/python3.12/site-packages/airflow/models/dag.py", line 4307, in factory
    f(**f_kwargs)
  File "/opt/airflow/dags/local_to_gcs.py", line 31, in retail
    csv_files = [f for f in os.listdir(dataset_folder) if f.endswith(".csv")]
                            ^^^^^^^^^^^^^^^^^^^^^^^^^^
FileNotFoundError: [Errno 2] No such file or directory: 'include/dataset/'
[2024-12-30T06:57:23.673+0000] {processor.py:927} WARNING - No viable dags retrieved from /opt/airflow/dags/local_to_gcs.py
[2024-12-30T06:57:23.721+0000] {processor.py:208} INFO - Processing /opt/airflow/dags/local_to_gcs.py took 0.107 seconds
[2024-12-30T06:57:54.673+0000] {processor.py:186} INFO - Started process (PID=4595) to work on /opt/airflow/dags/local_to_gcs.py
[2024-12-30T06:57:54.675+0000] {processor.py:914} INFO - Processing file /opt/airflow/dags/local_to_gcs.py for tasks to queue
[2024-12-30T06:57:54.677+0000] {logging_mixin.py:190} INFO - [2024-12-30T06:57:54.677+0000] {dagbag.py:588} INFO - Filling up the DagBag from /opt/airflow/dags/local_to_gcs.py
[2024-12-30T06:57:54.714+0000] {logging_mixin.py:190} INFO - [2024-12-30T06:57:54.707+0000] {dagbag.py:387} ERROR - Failed to import: /opt/airflow/dags/local_to_gcs.py
Traceback (most recent call last):
  File "/home/airflow/.local/lib/python3.12/site-packages/airflow/models/dagbag.py", line 383, in parse
    loader.exec_module(new_module)
  File "<frozen importlib._bootstrap_external>", line 999, in exec_module
  File "<frozen importlib._bootstrap>", line 488, in _call_with_frames_removed
  File "/opt/airflow/dags/local_to_gcs.py", line 66, in <module>
    retail_dag = retail()  # Instantiate the DAG
                 ^^^^^^^^
  File "/home/airflow/.local/lib/python3.12/site-packages/airflow/models/dag.py", line 4307, in factory
    f(**f_kwargs)
  File "/opt/airflow/dags/local_to_gcs.py", line 31, in retail
    csv_files = [f for f in os.listdir(dataset_folder) if f.endswith(".csv")]
                            ^^^^^^^^^^^^^^^^^^^^^^^^^^
FileNotFoundError: [Errno 2] No such file or directory: 'include/dataset/'
[2024-12-30T06:57:54.716+0000] {processor.py:927} WARNING - No viable dags retrieved from /opt/airflow/dags/local_to_gcs.py
[2024-12-30T06:57:54.747+0000] {processor.py:208} INFO - Processing /opt/airflow/dags/local_to_gcs.py took 0.082 seconds
[2024-12-30T06:58:25.101+0000] {processor.py:186} INFO - Started process (PID=4661) to work on /opt/airflow/dags/local_to_gcs.py
[2024-12-30T06:58:25.105+0000] {processor.py:914} INFO - Processing file /opt/airflow/dags/local_to_gcs.py for tasks to queue
[2024-12-30T06:58:25.107+0000] {logging_mixin.py:190} INFO - [2024-12-30T06:58:25.107+0000] {dagbag.py:588} INFO - Filling up the DagBag from /opt/airflow/dags/local_to_gcs.py
[2024-12-30T06:58:25.156+0000] {logging_mixin.py:190} INFO - [2024-12-30T06:58:25.149+0000] {dagbag.py:387} ERROR - Failed to import: /opt/airflow/dags/local_to_gcs.py
Traceback (most recent call last):
  File "/home/airflow/.local/lib/python3.12/site-packages/airflow/models/dagbag.py", line 383, in parse
    loader.exec_module(new_module)
  File "<frozen importlib._bootstrap_external>", line 999, in exec_module
  File "<frozen importlib._bootstrap>", line 488, in _call_with_frames_removed
  File "/opt/airflow/dags/local_to_gcs.py", line 66, in <module>
    retail_dag = retail()  # Instantiate the DAG
                 ^^^^^^^^
  File "/home/airflow/.local/lib/python3.12/site-packages/airflow/models/dag.py", line 4307, in factory
    f(**f_kwargs)
  File "/opt/airflow/dags/local_to_gcs.py", line 31, in retail
    csv_files = [f for f in os.listdir(dataset_folder) if f.endswith(".csv")]
                            ^^^^^^^^^^^^^^^^^^^^^^^^^^
FileNotFoundError: [Errno 2] No such file or directory: 'include/dataset/'
[2024-12-30T06:58:25.158+0000] {processor.py:927} WARNING - No viable dags retrieved from /opt/airflow/dags/local_to_gcs.py
[2024-12-30T06:58:25.189+0000] {processor.py:208} INFO - Processing /opt/airflow/dags/local_to_gcs.py took 0.101 seconds
[2024-12-30T06:58:55.759+0000] {processor.py:186} INFO - Started process (PID=4727) to work on /opt/airflow/dags/local_to_gcs.py
[2024-12-30T06:58:55.761+0000] {processor.py:914} INFO - Processing file /opt/airflow/dags/local_to_gcs.py for tasks to queue
[2024-12-30T06:58:55.764+0000] {logging_mixin.py:190} INFO - [2024-12-30T06:58:55.764+0000] {dagbag.py:588} INFO - Filling up the DagBag from /opt/airflow/dags/local_to_gcs.py
[2024-12-30T06:58:55.812+0000] {logging_mixin.py:190} INFO - [2024-12-30T06:58:55.805+0000] {dagbag.py:387} ERROR - Failed to import: /opt/airflow/dags/local_to_gcs.py
Traceback (most recent call last):
  File "/home/airflow/.local/lib/python3.12/site-packages/airflow/models/dagbag.py", line 383, in parse
    loader.exec_module(new_module)
  File "<frozen importlib._bootstrap_external>", line 999, in exec_module
  File "<frozen importlib._bootstrap>", line 488, in _call_with_frames_removed
  File "/opt/airflow/dags/local_to_gcs.py", line 66, in <module>
    retail_dag = retail()  # Instantiate the DAG
                 ^^^^^^^^
  File "/home/airflow/.local/lib/python3.12/site-packages/airflow/models/dag.py", line 4307, in factory
    f(**f_kwargs)
  File "/opt/airflow/dags/local_to_gcs.py", line 31, in retail
    csv_files = [f for f in os.listdir(dataset_folder) if f.endswith(".csv")]
                            ^^^^^^^^^^^^^^^^^^^^^^^^^^
FileNotFoundError: [Errno 2] No such file or directory: 'include/dataset/'
[2024-12-30T06:58:55.815+0000] {processor.py:927} WARNING - No viable dags retrieved from /opt/airflow/dags/local_to_gcs.py
[2024-12-30T06:58:55.846+0000] {processor.py:208} INFO - Processing /opt/airflow/dags/local_to_gcs.py took 0.095 seconds
[2024-12-30T06:59:26.011+0000] {processor.py:186} INFO - Started process (PID=4793) to work on /opt/airflow/dags/local_to_gcs.py
[2024-12-30T06:59:26.012+0000] {processor.py:914} INFO - Processing file /opt/airflow/dags/local_to_gcs.py for tasks to queue
[2024-12-30T06:59:26.016+0000] {logging_mixin.py:190} INFO - [2024-12-30T06:59:26.015+0000] {dagbag.py:588} INFO - Filling up the DagBag from /opt/airflow/dags/local_to_gcs.py
[2024-12-30T06:59:26.067+0000] {logging_mixin.py:190} INFO - [2024-12-30T06:59:26.057+0000] {dagbag.py:387} ERROR - Failed to import: /opt/airflow/dags/local_to_gcs.py
Traceback (most recent call last):
  File "/home/airflow/.local/lib/python3.12/site-packages/airflow/models/dagbag.py", line 383, in parse
    loader.exec_module(new_module)
  File "<frozen importlib._bootstrap_external>", line 999, in exec_module
  File "<frozen importlib._bootstrap>", line 488, in _call_with_frames_removed
  File "/opt/airflow/dags/local_to_gcs.py", line 66, in <module>
    retail_dag = retail()  # Instantiate the DAG
                 ^^^^^^^^
  File "/home/airflow/.local/lib/python3.12/site-packages/airflow/models/dag.py", line 4307, in factory
    f(**f_kwargs)
  File "/opt/airflow/dags/local_to_gcs.py", line 31, in retail
    csv_files = [f for f in os.listdir(dataset_folder) if f.endswith(".csv")]
                            ^^^^^^^^^^^^^^^^^^^^^^^^^^
FileNotFoundError: [Errno 2] No such file or directory: 'include/dataset/'
[2024-12-30T06:59:26.069+0000] {processor.py:927} WARNING - No viable dags retrieved from /opt/airflow/dags/local_to_gcs.py
[2024-12-30T06:59:26.119+0000] {processor.py:208} INFO - Processing /opt/airflow/dags/local_to_gcs.py took 0.116 seconds
[2024-12-30T06:59:56.230+0000] {processor.py:186} INFO - Started process (PID=4859) to work on /opt/airflow/dags/local_to_gcs.py
[2024-12-30T06:59:56.232+0000] {processor.py:914} INFO - Processing file /opt/airflow/dags/local_to_gcs.py for tasks to queue
[2024-12-30T06:59:56.235+0000] {logging_mixin.py:190} INFO - [2024-12-30T06:59:56.234+0000] {dagbag.py:588} INFO - Filling up the DagBag from /opt/airflow/dags/local_to_gcs.py
[2024-12-30T06:59:56.277+0000] {logging_mixin.py:190} INFO - [2024-12-30T06:59:56.270+0000] {dagbag.py:387} ERROR - Failed to import: /opt/airflow/dags/local_to_gcs.py
Traceback (most recent call last):
  File "/home/airflow/.local/lib/python3.12/site-packages/airflow/models/dagbag.py", line 383, in parse
    loader.exec_module(new_module)
  File "<frozen importlib._bootstrap_external>", line 999, in exec_module
  File "<frozen importlib._bootstrap>", line 488, in _call_with_frames_removed
  File "/opt/airflow/dags/local_to_gcs.py", line 66, in <module>
    retail_dag = retail()  # Instantiate the DAG
                 ^^^^^^^^
  File "/home/airflow/.local/lib/python3.12/site-packages/airflow/models/dag.py", line 4307, in factory
    f(**f_kwargs)
  File "/opt/airflow/dags/local_to_gcs.py", line 31, in retail
    csv_files = [f for f in os.listdir(dataset_folder) if f.endswith(".csv")]
                            ^^^^^^^^^^^^^^^^^^^^^^^^^^
FileNotFoundError: [Errno 2] No such file or directory: 'include/dataset/'
[2024-12-30T06:59:56.279+0000] {processor.py:927} WARNING - No viable dags retrieved from /opt/airflow/dags/local_to_gcs.py
[2024-12-30T06:59:56.314+0000] {processor.py:208} INFO - Processing /opt/airflow/dags/local_to_gcs.py took 0.092 seconds
[2024-12-30T07:00:26.463+0000] {processor.py:186} INFO - Started process (PID=4920) to work on /opt/airflow/dags/local_to_gcs.py
[2024-12-30T07:00:26.465+0000] {processor.py:914} INFO - Processing file /opt/airflow/dags/local_to_gcs.py for tasks to queue
[2024-12-30T07:00:26.468+0000] {logging_mixin.py:190} INFO - [2024-12-30T07:00:26.468+0000] {dagbag.py:588} INFO - Filling up the DagBag from /opt/airflow/dags/local_to_gcs.py
[2024-12-30T07:00:26.527+0000] {logging_mixin.py:190} INFO - [2024-12-30T07:00:26.516+0000] {dagbag.py:387} ERROR - Failed to import: /opt/airflow/dags/local_to_gcs.py
Traceback (most recent call last):
  File "/home/airflow/.local/lib/python3.12/site-packages/airflow/models/dagbag.py", line 383, in parse
    loader.exec_module(new_module)
  File "<frozen importlib._bootstrap_external>", line 999, in exec_module
  File "<frozen importlib._bootstrap>", line 488, in _call_with_frames_removed
  File "/opt/airflow/dags/local_to_gcs.py", line 66, in <module>
    retail_dag = retail()  # Instantiate the DAG
                 ^^^^^^^^
  File "/home/airflow/.local/lib/python3.12/site-packages/airflow/models/dag.py", line 4307, in factory
    f(**f_kwargs)
  File "/opt/airflow/dags/local_to_gcs.py", line 31, in retail
    csv_files = [f for f in os.listdir(dataset_folder) if f.endswith(".csv")]
                            ^^^^^^^^^^^^^^^^^^^^^^^^^^
FileNotFoundError: [Errno 2] No such file or directory: 'include/dataset/'
[2024-12-30T07:00:26.531+0000] {processor.py:927} WARNING - No viable dags retrieved from /opt/airflow/dags/local_to_gcs.py
[2024-12-30T07:00:26.575+0000] {processor.py:208} INFO - Processing /opt/airflow/dags/local_to_gcs.py took 0.125 seconds
[2024-12-30T07:00:56.900+0000] {processor.py:186} INFO - Started process (PID=4986) to work on /opt/airflow/dags/local_to_gcs.py
[2024-12-30T07:00:56.901+0000] {processor.py:914} INFO - Processing file /opt/airflow/dags/local_to_gcs.py for tasks to queue
[2024-12-30T07:00:56.904+0000] {logging_mixin.py:190} INFO - [2024-12-30T07:00:56.903+0000] {dagbag.py:588} INFO - Filling up the DagBag from /opt/airflow/dags/local_to_gcs.py
[2024-12-30T07:00:56.951+0000] {logging_mixin.py:190} INFO - [2024-12-30T07:00:56.940+0000] {dagbag.py:387} ERROR - Failed to import: /opt/airflow/dags/local_to_gcs.py
Traceback (most recent call last):
  File "/home/airflow/.local/lib/python3.12/site-packages/airflow/models/dagbag.py", line 383, in parse
    loader.exec_module(new_module)
  File "<frozen importlib._bootstrap_external>", line 999, in exec_module
  File "<frozen importlib._bootstrap>", line 488, in _call_with_frames_removed
  File "/opt/airflow/dags/local_to_gcs.py", line 66, in <module>
    retail_dag = retail()  # Instantiate the DAG
                 ^^^^^^^^
  File "/home/airflow/.local/lib/python3.12/site-packages/airflow/models/dag.py", line 4307, in factory
    f(**f_kwargs)
  File "/opt/airflow/dags/local_to_gcs.py", line 31, in retail
    csv_files = [f for f in os.listdir(dataset_folder) if f.endswith(".csv")]
                            ^^^^^^^^^^^^^^^^^^^^^^^^^^
FileNotFoundError: [Errno 2] No such file or directory: 'include/dataset/'
[2024-12-30T07:00:56.953+0000] {processor.py:927} WARNING - No viable dags retrieved from /opt/airflow/dags/local_to_gcs.py
[2024-12-30T07:00:56.988+0000] {processor.py:208} INFO - Processing /opt/airflow/dags/local_to_gcs.py took 0.102 seconds
[2024-12-30T07:01:27.280+0000] {processor.py:186} INFO - Started process (PID=5048) to work on /opt/airflow/dags/local_to_gcs.py
[2024-12-30T07:01:27.282+0000] {processor.py:914} INFO - Processing file /opt/airflow/dags/local_to_gcs.py for tasks to queue
[2024-12-30T07:01:27.289+0000] {logging_mixin.py:190} INFO - [2024-12-30T07:01:27.289+0000] {dagbag.py:588} INFO - Filling up the DagBag from /opt/airflow/dags/local_to_gcs.py
[2024-12-30T07:01:27.368+0000] {logging_mixin.py:190} INFO - [2024-12-30T07:01:27.359+0000] {dagbag.py:387} ERROR - Failed to import: /opt/airflow/dags/local_to_gcs.py
Traceback (most recent call last):
  File "/home/airflow/.local/lib/python3.12/site-packages/airflow/models/dagbag.py", line 383, in parse
    loader.exec_module(new_module)
  File "<frozen importlib._bootstrap_external>", line 999, in exec_module
  File "<frozen importlib._bootstrap>", line 488, in _call_with_frames_removed
  File "/opt/airflow/dags/local_to_gcs.py", line 66, in <module>
    retail_dag = retail()  # Instantiate the DAG
                 ^^^^^^^^
  File "/home/airflow/.local/lib/python3.12/site-packages/airflow/models/dag.py", line 4307, in factory
    f(**f_kwargs)
  File "/opt/airflow/dags/local_to_gcs.py", line 31, in retail
    csv_files = [f for f in os.listdir(dataset_folder) if f.endswith(".csv")]
                            ^^^^^^^^^^^^^^^^^^^^^^^^^^
FileNotFoundError: [Errno 2] No such file or directory: 'include/dataset/'
[2024-12-30T07:01:27.372+0000] {processor.py:927} WARNING - No viable dags retrieved from /opt/airflow/dags/local_to_gcs.py
[2024-12-30T07:01:27.426+0000] {processor.py:208} INFO - Processing /opt/airflow/dags/local_to_gcs.py took 0.154 seconds
[2024-12-30T07:01:57.972+0000] {processor.py:186} INFO - Started process (PID=5114) to work on /opt/airflow/dags/local_to_gcs.py
[2024-12-30T07:01:57.977+0000] {processor.py:914} INFO - Processing file /opt/airflow/dags/local_to_gcs.py for tasks to queue
[2024-12-30T07:01:57.981+0000] {logging_mixin.py:190} INFO - [2024-12-30T07:01:57.980+0000] {dagbag.py:588} INFO - Filling up the DagBag from /opt/airflow/dags/local_to_gcs.py
[2024-12-30T07:01:58.057+0000] {logging_mixin.py:190} INFO - [2024-12-30T07:01:58.042+0000] {dagbag.py:387} ERROR - Failed to import: /opt/airflow/dags/local_to_gcs.py
Traceback (most recent call last):
  File "/home/airflow/.local/lib/python3.12/site-packages/airflow/models/dagbag.py", line 383, in parse
    loader.exec_module(new_module)
  File "<frozen importlib._bootstrap_external>", line 999, in exec_module
  File "<frozen importlib._bootstrap>", line 488, in _call_with_frames_removed
  File "/opt/airflow/dags/local_to_gcs.py", line 66, in <module>
    retail_dag = retail()  # Instantiate the DAG
                 ^^^^^^^^
  File "/home/airflow/.local/lib/python3.12/site-packages/airflow/models/dag.py", line 4307, in factory
    f(**f_kwargs)
  File "/opt/airflow/dags/local_to_gcs.py", line 31, in retail
    csv_files = [f for f in os.listdir(dataset_folder) if f.endswith(".csv")]
                            ^^^^^^^^^^^^^^^^^^^^^^^^^^
FileNotFoundError: [Errno 2] No such file or directory: 'include/dataset/'
[2024-12-30T07:01:58.060+0000] {processor.py:927} WARNING - No viable dags retrieved from /opt/airflow/dags/local_to_gcs.py
[2024-12-30T07:01:58.124+0000] {processor.py:208} INFO - Processing /opt/airflow/dags/local_to_gcs.py took 0.167 seconds
[2024-12-30T07:02:28.228+0000] {processor.py:186} INFO - Started process (PID=5180) to work on /opt/airflow/dags/local_to_gcs.py
[2024-12-30T07:02:28.230+0000] {processor.py:914} INFO - Processing file /opt/airflow/dags/local_to_gcs.py for tasks to queue
[2024-12-30T07:02:28.235+0000] {logging_mixin.py:190} INFO - [2024-12-30T07:02:28.233+0000] {dagbag.py:588} INFO - Filling up the DagBag from /opt/airflow/dags/local_to_gcs.py
[2024-12-30T07:02:28.282+0000] {logging_mixin.py:190} INFO - [2024-12-30T07:02:28.274+0000] {dagbag.py:387} ERROR - Failed to import: /opt/airflow/dags/local_to_gcs.py
Traceback (most recent call last):
  File "/home/airflow/.local/lib/python3.12/site-packages/airflow/models/dagbag.py", line 383, in parse
    loader.exec_module(new_module)
  File "<frozen importlib._bootstrap_external>", line 999, in exec_module
  File "<frozen importlib._bootstrap>", line 488, in _call_with_frames_removed
  File "/opt/airflow/dags/local_to_gcs.py", line 66, in <module>
    retail_dag = retail()  # Instantiate the DAG
                 ^^^^^^^^
  File "/home/airflow/.local/lib/python3.12/site-packages/airflow/models/dag.py", line 4307, in factory
    f(**f_kwargs)
  File "/opt/airflow/dags/local_to_gcs.py", line 31, in retail
    csv_files = [f for f in os.listdir(dataset_folder) if f.endswith(".csv")]
                            ^^^^^^^^^^^^^^^^^^^^^^^^^^
FileNotFoundError: [Errno 2] No such file or directory: 'include/dataset/'
[2024-12-30T07:02:28.285+0000] {processor.py:927} WARNING - No viable dags retrieved from /opt/airflow/dags/local_to_gcs.py
[2024-12-30T07:02:28.319+0000] {processor.py:208} INFO - Processing /opt/airflow/dags/local_to_gcs.py took 0.099 seconds
[2024-12-30T07:02:58.605+0000] {processor.py:186} INFO - Started process (PID=5246) to work on /opt/airflow/dags/local_to_gcs.py
[2024-12-30T07:02:58.606+0000] {processor.py:914} INFO - Processing file /opt/airflow/dags/local_to_gcs.py for tasks to queue
[2024-12-30T07:02:58.609+0000] {logging_mixin.py:190} INFO - [2024-12-30T07:02:58.608+0000] {dagbag.py:588} INFO - Filling up the DagBag from /opt/airflow/dags/local_to_gcs.py
[2024-12-30T07:02:58.647+0000] {logging_mixin.py:190} INFO - [2024-12-30T07:02:58.637+0000] {dagbag.py:387} ERROR - Failed to import: /opt/airflow/dags/local_to_gcs.py
Traceback (most recent call last):
  File "/home/airflow/.local/lib/python3.12/site-packages/airflow/models/dagbag.py", line 383, in parse
    loader.exec_module(new_module)
  File "<frozen importlib._bootstrap_external>", line 999, in exec_module
  File "<frozen importlib._bootstrap>", line 488, in _call_with_frames_removed
  File "/opt/airflow/dags/local_to_gcs.py", line 66, in <module>
    retail_dag = retail()  # Instantiate the DAG
                 ^^^^^^^^
  File "/home/airflow/.local/lib/python3.12/site-packages/airflow/models/dag.py", line 4307, in factory
    f(**f_kwargs)
  File "/opt/airflow/dags/local_to_gcs.py", line 31, in retail
    csv_files = [f for f in os.listdir(dataset_folder) if f.endswith(".csv")]
                            ^^^^^^^^^^^^^^^^^^^^^^^^^^
FileNotFoundError: [Errno 2] No such file or directory: 'include/dataset/'
[2024-12-30T07:02:58.651+0000] {processor.py:927} WARNING - No viable dags retrieved from /opt/airflow/dags/local_to_gcs.py
[2024-12-30T07:02:58.685+0000] {processor.py:208} INFO - Processing /opt/airflow/dags/local_to_gcs.py took 0.088 seconds
[2024-12-30T07:03:28.775+0000] {processor.py:186} INFO - Started process (PID=5307) to work on /opt/airflow/dags/local_to_gcs.py
[2024-12-30T07:03:28.776+0000] {processor.py:914} INFO - Processing file /opt/airflow/dags/local_to_gcs.py for tasks to queue
[2024-12-30T07:03:28.778+0000] {logging_mixin.py:190} INFO - [2024-12-30T07:03:28.778+0000] {dagbag.py:588} INFO - Filling up the DagBag from /opt/airflow/dags/local_to_gcs.py
[2024-12-30T07:03:28.816+0000] {logging_mixin.py:190} INFO - [2024-12-30T07:03:28.810+0000] {dagbag.py:387} ERROR - Failed to import: /opt/airflow/dags/local_to_gcs.py
Traceback (most recent call last):
  File "/home/airflow/.local/lib/python3.12/site-packages/airflow/models/dagbag.py", line 383, in parse
    loader.exec_module(new_module)
  File "<frozen importlib._bootstrap_external>", line 999, in exec_module
  File "<frozen importlib._bootstrap>", line 488, in _call_with_frames_removed
  File "/opt/airflow/dags/local_to_gcs.py", line 66, in <module>
    retail_dag = retail()  # Instantiate the DAG
                 ^^^^^^^^
  File "/home/airflow/.local/lib/python3.12/site-packages/airflow/models/dag.py", line 4307, in factory
    f(**f_kwargs)
  File "/opt/airflow/dags/local_to_gcs.py", line 31, in retail
    csv_files = [f for f in os.listdir(dataset_folder) if f.endswith(".csv")]
                            ^^^^^^^^^^^^^^^^^^^^^^^^^^
FileNotFoundError: [Errno 2] No such file or directory: 'include/dataset/'
[2024-12-30T07:03:28.818+0000] {processor.py:927} WARNING - No viable dags retrieved from /opt/airflow/dags/local_to_gcs.py
[2024-12-30T07:03:28.855+0000] {processor.py:208} INFO - Processing /opt/airflow/dags/local_to_gcs.py took 0.087 seconds
[2024-12-30T07:03:59.080+0000] {processor.py:186} INFO - Started process (PID=5373) to work on /opt/airflow/dags/local_to_gcs.py
[2024-12-30T07:03:59.082+0000] {processor.py:914} INFO - Processing file /opt/airflow/dags/local_to_gcs.py for tasks to queue
[2024-12-30T07:03:59.086+0000] {logging_mixin.py:190} INFO - [2024-12-30T07:03:59.085+0000] {dagbag.py:588} INFO - Filling up the DagBag from /opt/airflow/dags/local_to_gcs.py
[2024-12-30T07:03:59.147+0000] {logging_mixin.py:190} INFO - [2024-12-30T07:03:59.133+0000] {dagbag.py:387} ERROR - Failed to import: /opt/airflow/dags/local_to_gcs.py
Traceback (most recent call last):
  File "/home/airflow/.local/lib/python3.12/site-packages/airflow/models/dagbag.py", line 383, in parse
    loader.exec_module(new_module)
  File "<frozen importlib._bootstrap_external>", line 999, in exec_module
  File "<frozen importlib._bootstrap>", line 488, in _call_with_frames_removed
  File "/opt/airflow/dags/local_to_gcs.py", line 66, in <module>
    retail_dag = retail()  # Instantiate the DAG
                 ^^^^^^^^
  File "/home/airflow/.local/lib/python3.12/site-packages/airflow/models/dag.py", line 4307, in factory
    f(**f_kwargs)
  File "/opt/airflow/dags/local_to_gcs.py", line 31, in retail
    csv_files = [f for f in os.listdir(dataset_folder) if f.endswith(".csv")]
                            ^^^^^^^^^^^^^^^^^^^^^^^^^^
FileNotFoundError: [Errno 2] No such file or directory: 'include/dataset/'
[2024-12-30T07:03:59.149+0000] {processor.py:927} WARNING - No viable dags retrieved from /opt/airflow/dags/local_to_gcs.py
[2024-12-30T07:03:59.188+0000] {processor.py:208} INFO - Processing /opt/airflow/dags/local_to_gcs.py took 0.120 seconds
[2024-12-30T07:04:29.272+0000] {processor.py:186} INFO - Started process (PID=5438) to work on /opt/airflow/dags/local_to_gcs.py
[2024-12-30T07:04:29.274+0000] {processor.py:914} INFO - Processing file /opt/airflow/dags/local_to_gcs.py for tasks to queue
[2024-12-30T07:04:29.278+0000] {logging_mixin.py:190} INFO - [2024-12-30T07:04:29.277+0000] {dagbag.py:588} INFO - Filling up the DagBag from /opt/airflow/dags/local_to_gcs.py
[2024-12-30T07:04:29.321+0000] {logging_mixin.py:190} INFO - [2024-12-30T07:04:29.316+0000] {dagbag.py:387} ERROR - Failed to import: /opt/airflow/dags/local_to_gcs.py
Traceback (most recent call last):
  File "/home/airflow/.local/lib/python3.12/site-packages/airflow/models/dagbag.py", line 383, in parse
    loader.exec_module(new_module)
  File "<frozen importlib._bootstrap_external>", line 999, in exec_module
  File "<frozen importlib._bootstrap>", line 488, in _call_with_frames_removed
  File "/opt/airflow/dags/local_to_gcs.py", line 66, in <module>
    retail_dag = retail()  # Instantiate the DAG
                 ^^^^^^^^
  File "/home/airflow/.local/lib/python3.12/site-packages/airflow/models/dag.py", line 4307, in factory
    f(**f_kwargs)
  File "/opt/airflow/dags/local_to_gcs.py", line 31, in retail
    csv_files = [f for f in os.listdir(dataset_folder) if f.endswith(".csv")]
                            ^^^^^^^^^^^^^^^^^^^^^^^^^^
FileNotFoundError: [Errno 2] No such file or directory: 'include/dataset/'
[2024-12-30T07:04:29.323+0000] {processor.py:927} WARNING - No viable dags retrieved from /opt/airflow/dags/local_to_gcs.py
[2024-12-30T07:04:29.355+0000] {processor.py:208} INFO - Processing /opt/airflow/dags/local_to_gcs.py took 0.090 seconds
[2024-12-30T07:04:59.582+0000] {processor.py:186} INFO - Started process (PID=5502) to work on /opt/airflow/dags/local_to_gcs.py
[2024-12-30T07:04:59.585+0000] {processor.py:914} INFO - Processing file /opt/airflow/dags/local_to_gcs.py for tasks to queue
[2024-12-30T07:04:59.588+0000] {logging_mixin.py:190} INFO - [2024-12-30T07:04:59.587+0000] {dagbag.py:588} INFO - Filling up the DagBag from /opt/airflow/dags/local_to_gcs.py
[2024-12-30T07:04:59.628+0000] {logging_mixin.py:190} INFO - [2024-12-30T07:04:59.621+0000] {dagbag.py:387} ERROR - Failed to import: /opt/airflow/dags/local_to_gcs.py
Traceback (most recent call last):
  File "/home/airflow/.local/lib/python3.12/site-packages/airflow/models/dagbag.py", line 383, in parse
    loader.exec_module(new_module)
  File "<frozen importlib._bootstrap_external>", line 999, in exec_module
  File "<frozen importlib._bootstrap>", line 488, in _call_with_frames_removed
  File "/opt/airflow/dags/local_to_gcs.py", line 66, in <module>
    retail_dag = retail()  # Instantiate the DAG
                 ^^^^^^^^
  File "/home/airflow/.local/lib/python3.12/site-packages/airflow/models/dag.py", line 4307, in factory
    f(**f_kwargs)
  File "/opt/airflow/dags/local_to_gcs.py", line 31, in retail
    csv_files = [f for f in os.listdir(dataset_folder) if f.endswith(".csv")]
                            ^^^^^^^^^^^^^^^^^^^^^^^^^^
FileNotFoundError: [Errno 2] No such file or directory: 'include/dataset/'
[2024-12-30T07:04:59.630+0000] {processor.py:927} WARNING - No viable dags retrieved from /opt/airflow/dags/local_to_gcs.py
[2024-12-30T07:04:59.660+0000] {processor.py:208} INFO - Processing /opt/airflow/dags/local_to_gcs.py took 0.087 seconds
[2024-12-30T07:05:30.394+0000] {processor.py:186} INFO - Started process (PID=5567) to work on /opt/airflow/dags/local_to_gcs.py
[2024-12-30T07:05:30.396+0000] {processor.py:914} INFO - Processing file /opt/airflow/dags/local_to_gcs.py for tasks to queue
[2024-12-30T07:05:30.399+0000] {logging_mixin.py:190} INFO - [2024-12-30T07:05:30.398+0000] {dagbag.py:588} INFO - Filling up the DagBag from /opt/airflow/dags/local_to_gcs.py
[2024-12-30T07:05:30.444+0000] {logging_mixin.py:190} INFO - [2024-12-30T07:05:30.434+0000] {dagbag.py:387} ERROR - Failed to import: /opt/airflow/dags/local_to_gcs.py
Traceback (most recent call last):
  File "/home/airflow/.local/lib/python3.12/site-packages/airflow/models/dagbag.py", line 383, in parse
    loader.exec_module(new_module)
  File "<frozen importlib._bootstrap_external>", line 999, in exec_module
  File "<frozen importlib._bootstrap>", line 488, in _call_with_frames_removed
  File "/opt/airflow/dags/local_to_gcs.py", line 66, in <module>
    retail_dag = retail()  # Instantiate the DAG
                 ^^^^^^^^
  File "/home/airflow/.local/lib/python3.12/site-packages/airflow/models/dag.py", line 4307, in factory
    f(**f_kwargs)
  File "/opt/airflow/dags/local_to_gcs.py", line 31, in retail
    csv_files = [f for f in os.listdir(dataset_folder) if f.endswith(".csv")]
                            ^^^^^^^^^^^^^^^^^^^^^^^^^^
FileNotFoundError: [Errno 2] No such file or directory: 'include/dataset/'
[2024-12-30T07:05:30.446+0000] {processor.py:927} WARNING - No viable dags retrieved from /opt/airflow/dags/local_to_gcs.py
[2024-12-30T07:05:30.488+0000] {processor.py:208} INFO - Processing /opt/airflow/dags/local_to_gcs.py took 0.106 seconds
[2024-12-30T07:06:00.637+0000] {processor.py:186} INFO - Started process (PID=5628) to work on /opt/airflow/dags/local_to_gcs.py
[2024-12-30T07:06:00.638+0000] {processor.py:914} INFO - Processing file /opt/airflow/dags/local_to_gcs.py for tasks to queue
[2024-12-30T07:06:00.640+0000] {logging_mixin.py:190} INFO - [2024-12-30T07:06:00.640+0000] {dagbag.py:588} INFO - Filling up the DagBag from /opt/airflow/dags/local_to_gcs.py
[2024-12-30T07:06:00.674+0000] {logging_mixin.py:190} INFO - [2024-12-30T07:06:00.668+0000] {dagbag.py:387} ERROR - Failed to import: /opt/airflow/dags/local_to_gcs.py
Traceback (most recent call last):
  File "/home/airflow/.local/lib/python3.12/site-packages/airflow/models/dagbag.py", line 383, in parse
    loader.exec_module(new_module)
  File "<frozen importlib._bootstrap_external>", line 999, in exec_module
  File "<frozen importlib._bootstrap>", line 488, in _call_with_frames_removed
  File "/opt/airflow/dags/local_to_gcs.py", line 66, in <module>
    retail_dag = retail()  # Instantiate the DAG
                 ^^^^^^^^
  File "/home/airflow/.local/lib/python3.12/site-packages/airflow/models/dag.py", line 4307, in factory
    f(**f_kwargs)
  File "/opt/airflow/dags/local_to_gcs.py", line 31, in retail
    csv_files = [f for f in os.listdir(dataset_folder) if f.endswith(".csv")]
                            ^^^^^^^^^^^^^^^^^^^^^^^^^^
FileNotFoundError: [Errno 2] No such file or directory: 'include/dataset/'
[2024-12-30T07:06:00.676+0000] {processor.py:927} WARNING - No viable dags retrieved from /opt/airflow/dags/local_to_gcs.py
[2024-12-30T07:06:00.704+0000] {processor.py:208} INFO - Processing /opt/airflow/dags/local_to_gcs.py took 0.076 seconds
[2024-12-30T07:06:30.818+0000] {processor.py:186} INFO - Started process (PID=5688) to work on /opt/airflow/dags/local_to_gcs.py
[2024-12-30T07:06:30.820+0000] {processor.py:914} INFO - Processing file /opt/airflow/dags/local_to_gcs.py for tasks to queue
[2024-12-30T07:06:30.822+0000] {logging_mixin.py:190} INFO - [2024-12-30T07:06:30.821+0000] {dagbag.py:588} INFO - Filling up the DagBag from /opt/airflow/dags/local_to_gcs.py
[2024-12-30T07:06:30.858+0000] {logging_mixin.py:190} INFO - [2024-12-30T07:06:30.852+0000] {dagbag.py:387} ERROR - Failed to import: /opt/airflow/dags/local_to_gcs.py
Traceback (most recent call last):
  File "/home/airflow/.local/lib/python3.12/site-packages/airflow/models/dagbag.py", line 383, in parse
    loader.exec_module(new_module)
  File "<frozen importlib._bootstrap_external>", line 999, in exec_module
  File "<frozen importlib._bootstrap>", line 488, in _call_with_frames_removed
  File "/opt/airflow/dags/local_to_gcs.py", line 66, in <module>
    retail_dag = retail()  # Instantiate the DAG
                 ^^^^^^^^
  File "/home/airflow/.local/lib/python3.12/site-packages/airflow/models/dag.py", line 4307, in factory
    f(**f_kwargs)
  File "/opt/airflow/dags/local_to_gcs.py", line 31, in retail
    csv_files = [f for f in os.listdir(dataset_folder) if f.endswith(".csv")]
                            ^^^^^^^^^^^^^^^^^^^^^^^^^^
FileNotFoundError: [Errno 2] No such file or directory: 'include/dataset/'
[2024-12-30T07:06:30.860+0000] {processor.py:927} WARNING - No viable dags retrieved from /opt/airflow/dags/local_to_gcs.py
[2024-12-30T07:06:30.888+0000] {processor.py:208} INFO - Processing /opt/airflow/dags/local_to_gcs.py took 0.078 seconds
[2024-12-30T07:07:01.022+0000] {processor.py:186} INFO - Started process (PID=5754) to work on /opt/airflow/dags/local_to_gcs.py
[2024-12-30T07:07:01.025+0000] {processor.py:914} INFO - Processing file /opt/airflow/dags/local_to_gcs.py for tasks to queue
[2024-12-30T07:07:01.028+0000] {logging_mixin.py:190} INFO - [2024-12-30T07:07:01.027+0000] {dagbag.py:588} INFO - Filling up the DagBag from /opt/airflow/dags/local_to_gcs.py
[2024-12-30T07:07:01.062+0000] {logging_mixin.py:190} INFO - [2024-12-30T07:07:01.057+0000] {dagbag.py:387} ERROR - Failed to import: /opt/airflow/dags/local_to_gcs.py
Traceback (most recent call last):
  File "/home/airflow/.local/lib/python3.12/site-packages/airflow/models/dagbag.py", line 383, in parse
    loader.exec_module(new_module)
  File "<frozen importlib._bootstrap_external>", line 999, in exec_module
  File "<frozen importlib._bootstrap>", line 488, in _call_with_frames_removed
  File "/opt/airflow/dags/local_to_gcs.py", line 66, in <module>
    retail_dag = retail()  # Instantiate the DAG
                 ^^^^^^^^
  File "/home/airflow/.local/lib/python3.12/site-packages/airflow/models/dag.py", line 4307, in factory
    f(**f_kwargs)
  File "/opt/airflow/dags/local_to_gcs.py", line 31, in retail
    csv_files = [f for f in os.listdir(dataset_folder) if f.endswith(".csv")]
                            ^^^^^^^^^^^^^^^^^^^^^^^^^^
FileNotFoundError: [Errno 2] No such file or directory: 'include/dataset/'
[2024-12-30T07:07:01.064+0000] {processor.py:927} WARNING - No viable dags retrieved from /opt/airflow/dags/local_to_gcs.py
[2024-12-30T07:07:01.088+0000] {processor.py:208} INFO - Processing /opt/airflow/dags/local_to_gcs.py took 0.074 seconds
[2024-12-30T07:07:31.439+0000] {processor.py:186} INFO - Started process (PID=5820) to work on /opt/airflow/dags/local_to_gcs.py
[2024-12-30T07:07:31.440+0000] {processor.py:914} INFO - Processing file /opt/airflow/dags/local_to_gcs.py for tasks to queue
[2024-12-30T07:07:31.442+0000] {logging_mixin.py:190} INFO - [2024-12-30T07:07:31.442+0000] {dagbag.py:588} INFO - Filling up the DagBag from /opt/airflow/dags/local_to_gcs.py
[2024-12-30T07:07:31.471+0000] {logging_mixin.py:190} INFO - [2024-12-30T07:07:31.465+0000] {dagbag.py:387} ERROR - Failed to import: /opt/airflow/dags/local_to_gcs.py
Traceback (most recent call last):
  File "/home/airflow/.local/lib/python3.12/site-packages/airflow/models/dagbag.py", line 383, in parse
    loader.exec_module(new_module)
  File "<frozen importlib._bootstrap_external>", line 999, in exec_module
  File "<frozen importlib._bootstrap>", line 488, in _call_with_frames_removed
  File "/opt/airflow/dags/local_to_gcs.py", line 66, in <module>
    retail_dag = retail()  # Instantiate the DAG
                 ^^^^^^^^
  File "/home/airflow/.local/lib/python3.12/site-packages/airflow/models/dag.py", line 4307, in factory
    f(**f_kwargs)
  File "/opt/airflow/dags/local_to_gcs.py", line 31, in retail
    csv_files = [f for f in os.listdir(dataset_folder) if f.endswith(".csv")]
                            ^^^^^^^^^^^^^^^^^^^^^^^^^^
FileNotFoundError: [Errno 2] No such file or directory: 'include/dataset/'
[2024-12-30T07:07:31.473+0000] {processor.py:927} WARNING - No viable dags retrieved from /opt/airflow/dags/local_to_gcs.py
[2024-12-30T07:07:31.507+0000] {processor.py:208} INFO - Processing /opt/airflow/dags/local_to_gcs.py took 0.075 seconds
[2024-12-30T07:08:01.887+0000] {processor.py:186} INFO - Started process (PID=5886) to work on /opt/airflow/dags/local_to_gcs.py
[2024-12-30T07:08:01.888+0000] {processor.py:914} INFO - Processing file /opt/airflow/dags/local_to_gcs.py for tasks to queue
[2024-12-30T07:08:01.890+0000] {logging_mixin.py:190} INFO - [2024-12-30T07:08:01.890+0000] {dagbag.py:588} INFO - Filling up the DagBag from /opt/airflow/dags/local_to_gcs.py
[2024-12-30T07:08:01.937+0000] {logging_mixin.py:190} INFO - [2024-12-30T07:08:01.928+0000] {dagbag.py:387} ERROR - Failed to import: /opt/airflow/dags/local_to_gcs.py
Traceback (most recent call last):
  File "/home/airflow/.local/lib/python3.12/site-packages/airflow/models/dagbag.py", line 383, in parse
    loader.exec_module(new_module)
  File "<frozen importlib._bootstrap_external>", line 999, in exec_module
  File "<frozen importlib._bootstrap>", line 488, in _call_with_frames_removed
  File "/opt/airflow/dags/local_to_gcs.py", line 66, in <module>
    retail_dag = retail()  # Instantiate the DAG
                 ^^^^^^^^
  File "/home/airflow/.local/lib/python3.12/site-packages/airflow/models/dag.py", line 4307, in factory
    f(**f_kwargs)
  File "/opt/airflow/dags/local_to_gcs.py", line 31, in retail
    csv_files = [f for f in os.listdir(dataset_folder) if f.endswith(".csv")]
                            ^^^^^^^^^^^^^^^^^^^^^^^^^^
FileNotFoundError: [Errno 2] No such file or directory: 'include/dataset/'
[2024-12-30T07:08:01.941+0000] {processor.py:927} WARNING - No viable dags retrieved from /opt/airflow/dags/local_to_gcs.py
[2024-12-30T07:08:01.987+0000] {processor.py:208} INFO - Processing /opt/airflow/dags/local_to_gcs.py took 0.110 seconds
[2024-12-30T07:08:32.225+0000] {processor.py:186} INFO - Started process (PID=5952) to work on /opt/airflow/dags/local_to_gcs.py
[2024-12-30T07:08:32.227+0000] {processor.py:914} INFO - Processing file /opt/airflow/dags/local_to_gcs.py for tasks to queue
[2024-12-30T07:08:32.229+0000] {logging_mixin.py:190} INFO - [2024-12-30T07:08:32.229+0000] {dagbag.py:588} INFO - Filling up the DagBag from /opt/airflow/dags/local_to_gcs.py
[2024-12-30T07:08:32.261+0000] {logging_mixin.py:190} INFO - [2024-12-30T07:08:32.254+0000] {dagbag.py:387} ERROR - Failed to import: /opt/airflow/dags/local_to_gcs.py
Traceback (most recent call last):
  File "/home/airflow/.local/lib/python3.12/site-packages/airflow/models/dagbag.py", line 383, in parse
    loader.exec_module(new_module)
  File "<frozen importlib._bootstrap_external>", line 999, in exec_module
  File "<frozen importlib._bootstrap>", line 488, in _call_with_frames_removed
  File "/opt/airflow/dags/local_to_gcs.py", line 66, in <module>
    retail_dag = retail()  # Instantiate the DAG
                 ^^^^^^^^
  File "/home/airflow/.local/lib/python3.12/site-packages/airflow/models/dag.py", line 4307, in factory
    f(**f_kwargs)
  File "/opt/airflow/dags/local_to_gcs.py", line 31, in retail
    csv_files = [f for f in os.listdir(dataset_folder) if f.endswith(".csv")]
                            ^^^^^^^^^^^^^^^^^^^^^^^^^^
FileNotFoundError: [Errno 2] No such file or directory: 'include/dataset/'
[2024-12-30T07:08:32.263+0000] {processor.py:927} WARNING - No viable dags retrieved from /opt/airflow/dags/local_to_gcs.py
[2024-12-30T07:08:32.297+0000] {processor.py:208} INFO - Processing /opt/airflow/dags/local_to_gcs.py took 0.085 seconds
[2024-12-30T07:09:02.796+0000] {processor.py:186} INFO - Started process (PID=6017) to work on /opt/airflow/dags/local_to_gcs.py
[2024-12-30T07:09:02.798+0000] {processor.py:914} INFO - Processing file /opt/airflow/dags/local_to_gcs.py for tasks to queue
[2024-12-30T07:09:02.803+0000] {logging_mixin.py:190} INFO - [2024-12-30T07:09:02.802+0000] {dagbag.py:588} INFO - Filling up the DagBag from /opt/airflow/dags/local_to_gcs.py
[2024-12-30T07:09:02.866+0000] {logging_mixin.py:190} INFO - [2024-12-30T07:09:02.857+0000] {dagbag.py:387} ERROR - Failed to import: /opt/airflow/dags/local_to_gcs.py
Traceback (most recent call last):
  File "/home/airflow/.local/lib/python3.12/site-packages/airflow/models/dagbag.py", line 383, in parse
    loader.exec_module(new_module)
  File "<frozen importlib._bootstrap_external>", line 999, in exec_module
  File "<frozen importlib._bootstrap>", line 488, in _call_with_frames_removed
  File "/opt/airflow/dags/local_to_gcs.py", line 66, in <module>
    retail_dag = retail()  # Instantiate the DAG
                 ^^^^^^^^
  File "/home/airflow/.local/lib/python3.12/site-packages/airflow/models/dag.py", line 4307, in factory
    f(**f_kwargs)
  File "/opt/airflow/dags/local_to_gcs.py", line 31, in retail
    csv_files = [f for f in os.listdir(dataset_folder) if f.endswith(".csv")]
                            ^^^^^^^^^^^^^^^^^^^^^^^^^^
FileNotFoundError: [Errno 2] No such file or directory: 'include/dataset/'
[2024-12-30T07:09:02.869+0000] {processor.py:927} WARNING - No viable dags retrieved from /opt/airflow/dags/local_to_gcs.py
[2024-12-30T07:09:02.919+0000] {processor.py:208} INFO - Processing /opt/airflow/dags/local_to_gcs.py took 0.135 seconds
[2024-12-30T07:09:33.612+0000] {processor.py:186} INFO - Started process (PID=6081) to work on /opt/airflow/dags/local_to_gcs.py
[2024-12-30T07:09:33.613+0000] {processor.py:914} INFO - Processing file /opt/airflow/dags/local_to_gcs.py for tasks to queue
[2024-12-30T07:09:33.615+0000] {logging_mixin.py:190} INFO - [2024-12-30T07:09:33.615+0000] {dagbag.py:588} INFO - Filling up the DagBag from /opt/airflow/dags/local_to_gcs.py
[2024-12-30T07:09:33.647+0000] {logging_mixin.py:190} INFO - [2024-12-30T07:09:33.642+0000] {dagbag.py:387} ERROR - Failed to import: /opt/airflow/dags/local_to_gcs.py
Traceback (most recent call last):
  File "/home/airflow/.local/lib/python3.12/site-packages/airflow/models/dagbag.py", line 383, in parse
    loader.exec_module(new_module)
  File "<frozen importlib._bootstrap_external>", line 999, in exec_module
  File "<frozen importlib._bootstrap>", line 488, in _call_with_frames_removed
  File "/opt/airflow/dags/local_to_gcs.py", line 66, in <module>
    retail_dag = retail()  # Instantiate the DAG
                 ^^^^^^^^
  File "/home/airflow/.local/lib/python3.12/site-packages/airflow/models/dag.py", line 4307, in factory
    f(**f_kwargs)
  File "/opt/airflow/dags/local_to_gcs.py", line 31, in retail
    csv_files = [f for f in os.listdir(dataset_folder) if f.endswith(".csv")]
                            ^^^^^^^^^^^^^^^^^^^^^^^^^^
FileNotFoundError: [Errno 2] No such file or directory: 'include/dataset/'
[2024-12-30T07:09:33.649+0000] {processor.py:927} WARNING - No viable dags retrieved from /opt/airflow/dags/local_to_gcs.py
[2024-12-30T07:09:33.677+0000] {processor.py:208} INFO - Processing /opt/airflow/dags/local_to_gcs.py took 0.073 seconds
[2024-12-30T07:10:05.550+0000] {processor.py:186} INFO - Started process (PID=6147) to work on /opt/airflow/dags/local_to_gcs.py
[2024-12-30T07:10:05.552+0000] {processor.py:914} INFO - Processing file /opt/airflow/dags/local_to_gcs.py for tasks to queue
[2024-12-30T07:10:05.556+0000] {logging_mixin.py:190} INFO - [2024-12-30T07:10:05.556+0000] {dagbag.py:588} INFO - Filling up the DagBag from /opt/airflow/dags/local_to_gcs.py
[2024-12-30T07:10:05.642+0000] {logging_mixin.py:190} INFO - [2024-12-30T07:10:05.618+0000] {dagbag.py:387} ERROR - Failed to import: /opt/airflow/dags/local_to_gcs.py
Traceback (most recent call last):
  File "/home/airflow/.local/lib/python3.12/site-packages/airflow/models/dagbag.py", line 383, in parse
    loader.exec_module(new_module)
  File "<frozen importlib._bootstrap_external>", line 999, in exec_module
  File "<frozen importlib._bootstrap>", line 488, in _call_with_frames_removed
  File "/opt/airflow/dags/local_to_gcs.py", line 66, in <module>
    retail_dag = retail()  # Instantiate the DAG
                 ^^^^^^^^
  File "/home/airflow/.local/lib/python3.12/site-packages/airflow/models/dag.py", line 4307, in factory
    f(**f_kwargs)
  File "/opt/airflow/dags/local_to_gcs.py", line 31, in retail
    csv_files = [f for f in os.listdir(dataset_folder) if f.endswith(".csv")]
                            ^^^^^^^^^^^^^^^^^^^^^^^^^^
FileNotFoundError: [Errno 2] No such file or directory: 'include/dataset/'
[2024-12-30T07:10:05.646+0000] {processor.py:927} WARNING - No viable dags retrieved from /opt/airflow/dags/local_to_gcs.py
[2024-12-30T07:10:05.891+0000] {processor.py:208} INFO - Processing /opt/airflow/dags/local_to_gcs.py took 0.359 seconds
