[2025-01-07T05:57:40.674+0000] {processor.py:186} INFO - Started process (PID=40) to work on /opt/airflow/dags/local_to_gcs.py
[2025-01-07T05:57:40.676+0000] {processor.py:914} INFO - Processing file /opt/airflow/dags/local_to_gcs.py for tasks to queue
[2025-01-07T05:57:40.769+0000] {logging_mixin.py:190} INFO - [2025-01-07T05:57:40.769+0000] {dagbag.py:588} INFO - Filling up the DagBag from /opt/airflow/dags/local_to_gcs.py
[2025-01-07T05:57:40.922+0000] {logging_mixin.py:190} INFO - [2025-01-07T05:57:40.901+0000] {dagbag.py:387} ERROR - Failed to import: /opt/airflow/dags/local_to_gcs.py
Traceback (most recent call last):
  File "/home/airflow/.local/lib/python3.12/site-packages/airflow/models/dagbag.py", line 383, in parse
    loader.exec_module(new_module)
  File "<frozen importlib._bootstrap_external>", line 999, in exec_module
  File "<frozen importlib._bootstrap>", line 488, in _call_with_frames_removed
  File "/opt/airflow/dags/local_to_gcs.py", line 66, in <module>
    retail_dag = retail()  # Instantiate the DAG
                 ^^^^^^^^
  File "/home/airflow/.local/lib/python3.12/site-packages/airflow/models/dag.py", line 4307, in factory
    f(**f_kwargs)
  File "/opt/airflow/dags/local_to_gcs.py", line 31, in retail
    csv_files = [f for f in os.listdir(dataset_folder) if f.endswith(".csv")]
                            ^^^^^^^^^^^^^^^^^^^^^^^^^^
FileNotFoundError: [Errno 2] No such file or directory: 'include/dataset/'
[2025-01-07T05:57:40.924+0000] {processor.py:927} WARNING - No viable dags retrieved from /opt/airflow/dags/local_to_gcs.py
[2025-01-07T05:57:40.985+0000] {processor.py:208} INFO - Processing /opt/airflow/dags/local_to_gcs.py took 0.355 seconds
[2025-01-07T05:58:12.966+0000] {processor.py:186} INFO - Started process (PID=106) to work on /opt/airflow/dags/local_to_gcs.py
[2025-01-07T05:58:12.967+0000] {processor.py:914} INFO - Processing file /opt/airflow/dags/local_to_gcs.py for tasks to queue
[2025-01-07T05:58:12.971+0000] {logging_mixin.py:190} INFO - [2025-01-07T05:58:12.971+0000] {dagbag.py:588} INFO - Filling up the DagBag from /opt/airflow/dags/local_to_gcs.py
[2025-01-07T05:58:13.009+0000] {logging_mixin.py:190} INFO - [2025-01-07T05:58:13.002+0000] {dagbag.py:387} ERROR - Failed to import: /opt/airflow/dags/local_to_gcs.py
Traceback (most recent call last):
  File "/home/airflow/.local/lib/python3.12/site-packages/airflow/models/dagbag.py", line 383, in parse
    loader.exec_module(new_module)
  File "<frozen importlib._bootstrap_external>", line 999, in exec_module
  File "<frozen importlib._bootstrap>", line 488, in _call_with_frames_removed
  File "/opt/airflow/dags/local_to_gcs.py", line 66, in <module>
    retail_dag = retail()  # Instantiate the DAG
                 ^^^^^^^^
  File "/home/airflow/.local/lib/python3.12/site-packages/airflow/models/dag.py", line 4307, in factory
    f(**f_kwargs)
  File "/opt/airflow/dags/local_to_gcs.py", line 31, in retail
    csv_files = [f for f in os.listdir(dataset_folder) if f.endswith(".csv")]
                            ^^^^^^^^^^^^^^^^^^^^^^^^^^
FileNotFoundError: [Errno 2] No such file or directory: 'include/dataset/'
[2025-01-07T05:58:13.011+0000] {processor.py:927} WARNING - No viable dags retrieved from /opt/airflow/dags/local_to_gcs.py
[2025-01-07T05:58:13.050+0000] {processor.py:208} INFO - Processing /opt/airflow/dags/local_to_gcs.py took 0.091 seconds
[2025-01-07T05:58:43.768+0000] {processor.py:186} INFO - Started process (PID=172) to work on /opt/airflow/dags/local_to_gcs.py
[2025-01-07T05:58:43.771+0000] {processor.py:914} INFO - Processing file /opt/airflow/dags/local_to_gcs.py for tasks to queue
[2025-01-07T05:58:43.780+0000] {logging_mixin.py:190} INFO - [2025-01-07T05:58:43.779+0000] {dagbag.py:588} INFO - Filling up the DagBag from /opt/airflow/dags/local_to_gcs.py
[2025-01-07T05:58:43.892+0000] {logging_mixin.py:190} INFO - [2025-01-07T05:58:43.873+0000] {dagbag.py:387} ERROR - Failed to import: /opt/airflow/dags/local_to_gcs.py
Traceback (most recent call last):
  File "/home/airflow/.local/lib/python3.12/site-packages/airflow/models/dagbag.py", line 383, in parse
    loader.exec_module(new_module)
  File "<frozen importlib._bootstrap_external>", line 999, in exec_module
  File "<frozen importlib._bootstrap>", line 488, in _call_with_frames_removed
  File "/opt/airflow/dags/local_to_gcs.py", line 66, in <module>
    retail_dag = retail()  # Instantiate the DAG
                 ^^^^^^^^
  File "/home/airflow/.local/lib/python3.12/site-packages/airflow/models/dag.py", line 4307, in factory
    f(**f_kwargs)
  File "/opt/airflow/dags/local_to_gcs.py", line 31, in retail
    csv_files = [f for f in os.listdir(dataset_folder) if f.endswith(".csv")]
                            ^^^^^^^^^^^^^^^^^^^^^^^^^^
FileNotFoundError: [Errno 2] No such file or directory: 'include/dataset/'
[2025-01-07T05:58:43.903+0000] {processor.py:927} WARNING - No viable dags retrieved from /opt/airflow/dags/local_to_gcs.py
[2025-01-07T05:58:43.998+0000] {processor.py:208} INFO - Processing /opt/airflow/dags/local_to_gcs.py took 0.254 seconds
[2025-01-07T05:59:14.707+0000] {processor.py:186} INFO - Started process (PID=238) to work on /opt/airflow/dags/local_to_gcs.py
[2025-01-07T05:59:14.710+0000] {processor.py:914} INFO - Processing file /opt/airflow/dags/local_to_gcs.py for tasks to queue
[2025-01-07T05:59:14.718+0000] {logging_mixin.py:190} INFO - [2025-01-07T05:59:14.717+0000] {dagbag.py:588} INFO - Filling up the DagBag from /opt/airflow/dags/local_to_gcs.py
[2025-01-07T05:59:14.774+0000] {logging_mixin.py:190} INFO - [2025-01-07T05:59:14.765+0000] {dagbag.py:387} ERROR - Failed to import: /opt/airflow/dags/local_to_gcs.py
Traceback (most recent call last):
  File "/home/airflow/.local/lib/python3.12/site-packages/airflow/models/dagbag.py", line 383, in parse
    loader.exec_module(new_module)
  File "<frozen importlib._bootstrap_external>", line 999, in exec_module
  File "<frozen importlib._bootstrap>", line 488, in _call_with_frames_removed
  File "/opt/airflow/dags/local_to_gcs.py", line 66, in <module>
    retail_dag = retail()  # Instantiate the DAG
                 ^^^^^^^^
  File "/home/airflow/.local/lib/python3.12/site-packages/airflow/models/dag.py", line 4307, in factory
    f(**f_kwargs)
  File "/opt/airflow/dags/local_to_gcs.py", line 31, in retail
    csv_files = [f for f in os.listdir(dataset_folder) if f.endswith(".csv")]
                            ^^^^^^^^^^^^^^^^^^^^^^^^^^
FileNotFoundError: [Errno 2] No such file or directory: 'include/dataset/'
[2025-01-07T05:59:14.776+0000] {processor.py:927} WARNING - No viable dags retrieved from /opt/airflow/dags/local_to_gcs.py
[2025-01-07T05:59:14.812+0000] {processor.py:208} INFO - Processing /opt/airflow/dags/local_to_gcs.py took 0.116 seconds
[2025-01-07T05:59:45.339+0000] {processor.py:186} INFO - Started process (PID=305) to work on /opt/airflow/dags/local_to_gcs.py
[2025-01-07T05:59:45.340+0000] {processor.py:914} INFO - Processing file /opt/airflow/dags/local_to_gcs.py for tasks to queue
[2025-01-07T05:59:45.347+0000] {logging_mixin.py:190} INFO - [2025-01-07T05:59:45.346+0000] {dagbag.py:588} INFO - Filling up the DagBag from /opt/airflow/dags/local_to_gcs.py
[2025-01-07T05:59:45.406+0000] {logging_mixin.py:190} INFO - [2025-01-07T05:59:45.397+0000] {dagbag.py:387} ERROR - Failed to import: /opt/airflow/dags/local_to_gcs.py
Traceback (most recent call last):
  File "/home/airflow/.local/lib/python3.12/site-packages/airflow/models/dagbag.py", line 383, in parse
    loader.exec_module(new_module)
  File "<frozen importlib._bootstrap_external>", line 999, in exec_module
  File "<frozen importlib._bootstrap>", line 488, in _call_with_frames_removed
  File "/opt/airflow/dags/local_to_gcs.py", line 66, in <module>
    retail_dag = retail()  # Instantiate the DAG
                 ^^^^^^^^
  File "/home/airflow/.local/lib/python3.12/site-packages/airflow/models/dag.py", line 4307, in factory
    f(**f_kwargs)
  File "/opt/airflow/dags/local_to_gcs.py", line 31, in retail
    csv_files = [f for f in os.listdir(dataset_folder) if f.endswith(".csv")]
                            ^^^^^^^^^^^^^^^^^^^^^^^^^^
FileNotFoundError: [Errno 2] No such file or directory: 'include/dataset/'
[2025-01-07T05:59:45.411+0000] {processor.py:927} WARNING - No viable dags retrieved from /opt/airflow/dags/local_to_gcs.py
[2025-01-07T05:59:45.449+0000] {processor.py:208} INFO - Processing /opt/airflow/dags/local_to_gcs.py took 0.118 seconds
[2025-01-07T06:00:16.081+0000] {processor.py:186} INFO - Started process (PID=371) to work on /opt/airflow/dags/local_to_gcs.py
[2025-01-07T06:00:16.085+0000] {processor.py:914} INFO - Processing file /opt/airflow/dags/local_to_gcs.py for tasks to queue
[2025-01-07T06:00:16.095+0000] {logging_mixin.py:190} INFO - [2025-01-07T06:00:16.095+0000] {dagbag.py:588} INFO - Filling up the DagBag from /opt/airflow/dags/local_to_gcs.py
[2025-01-07T06:00:16.190+0000] {logging_mixin.py:190} INFO - [2025-01-07T06:00:16.171+0000] {dagbag.py:387} ERROR - Failed to import: /opt/airflow/dags/local_to_gcs.py
Traceback (most recent call last):
  File "/home/airflow/.local/lib/python3.12/site-packages/airflow/models/dagbag.py", line 383, in parse
    loader.exec_module(new_module)
  File "<frozen importlib._bootstrap_external>", line 999, in exec_module
  File "<frozen importlib._bootstrap>", line 488, in _call_with_frames_removed
  File "/opt/airflow/dags/local_to_gcs.py", line 66, in <module>
    retail_dag = retail()  # Instantiate the DAG
                 ^^^^^^^^
  File "/home/airflow/.local/lib/python3.12/site-packages/airflow/models/dag.py", line 4307, in factory
    f(**f_kwargs)
  File "/opt/airflow/dags/local_to_gcs.py", line 31, in retail
    csv_files = [f for f in os.listdir(dataset_folder) if f.endswith(".csv")]
                            ^^^^^^^^^^^^^^^^^^^^^^^^^^
FileNotFoundError: [Errno 2] No such file or directory: 'include/dataset/'
[2025-01-07T06:00:16.196+0000] {processor.py:927} WARNING - No viable dags retrieved from /opt/airflow/dags/local_to_gcs.py
[2025-01-07T06:00:16.300+0000] {processor.py:208} INFO - Processing /opt/airflow/dags/local_to_gcs.py took 0.240 seconds
[2025-01-07T06:00:46.490+0000] {processor.py:186} INFO - Started process (PID=437) to work on /opt/airflow/dags/local_to_gcs.py
[2025-01-07T06:00:46.491+0000] {processor.py:914} INFO - Processing file /opt/airflow/dags/local_to_gcs.py for tasks to queue
[2025-01-07T06:00:46.495+0000] {logging_mixin.py:190} INFO - [2025-01-07T06:00:46.494+0000] {dagbag.py:588} INFO - Filling up the DagBag from /opt/airflow/dags/local_to_gcs.py
[2025-01-07T06:00:46.527+0000] {logging_mixin.py:190} INFO - [2025-01-07T06:00:46.521+0000] {dagbag.py:387} ERROR - Failed to import: /opt/airflow/dags/local_to_gcs.py
Traceback (most recent call last):
  File "/home/airflow/.local/lib/python3.12/site-packages/airflow/models/dagbag.py", line 383, in parse
    loader.exec_module(new_module)
  File "<frozen importlib._bootstrap_external>", line 999, in exec_module
  File "<frozen importlib._bootstrap>", line 488, in _call_with_frames_removed
  File "/opt/airflow/dags/local_to_gcs.py", line 66, in <module>
    retail_dag = retail()  # Instantiate the DAG
                 ^^^^^^^^
  File "/home/airflow/.local/lib/python3.12/site-packages/airflow/models/dag.py", line 4307, in factory
    f(**f_kwargs)
  File "/opt/airflow/dags/local_to_gcs.py", line 31, in retail
    csv_files = [f for f in os.listdir(dataset_folder) if f.endswith(".csv")]
                            ^^^^^^^^^^^^^^^^^^^^^^^^^^
FileNotFoundError: [Errno 2] No such file or directory: 'include/dataset/'
[2025-01-07T06:00:46.528+0000] {processor.py:927} WARNING - No viable dags retrieved from /opt/airflow/dags/local_to_gcs.py
[2025-01-07T06:00:46.556+0000] {processor.py:208} INFO - Processing /opt/airflow/dags/local_to_gcs.py took 0.074 seconds
[2025-01-07T06:01:17.103+0000] {processor.py:186} INFO - Started process (PID=503) to work on /opt/airflow/dags/local_to_gcs.py
[2025-01-07T06:01:17.104+0000] {processor.py:914} INFO - Processing file /opt/airflow/dags/local_to_gcs.py for tasks to queue
[2025-01-07T06:01:17.108+0000] {logging_mixin.py:190} INFO - [2025-01-07T06:01:17.108+0000] {dagbag.py:588} INFO - Filling up the DagBag from /opt/airflow/dags/local_to_gcs.py
[2025-01-07T06:01:17.148+0000] {logging_mixin.py:190} INFO - [2025-01-07T06:01:17.140+0000] {dagbag.py:387} ERROR - Failed to import: /opt/airflow/dags/local_to_gcs.py
Traceback (most recent call last):
  File "/home/airflow/.local/lib/python3.12/site-packages/airflow/models/dagbag.py", line 383, in parse
    loader.exec_module(new_module)
  File "<frozen importlib._bootstrap_external>", line 999, in exec_module
  File "<frozen importlib._bootstrap>", line 488, in _call_with_frames_removed
  File "/opt/airflow/dags/local_to_gcs.py", line 66, in <module>
    retail_dag = retail()  # Instantiate the DAG
                 ^^^^^^^^
  File "/home/airflow/.local/lib/python3.12/site-packages/airflow/models/dag.py", line 4307, in factory
    f(**f_kwargs)
  File "/opt/airflow/dags/local_to_gcs.py", line 31, in retail
    csv_files = [f for f in os.listdir(dataset_folder) if f.endswith(".csv")]
                            ^^^^^^^^^^^^^^^^^^^^^^^^^^
FileNotFoundError: [Errno 2] No such file or directory: 'include/dataset/'
[2025-01-07T06:01:17.150+0000] {processor.py:927} WARNING - No viable dags retrieved from /opt/airflow/dags/local_to_gcs.py
[2025-01-07T06:01:17.184+0000] {processor.py:208} INFO - Processing /opt/airflow/dags/local_to_gcs.py took 0.090 seconds
[2025-01-07T06:01:47.329+0000] {processor.py:186} INFO - Started process (PID=569) to work on /opt/airflow/dags/local_to_gcs.py
[2025-01-07T06:01:47.332+0000] {processor.py:914} INFO - Processing file /opt/airflow/dags/local_to_gcs.py for tasks to queue
[2025-01-07T06:01:47.338+0000] {logging_mixin.py:190} INFO - [2025-01-07T06:01:47.337+0000] {dagbag.py:588} INFO - Filling up the DagBag from /opt/airflow/dags/local_to_gcs.py
[2025-01-07T06:01:47.406+0000] {logging_mixin.py:190} INFO - [2025-01-07T06:01:47.395+0000] {dagbag.py:387} ERROR - Failed to import: /opt/airflow/dags/local_to_gcs.py
Traceback (most recent call last):
  File "/home/airflow/.local/lib/python3.12/site-packages/airflow/models/dagbag.py", line 383, in parse
    loader.exec_module(new_module)
  File "<frozen importlib._bootstrap_external>", line 999, in exec_module
  File "<frozen importlib._bootstrap>", line 488, in _call_with_frames_removed
  File "/opt/airflow/dags/local_to_gcs.py", line 66, in <module>
    retail_dag = retail()  # Instantiate the DAG
                 ^^^^^^^^
  File "/home/airflow/.local/lib/python3.12/site-packages/airflow/models/dag.py", line 4307, in factory
    f(**f_kwargs)
  File "/opt/airflow/dags/local_to_gcs.py", line 31, in retail
    csv_files = [f for f in os.listdir(dataset_folder) if f.endswith(".csv")]
                            ^^^^^^^^^^^^^^^^^^^^^^^^^^
FileNotFoundError: [Errno 2] No such file or directory: 'include/dataset/'
[2025-01-07T06:01:47.408+0000] {processor.py:927} WARNING - No viable dags retrieved from /opt/airflow/dags/local_to_gcs.py
[2025-01-07T06:01:47.452+0000] {processor.py:208} INFO - Processing /opt/airflow/dags/local_to_gcs.py took 0.152 seconds
[2025-01-07T06:02:17.608+0000] {processor.py:186} INFO - Started process (PID=635) to work on /opt/airflow/dags/local_to_gcs.py
[2025-01-07T06:02:17.609+0000] {processor.py:914} INFO - Processing file /opt/airflow/dags/local_to_gcs.py for tasks to queue
[2025-01-07T06:02:17.613+0000] {logging_mixin.py:190} INFO - [2025-01-07T06:02:17.612+0000] {dagbag.py:588} INFO - Filling up the DagBag from /opt/airflow/dags/local_to_gcs.py
[2025-01-07T06:02:17.644+0000] {logging_mixin.py:190} INFO - [2025-01-07T06:02:17.638+0000] {dagbag.py:387} ERROR - Failed to import: /opt/airflow/dags/local_to_gcs.py
Traceback (most recent call last):
  File "/home/airflow/.local/lib/python3.12/site-packages/airflow/models/dagbag.py", line 383, in parse
    loader.exec_module(new_module)
  File "<frozen importlib._bootstrap_external>", line 999, in exec_module
  File "<frozen importlib._bootstrap>", line 488, in _call_with_frames_removed
  File "/opt/airflow/dags/local_to_gcs.py", line 66, in <module>
    retail_dag = retail()  # Instantiate the DAG
                 ^^^^^^^^
  File "/home/airflow/.local/lib/python3.12/site-packages/airflow/models/dag.py", line 4307, in factory
    f(**f_kwargs)
  File "/opt/airflow/dags/local_to_gcs.py", line 31, in retail
    csv_files = [f for f in os.listdir(dataset_folder) if f.endswith(".csv")]
                            ^^^^^^^^^^^^^^^^^^^^^^^^^^
FileNotFoundError: [Errno 2] No such file or directory: 'include/dataset/'
[2025-01-07T06:02:17.646+0000] {processor.py:927} WARNING - No viable dags retrieved from /opt/airflow/dags/local_to_gcs.py
[2025-01-07T06:02:17.673+0000] {processor.py:208} INFO - Processing /opt/airflow/dags/local_to_gcs.py took 0.075 seconds
[2025-01-07T06:02:47.837+0000] {processor.py:186} INFO - Started process (PID=701) to work on /opt/airflow/dags/local_to_gcs.py
[2025-01-07T06:02:47.838+0000] {processor.py:914} INFO - Processing file /opt/airflow/dags/local_to_gcs.py for tasks to queue
[2025-01-07T06:02:47.841+0000] {logging_mixin.py:190} INFO - [2025-01-07T06:02:47.841+0000] {dagbag.py:588} INFO - Filling up the DagBag from /opt/airflow/dags/local_to_gcs.py
[2025-01-07T06:02:47.872+0000] {logging_mixin.py:190} INFO - [2025-01-07T06:02:47.866+0000] {dagbag.py:387} ERROR - Failed to import: /opt/airflow/dags/local_to_gcs.py
Traceback (most recent call last):
  File "/home/airflow/.local/lib/python3.12/site-packages/airflow/models/dagbag.py", line 383, in parse
    loader.exec_module(new_module)
  File "<frozen importlib._bootstrap_external>", line 999, in exec_module
  File "<frozen importlib._bootstrap>", line 488, in _call_with_frames_removed
  File "/opt/airflow/dags/local_to_gcs.py", line 66, in <module>
    retail_dag = retail()  # Instantiate the DAG
                 ^^^^^^^^
  File "/home/airflow/.local/lib/python3.12/site-packages/airflow/models/dag.py", line 4307, in factory
    f(**f_kwargs)
  File "/opt/airflow/dags/local_to_gcs.py", line 31, in retail
    csv_files = [f for f in os.listdir(dataset_folder) if f.endswith(".csv")]
                            ^^^^^^^^^^^^^^^^^^^^^^^^^^
FileNotFoundError: [Errno 2] No such file or directory: 'include/dataset/'
[2025-01-07T06:02:47.874+0000] {processor.py:927} WARNING - No viable dags retrieved from /opt/airflow/dags/local_to_gcs.py
[2025-01-07T06:02:47.899+0000] {processor.py:208} INFO - Processing /opt/airflow/dags/local_to_gcs.py took 0.070 seconds
[2025-01-07T06:03:18.162+0000] {processor.py:186} INFO - Started process (PID=766) to work on /opt/airflow/dags/local_to_gcs.py
[2025-01-07T06:03:18.164+0000] {processor.py:914} INFO - Processing file /opt/airflow/dags/local_to_gcs.py for tasks to queue
[2025-01-07T06:03:18.168+0000] {logging_mixin.py:190} INFO - [2025-01-07T06:03:18.167+0000] {dagbag.py:588} INFO - Filling up the DagBag from /opt/airflow/dags/local_to_gcs.py
[2025-01-07T06:03:18.203+0000] {logging_mixin.py:190} INFO - [2025-01-07T06:03:18.197+0000] {dagbag.py:387} ERROR - Failed to import: /opt/airflow/dags/local_to_gcs.py
Traceback (most recent call last):
  File "/home/airflow/.local/lib/python3.12/site-packages/airflow/models/dagbag.py", line 383, in parse
    loader.exec_module(new_module)
  File "<frozen importlib._bootstrap_external>", line 999, in exec_module
  File "<frozen importlib._bootstrap>", line 488, in _call_with_frames_removed
  File "/opt/airflow/dags/local_to_gcs.py", line 66, in <module>
    retail_dag = retail()  # Instantiate the DAG
                 ^^^^^^^^
  File "/home/airflow/.local/lib/python3.12/site-packages/airflow/models/dag.py", line 4307, in factory
    f(**f_kwargs)
  File "/opt/airflow/dags/local_to_gcs.py", line 31, in retail
    csv_files = [f for f in os.listdir(dataset_folder) if f.endswith(".csv")]
                            ^^^^^^^^^^^^^^^^^^^^^^^^^^
FileNotFoundError: [Errno 2] No such file or directory: 'include/dataset/'
[2025-01-07T06:03:18.205+0000] {processor.py:927} WARNING - No viable dags retrieved from /opt/airflow/dags/local_to_gcs.py
[2025-01-07T06:03:18.230+0000] {processor.py:208} INFO - Processing /opt/airflow/dags/local_to_gcs.py took 0.078 seconds
[2025-01-07T06:03:48.428+0000] {processor.py:186} INFO - Started process (PID=832) to work on /opt/airflow/dags/local_to_gcs.py
[2025-01-07T06:03:48.434+0000] {processor.py:914} INFO - Processing file /opt/airflow/dags/local_to_gcs.py for tasks to queue
[2025-01-07T06:03:48.444+0000] {logging_mixin.py:190} INFO - [2025-01-07T06:03:48.443+0000] {dagbag.py:588} INFO - Filling up the DagBag from /opt/airflow/dags/local_to_gcs.py
[2025-01-07T06:03:48.517+0000] {logging_mixin.py:190} INFO - [2025-01-07T06:03:48.501+0000] {dagbag.py:387} ERROR - Failed to import: /opt/airflow/dags/local_to_gcs.py
Traceback (most recent call last):
  File "/home/airflow/.local/lib/python3.12/site-packages/airflow/models/dagbag.py", line 383, in parse
    loader.exec_module(new_module)
  File "<frozen importlib._bootstrap_external>", line 999, in exec_module
  File "<frozen importlib._bootstrap>", line 488, in _call_with_frames_removed
  File "/opt/airflow/dags/local_to_gcs.py", line 66, in <module>
    retail_dag = retail()  # Instantiate the DAG
                 ^^^^^^^^
  File "/home/airflow/.local/lib/python3.12/site-packages/airflow/models/dag.py", line 4307, in factory
    f(**f_kwargs)
  File "/opt/airflow/dags/local_to_gcs.py", line 31, in retail
    csv_files = [f for f in os.listdir(dataset_folder) if f.endswith(".csv")]
                            ^^^^^^^^^^^^^^^^^^^^^^^^^^
FileNotFoundError: [Errno 2] No such file or directory: 'include/dataset/'
[2025-01-07T06:03:48.521+0000] {processor.py:927} WARNING - No viable dags retrieved from /opt/airflow/dags/local_to_gcs.py
[2025-01-07T06:03:48.588+0000] {processor.py:208} INFO - Processing /opt/airflow/dags/local_to_gcs.py took 0.173 seconds
