[2024-12-24T07:28:52.567+0000] {processor.py:186} INFO - Started process (PID=41) to work on /opt/airflow/dags/local_to_gcs.py
[2024-12-24T07:28:52.581+0000] {processor.py:914} INFO - Processing file /opt/airflow/dags/local_to_gcs.py for tasks to queue
[2024-12-24T07:28:52.586+0000] {logging_mixin.py:190} INFO - [2024-12-24T07:28:52.586+0000] {dagbag.py:588} INFO - Filling up the DagBag from /opt/airflow/dags/local_to_gcs.py
[2024-12-24T07:28:52.655+0000] {logging_mixin.py:190} INFO - [2024-12-24T07:28:52.644+0000] {dagbag.py:387} ERROR - Failed to import: /opt/airflow/dags/local_to_gcs.py
Traceback (most recent call last):
  File "/home/airflow/.local/lib/python3.12/site-packages/airflow/models/dagbag.py", line 383, in parse
    loader.exec_module(new_module)
  File "<frozen importlib._bootstrap_external>", line 999, in exec_module
  File "<frozen importlib._bootstrap>", line 488, in _call_with_frames_removed
  File "/opt/airflow/dags/local_to_gcs.py", line 66, in <module>
    retail_dag = retail()  # Instantiate the DAG
                 ^^^^^^^^
  File "/home/airflow/.local/lib/python3.12/site-packages/airflow/models/dag.py", line 4307, in factory
    f(**f_kwargs)
  File "/opt/airflow/dags/local_to_gcs.py", line 31, in retail
    csv_files = [f for f in os.listdir(dataset_folder) if f.endswith(".csv")]
                            ^^^^^^^^^^^^^^^^^^^^^^^^^^
FileNotFoundError: [Errno 2] No such file or directory: 'include/dataset/'
[2024-12-24T07:28:52.657+0000] {processor.py:927} WARNING - No viable dags retrieved from /opt/airflow/dags/local_to_gcs.py
[2024-12-24T07:28:52.736+0000] {processor.py:208} INFO - Processing /opt/airflow/dags/local_to_gcs.py took 0.229 seconds
[2024-12-24T07:29:23.087+0000] {processor.py:186} INFO - Started process (PID=106) to work on /opt/airflow/dags/local_to_gcs.py
[2024-12-24T07:29:23.089+0000] {processor.py:914} INFO - Processing file /opt/airflow/dags/local_to_gcs.py for tasks to queue
[2024-12-24T07:29:23.093+0000] {logging_mixin.py:190} INFO - [2024-12-24T07:29:23.092+0000] {dagbag.py:588} INFO - Filling up the DagBag from /opt/airflow/dags/local_to_gcs.py
[2024-12-24T07:29:23.137+0000] {logging_mixin.py:190} INFO - [2024-12-24T07:29:23.130+0000] {dagbag.py:387} ERROR - Failed to import: /opt/airflow/dags/local_to_gcs.py
Traceback (most recent call last):
  File "/home/airflow/.local/lib/python3.12/site-packages/airflow/models/dagbag.py", line 383, in parse
    loader.exec_module(new_module)
  File "<frozen importlib._bootstrap_external>", line 999, in exec_module
  File "<frozen importlib._bootstrap>", line 488, in _call_with_frames_removed
  File "/opt/airflow/dags/local_to_gcs.py", line 66, in <module>
    retail_dag = retail()  # Instantiate the DAG
                 ^^^^^^^^
  File "/home/airflow/.local/lib/python3.12/site-packages/airflow/models/dag.py", line 4307, in factory
    f(**f_kwargs)
  File "/opt/airflow/dags/local_to_gcs.py", line 31, in retail
    csv_files = [f for f in os.listdir(dataset_folder) if f.endswith(".csv")]
                            ^^^^^^^^^^^^^^^^^^^^^^^^^^
FileNotFoundError: [Errno 2] No such file or directory: 'include/dataset/'
[2024-12-24T07:29:23.139+0000] {processor.py:927} WARNING - No viable dags retrieved from /opt/airflow/dags/local_to_gcs.py
[2024-12-24T07:29:23.173+0000] {processor.py:208} INFO - Processing /opt/airflow/dags/local_to_gcs.py took 0.094 seconds
[2024-12-24T07:29:54.210+0000] {processor.py:186} INFO - Started process (PID=172) to work on /opt/airflow/dags/local_to_gcs.py
[2024-12-24T07:29:54.212+0000] {processor.py:914} INFO - Processing file /opt/airflow/dags/local_to_gcs.py for tasks to queue
[2024-12-24T07:29:54.216+0000] {logging_mixin.py:190} INFO - [2024-12-24T07:29:54.215+0000] {dagbag.py:588} INFO - Filling up the DagBag from /opt/airflow/dags/local_to_gcs.py
[2024-12-24T07:29:54.250+0000] {logging_mixin.py:190} INFO - [2024-12-24T07:29:54.244+0000] {dagbag.py:387} ERROR - Failed to import: /opt/airflow/dags/local_to_gcs.py
Traceback (most recent call last):
  File "/home/airflow/.local/lib/python3.12/site-packages/airflow/models/dagbag.py", line 383, in parse
    loader.exec_module(new_module)
  File "<frozen importlib._bootstrap_external>", line 999, in exec_module
  File "<frozen importlib._bootstrap>", line 488, in _call_with_frames_removed
  File "/opt/airflow/dags/local_to_gcs.py", line 66, in <module>
    retail_dag = retail()  # Instantiate the DAG
                 ^^^^^^^^
  File "/home/airflow/.local/lib/python3.12/site-packages/airflow/models/dag.py", line 4307, in factory
    f(**f_kwargs)
  File "/opt/airflow/dags/local_to_gcs.py", line 31, in retail
    csv_files = [f for f in os.listdir(dataset_folder) if f.endswith(".csv")]
                            ^^^^^^^^^^^^^^^^^^^^^^^^^^
FileNotFoundError: [Errno 2] No such file or directory: 'include/dataset/'
[2024-12-24T07:29:54.254+0000] {processor.py:927} WARNING - No viable dags retrieved from /opt/airflow/dags/local_to_gcs.py
[2024-12-24T07:29:54.280+0000] {processor.py:208} INFO - Processing /opt/airflow/dags/local_to_gcs.py took 0.078 seconds
[2024-12-24T07:30:24.526+0000] {processor.py:186} INFO - Started process (PID=238) to work on /opt/airflow/dags/local_to_gcs.py
[2024-12-24T07:30:24.528+0000] {processor.py:914} INFO - Processing file /opt/airflow/dags/local_to_gcs.py for tasks to queue
[2024-12-24T07:30:24.536+0000] {logging_mixin.py:190} INFO - [2024-12-24T07:30:24.536+0000] {dagbag.py:588} INFO - Filling up the DagBag from /opt/airflow/dags/local_to_gcs.py
[2024-12-24T07:30:24.624+0000] {logging_mixin.py:190} INFO - [2024-12-24T07:30:24.604+0000] {dagbag.py:387} ERROR - Failed to import: /opt/airflow/dags/local_to_gcs.py
Traceback (most recent call last):
  File "/home/airflow/.local/lib/python3.12/site-packages/airflow/models/dagbag.py", line 383, in parse
    loader.exec_module(new_module)
  File "<frozen importlib._bootstrap_external>", line 999, in exec_module
  File "<frozen importlib._bootstrap>", line 488, in _call_with_frames_removed
  File "/opt/airflow/dags/local_to_gcs.py", line 66, in <module>
    retail_dag = retail()  # Instantiate the DAG
                 ^^^^^^^^
  File "/home/airflow/.local/lib/python3.12/site-packages/airflow/models/dag.py", line 4307, in factory
    f(**f_kwargs)
  File "/opt/airflow/dags/local_to_gcs.py", line 31, in retail
    csv_files = [f for f in os.listdir(dataset_folder) if f.endswith(".csv")]
                            ^^^^^^^^^^^^^^^^^^^^^^^^^^
FileNotFoundError: [Errno 2] No such file or directory: 'include/dataset/'
[2024-12-24T07:30:24.627+0000] {processor.py:927} WARNING - No viable dags retrieved from /opt/airflow/dags/local_to_gcs.py
[2024-12-24T07:30:24.696+0000] {processor.py:208} INFO - Processing /opt/airflow/dags/local_to_gcs.py took 0.191 seconds
[2024-12-24T07:30:55.050+0000] {processor.py:186} INFO - Started process (PID=304) to work on /opt/airflow/dags/local_to_gcs.py
[2024-12-24T07:30:55.052+0000] {processor.py:914} INFO - Processing file /opt/airflow/dags/local_to_gcs.py for tasks to queue
[2024-12-24T07:30:55.057+0000] {logging_mixin.py:190} INFO - [2024-12-24T07:30:55.056+0000] {dagbag.py:588} INFO - Filling up the DagBag from /opt/airflow/dags/local_to_gcs.py
[2024-12-24T07:30:55.109+0000] {logging_mixin.py:190} INFO - [2024-12-24T07:30:55.096+0000] {dagbag.py:387} ERROR - Failed to import: /opt/airflow/dags/local_to_gcs.py
Traceback (most recent call last):
  File "/home/airflow/.local/lib/python3.12/site-packages/airflow/models/dagbag.py", line 383, in parse
    loader.exec_module(new_module)
  File "<frozen importlib._bootstrap_external>", line 999, in exec_module
  File "<frozen importlib._bootstrap>", line 488, in _call_with_frames_removed
  File "/opt/airflow/dags/local_to_gcs.py", line 66, in <module>
    retail_dag = retail()  # Instantiate the DAG
                 ^^^^^^^^
  File "/home/airflow/.local/lib/python3.12/site-packages/airflow/models/dag.py", line 4307, in factory
    f(**f_kwargs)
  File "/opt/airflow/dags/local_to_gcs.py", line 31, in retail
    csv_files = [f for f in os.listdir(dataset_folder) if f.endswith(".csv")]
                            ^^^^^^^^^^^^^^^^^^^^^^^^^^
FileNotFoundError: [Errno 2] No such file or directory: 'include/dataset/'
[2024-12-24T07:30:55.113+0000] {processor.py:927} WARNING - No viable dags retrieved from /opt/airflow/dags/local_to_gcs.py
[2024-12-24T07:30:55.161+0000] {processor.py:208} INFO - Processing /opt/airflow/dags/local_to_gcs.py took 0.122 seconds
[2024-12-24T07:31:25.909+0000] {processor.py:186} INFO - Started process (PID=369) to work on /opt/airflow/dags/local_to_gcs.py
[2024-12-24T07:31:25.913+0000] {processor.py:914} INFO - Processing file /opt/airflow/dags/local_to_gcs.py for tasks to queue
[2024-12-24T07:31:25.918+0000] {logging_mixin.py:190} INFO - [2024-12-24T07:31:25.918+0000] {dagbag.py:588} INFO - Filling up the DagBag from /opt/airflow/dags/local_to_gcs.py
[2024-12-24T07:31:25.987+0000] {logging_mixin.py:190} INFO - [2024-12-24T07:31:25.977+0000] {dagbag.py:387} ERROR - Failed to import: /opt/airflow/dags/local_to_gcs.py
Traceback (most recent call last):
  File "/home/airflow/.local/lib/python3.12/site-packages/airflow/models/dagbag.py", line 383, in parse
    loader.exec_module(new_module)
  File "<frozen importlib._bootstrap_external>", line 999, in exec_module
  File "<frozen importlib._bootstrap>", line 488, in _call_with_frames_removed
  File "/opt/airflow/dags/local_to_gcs.py", line 66, in <module>
    retail_dag = retail()  # Instantiate the DAG
                 ^^^^^^^^
  File "/home/airflow/.local/lib/python3.12/site-packages/airflow/models/dag.py", line 4307, in factory
    f(**f_kwargs)
  File "/opt/airflow/dags/local_to_gcs.py", line 31, in retail
    csv_files = [f for f in os.listdir(dataset_folder) if f.endswith(".csv")]
                            ^^^^^^^^^^^^^^^^^^^^^^^^^^
FileNotFoundError: [Errno 2] No such file or directory: 'include/dataset/'
[2024-12-24T07:31:25.990+0000] {processor.py:927} WARNING - No viable dags retrieved from /opt/airflow/dags/local_to_gcs.py
[2024-12-24T07:31:26.035+0000] {processor.py:208} INFO - Processing /opt/airflow/dags/local_to_gcs.py took 0.143 seconds
[2024-12-24T07:31:56.633+0000] {processor.py:186} INFO - Started process (PID=435) to work on /opt/airflow/dags/local_to_gcs.py
[2024-12-24T07:31:56.635+0000] {processor.py:914} INFO - Processing file /opt/airflow/dags/local_to_gcs.py for tasks to queue
[2024-12-24T07:31:56.639+0000] {logging_mixin.py:190} INFO - [2024-12-24T07:31:56.639+0000] {dagbag.py:588} INFO - Filling up the DagBag from /opt/airflow/dags/local_to_gcs.py
[2024-12-24T07:31:56.688+0000] {logging_mixin.py:190} INFO - [2024-12-24T07:31:56.678+0000] {dagbag.py:387} ERROR - Failed to import: /opt/airflow/dags/local_to_gcs.py
Traceback (most recent call last):
  File "/home/airflow/.local/lib/python3.12/site-packages/airflow/models/dagbag.py", line 383, in parse
    loader.exec_module(new_module)
  File "<frozen importlib._bootstrap_external>", line 999, in exec_module
  File "<frozen importlib._bootstrap>", line 488, in _call_with_frames_removed
  File "/opt/airflow/dags/local_to_gcs.py", line 66, in <module>
    retail_dag = retail()  # Instantiate the DAG
                 ^^^^^^^^
  File "/home/airflow/.local/lib/python3.12/site-packages/airflow/models/dag.py", line 4307, in factory
    f(**f_kwargs)
  File "/opt/airflow/dags/local_to_gcs.py", line 31, in retail
    csv_files = [f for f in os.listdir(dataset_folder) if f.endswith(".csv")]
                            ^^^^^^^^^^^^^^^^^^^^^^^^^^
FileNotFoundError: [Errno 2] No such file or directory: 'include/dataset/'
[2024-12-24T07:31:56.691+0000] {processor.py:927} WARNING - No viable dags retrieved from /opt/airflow/dags/local_to_gcs.py
[2024-12-24T07:31:56.727+0000] {processor.py:208} INFO - Processing /opt/airflow/dags/local_to_gcs.py took 0.104 seconds
[2024-12-24T07:32:27.844+0000] {processor.py:186} INFO - Started process (PID=501) to work on /opt/airflow/dags/local_to_gcs.py
[2024-12-24T07:32:27.848+0000] {processor.py:914} INFO - Processing file /opt/airflow/dags/local_to_gcs.py for tasks to queue
[2024-12-24T07:32:27.860+0000] {logging_mixin.py:190} INFO - [2024-12-24T07:32:27.859+0000] {dagbag.py:588} INFO - Filling up the DagBag from /opt/airflow/dags/local_to_gcs.py
[2024-12-24T07:32:27.955+0000] {logging_mixin.py:190} INFO - [2024-12-24T07:32:27.940+0000] {dagbag.py:387} ERROR - Failed to import: /opt/airflow/dags/local_to_gcs.py
Traceback (most recent call last):
  File "/home/airflow/.local/lib/python3.12/site-packages/airflow/models/dagbag.py", line 383, in parse
    loader.exec_module(new_module)
  File "<frozen importlib._bootstrap_external>", line 999, in exec_module
  File "<frozen importlib._bootstrap>", line 488, in _call_with_frames_removed
  File "/opt/airflow/dags/local_to_gcs.py", line 66, in <module>
    retail_dag = retail()  # Instantiate the DAG
                 ^^^^^^^^
  File "/home/airflow/.local/lib/python3.12/site-packages/airflow/models/dag.py", line 4307, in factory
    f(**f_kwargs)
  File "/opt/airflow/dags/local_to_gcs.py", line 31, in retail
    csv_files = [f for f in os.listdir(dataset_folder) if f.endswith(".csv")]
                            ^^^^^^^^^^^^^^^^^^^^^^^^^^
FileNotFoundError: [Errno 2] No such file or directory: 'include/dataset/'
[2024-12-24T07:32:27.959+0000] {processor.py:927} WARNING - No viable dags retrieved from /opt/airflow/dags/local_to_gcs.py
[2024-12-24T07:32:28.048+0000] {processor.py:208} INFO - Processing /opt/airflow/dags/local_to_gcs.py took 0.227 seconds
[2024-12-24T07:32:58.658+0000] {processor.py:186} INFO - Started process (PID=567) to work on /opt/airflow/dags/local_to_gcs.py
[2024-12-24T07:32:58.660+0000] {processor.py:914} INFO - Processing file /opt/airflow/dags/local_to_gcs.py for tasks to queue
[2024-12-24T07:32:58.670+0000] {logging_mixin.py:190} INFO - [2024-12-24T07:32:58.669+0000] {dagbag.py:588} INFO - Filling up the DagBag from /opt/airflow/dags/local_to_gcs.py
[2024-12-24T07:32:58.739+0000] {logging_mixin.py:190} INFO - [2024-12-24T07:32:58.728+0000] {dagbag.py:387} ERROR - Failed to import: /opt/airflow/dags/local_to_gcs.py
Traceback (most recent call last):
  File "/home/airflow/.local/lib/python3.12/site-packages/airflow/models/dagbag.py", line 383, in parse
    loader.exec_module(new_module)
  File "<frozen importlib._bootstrap_external>", line 999, in exec_module
  File "<frozen importlib._bootstrap>", line 488, in _call_with_frames_removed
  File "/opt/airflow/dags/local_to_gcs.py", line 66, in <module>
    retail_dag = retail()  # Instantiate the DAG
                 ^^^^^^^^
  File "/home/airflow/.local/lib/python3.12/site-packages/airflow/models/dag.py", line 4307, in factory
    f(**f_kwargs)
  File "/opt/airflow/dags/local_to_gcs.py", line 31, in retail
    csv_files = [f for f in os.listdir(dataset_folder) if f.endswith(".csv")]
                            ^^^^^^^^^^^^^^^^^^^^^^^^^^
FileNotFoundError: [Errno 2] No such file or directory: 'include/dataset/'
[2024-12-24T07:32:58.743+0000] {processor.py:927} WARNING - No viable dags retrieved from /opt/airflow/dags/local_to_gcs.py
[2024-12-24T07:32:58.797+0000] {processor.py:208} INFO - Processing /opt/airflow/dags/local_to_gcs.py took 0.155 seconds
[2024-12-24T07:33:29.196+0000] {processor.py:186} INFO - Started process (PID=633) to work on /opt/airflow/dags/local_to_gcs.py
[2024-12-24T07:33:29.198+0000] {processor.py:914} INFO - Processing file /opt/airflow/dags/local_to_gcs.py for tasks to queue
[2024-12-24T07:33:29.205+0000] {logging_mixin.py:190} INFO - [2024-12-24T07:33:29.204+0000] {dagbag.py:588} INFO - Filling up the DagBag from /opt/airflow/dags/local_to_gcs.py
[2024-12-24T07:33:29.250+0000] {logging_mixin.py:190} INFO - [2024-12-24T07:33:29.242+0000] {dagbag.py:387} ERROR - Failed to import: /opt/airflow/dags/local_to_gcs.py
Traceback (most recent call last):
  File "/home/airflow/.local/lib/python3.12/site-packages/airflow/models/dagbag.py", line 383, in parse
    loader.exec_module(new_module)
  File "<frozen importlib._bootstrap_external>", line 999, in exec_module
  File "<frozen importlib._bootstrap>", line 488, in _call_with_frames_removed
  File "/opt/airflow/dags/local_to_gcs.py", line 66, in <module>
    retail_dag = retail()  # Instantiate the DAG
                 ^^^^^^^^
  File "/home/airflow/.local/lib/python3.12/site-packages/airflow/models/dag.py", line 4307, in factory
    f(**f_kwargs)
  File "/opt/airflow/dags/local_to_gcs.py", line 31, in retail
    csv_files = [f for f in os.listdir(dataset_folder) if f.endswith(".csv")]
                            ^^^^^^^^^^^^^^^^^^^^^^^^^^
FileNotFoundError: [Errno 2] No such file or directory: 'include/dataset/'
[2024-12-24T07:33:29.253+0000] {processor.py:927} WARNING - No viable dags retrieved from /opt/airflow/dags/local_to_gcs.py
[2024-12-24T07:33:29.280+0000] {processor.py:208} INFO - Processing /opt/airflow/dags/local_to_gcs.py took 0.095 seconds
[2024-12-24T07:33:59.390+0000] {processor.py:186} INFO - Started process (PID=699) to work on /opt/airflow/dags/local_to_gcs.py
[2024-12-24T07:33:59.392+0000] {processor.py:914} INFO - Processing file /opt/airflow/dags/local_to_gcs.py for tasks to queue
[2024-12-24T07:33:59.395+0000] {logging_mixin.py:190} INFO - [2024-12-24T07:33:59.394+0000] {dagbag.py:588} INFO - Filling up the DagBag from /opt/airflow/dags/local_to_gcs.py
[2024-12-24T07:33:59.441+0000] {logging_mixin.py:190} INFO - [2024-12-24T07:33:59.434+0000] {dagbag.py:387} ERROR - Failed to import: /opt/airflow/dags/local_to_gcs.py
Traceback (most recent call last):
  File "/home/airflow/.local/lib/python3.12/site-packages/airflow/models/dagbag.py", line 383, in parse
    loader.exec_module(new_module)
  File "<frozen importlib._bootstrap_external>", line 999, in exec_module
  File "<frozen importlib._bootstrap>", line 488, in _call_with_frames_removed
  File "/opt/airflow/dags/local_to_gcs.py", line 66, in <module>
    retail_dag = retail()  # Instantiate the DAG
                 ^^^^^^^^
  File "/home/airflow/.local/lib/python3.12/site-packages/airflow/models/dag.py", line 4307, in factory
    f(**f_kwargs)
  File "/opt/airflow/dags/local_to_gcs.py", line 31, in retail
    csv_files = [f for f in os.listdir(dataset_folder) if f.endswith(".csv")]
                            ^^^^^^^^^^^^^^^^^^^^^^^^^^
FileNotFoundError: [Errno 2] No such file or directory: 'include/dataset/'
[2024-12-24T07:33:59.443+0000] {processor.py:927} WARNING - No viable dags retrieved from /opt/airflow/dags/local_to_gcs.py
[2024-12-24T07:33:59.473+0000] {processor.py:208} INFO - Processing /opt/airflow/dags/local_to_gcs.py took 0.091 seconds
[2024-12-24T07:34:29.632+0000] {processor.py:186} INFO - Started process (PID=766) to work on /opt/airflow/dags/local_to_gcs.py
[2024-12-24T07:34:29.634+0000] {processor.py:914} INFO - Processing file /opt/airflow/dags/local_to_gcs.py for tasks to queue
[2024-12-24T07:34:29.641+0000] {logging_mixin.py:190} INFO - [2024-12-24T07:34:29.641+0000] {dagbag.py:588} INFO - Filling up the DagBag from /opt/airflow/dags/local_to_gcs.py
[2024-12-24T07:34:29.674+0000] {logging_mixin.py:190} INFO - [2024-12-24T07:34:29.669+0000] {dagbag.py:387} ERROR - Failed to import: /opt/airflow/dags/local_to_gcs.py
Traceback (most recent call last):
  File "/home/airflow/.local/lib/python3.12/site-packages/airflow/models/dagbag.py", line 383, in parse
    loader.exec_module(new_module)
  File "<frozen importlib._bootstrap_external>", line 999, in exec_module
  File "<frozen importlib._bootstrap>", line 488, in _call_with_frames_removed
  File "/opt/airflow/dags/local_to_gcs.py", line 66, in <module>
    retail_dag = retail()  # Instantiate the DAG
                 ^^^^^^^^
  File "/home/airflow/.local/lib/python3.12/site-packages/airflow/models/dag.py", line 4307, in factory
    f(**f_kwargs)
  File "/opt/airflow/dags/local_to_gcs.py", line 31, in retail
    csv_files = [f for f in os.listdir(dataset_folder) if f.endswith(".csv")]
                            ^^^^^^^^^^^^^^^^^^^^^^^^^^
FileNotFoundError: [Errno 2] No such file or directory: 'include/dataset/'
[2024-12-24T07:34:29.676+0000] {processor.py:927} WARNING - No viable dags retrieved from /opt/airflow/dags/local_to_gcs.py
[2024-12-24T07:34:29.707+0000] {processor.py:208} INFO - Processing /opt/airflow/dags/local_to_gcs.py took 0.087 seconds
[2024-12-24T07:35:00.238+0000] {processor.py:186} INFO - Started process (PID=832) to work on /opt/airflow/dags/local_to_gcs.py
[2024-12-24T07:35:00.240+0000] {processor.py:914} INFO - Processing file /opt/airflow/dags/local_to_gcs.py for tasks to queue
[2024-12-24T07:35:00.245+0000] {logging_mixin.py:190} INFO - [2024-12-24T07:35:00.244+0000] {dagbag.py:588} INFO - Filling up the DagBag from /opt/airflow/dags/local_to_gcs.py
[2024-12-24T07:35:00.309+0000] {logging_mixin.py:190} INFO - [2024-12-24T07:35:00.296+0000] {dagbag.py:387} ERROR - Failed to import: /opt/airflow/dags/local_to_gcs.py
Traceback (most recent call last):
  File "/home/airflow/.local/lib/python3.12/site-packages/airflow/models/dagbag.py", line 383, in parse
    loader.exec_module(new_module)
  File "<frozen importlib._bootstrap_external>", line 999, in exec_module
  File "<frozen importlib._bootstrap>", line 488, in _call_with_frames_removed
  File "/opt/airflow/dags/local_to_gcs.py", line 66, in <module>
    retail_dag = retail()  # Instantiate the DAG
                 ^^^^^^^^
  File "/home/airflow/.local/lib/python3.12/site-packages/airflow/models/dag.py", line 4307, in factory
    f(**f_kwargs)
  File "/opt/airflow/dags/local_to_gcs.py", line 31, in retail
    csv_files = [f for f in os.listdir(dataset_folder) if f.endswith(".csv")]
                            ^^^^^^^^^^^^^^^^^^^^^^^^^^
FileNotFoundError: [Errno 2] No such file or directory: 'include/dataset/'
[2024-12-24T07:35:00.312+0000] {processor.py:927} WARNING - No viable dags retrieved from /opt/airflow/dags/local_to_gcs.py
[2024-12-24T07:35:00.347+0000] {processor.py:208} INFO - Processing /opt/airflow/dags/local_to_gcs.py took 0.121 seconds
[2024-12-24T07:35:31.321+0000] {processor.py:186} INFO - Started process (PID=898) to work on /opt/airflow/dags/local_to_gcs.py
[2024-12-24T07:35:31.323+0000] {processor.py:914} INFO - Processing file /opt/airflow/dags/local_to_gcs.py for tasks to queue
[2024-12-24T07:35:31.327+0000] {logging_mixin.py:190} INFO - [2024-12-24T07:35:31.326+0000] {dagbag.py:588} INFO - Filling up the DagBag from /opt/airflow/dags/local_to_gcs.py
[2024-12-24T07:35:31.372+0000] {logging_mixin.py:190} INFO - [2024-12-24T07:35:31.363+0000] {dagbag.py:387} ERROR - Failed to import: /opt/airflow/dags/local_to_gcs.py
Traceback (most recent call last):
  File "/home/airflow/.local/lib/python3.12/site-packages/airflow/models/dagbag.py", line 383, in parse
    loader.exec_module(new_module)
  File "<frozen importlib._bootstrap_external>", line 999, in exec_module
  File "<frozen importlib._bootstrap>", line 488, in _call_with_frames_removed
  File "/opt/airflow/dags/local_to_gcs.py", line 66, in <module>
    retail_dag = retail()  # Instantiate the DAG
                 ^^^^^^^^
  File "/home/airflow/.local/lib/python3.12/site-packages/airflow/models/dag.py", line 4307, in factory
    f(**f_kwargs)
  File "/opt/airflow/dags/local_to_gcs.py", line 31, in retail
    csv_files = [f for f in os.listdir(dataset_folder) if f.endswith(".csv")]
                            ^^^^^^^^^^^^^^^^^^^^^^^^^^
FileNotFoundError: [Errno 2] No such file or directory: 'include/dataset/'
[2024-12-24T07:35:31.373+0000] {processor.py:927} WARNING - No viable dags retrieved from /opt/airflow/dags/local_to_gcs.py
[2024-12-24T07:35:31.405+0000] {processor.py:208} INFO - Processing /opt/airflow/dags/local_to_gcs.py took 0.096 seconds
[2024-12-24T07:36:02.408+0000] {processor.py:186} INFO - Started process (PID=964) to work on /opt/airflow/dags/local_to_gcs.py
[2024-12-24T07:36:02.410+0000] {processor.py:914} INFO - Processing file /opt/airflow/dags/local_to_gcs.py for tasks to queue
[2024-12-24T07:36:02.414+0000] {logging_mixin.py:190} INFO - [2024-12-24T07:36:02.413+0000] {dagbag.py:588} INFO - Filling up the DagBag from /opt/airflow/dags/local_to_gcs.py
[2024-12-24T07:36:02.462+0000] {logging_mixin.py:190} INFO - [2024-12-24T07:36:02.454+0000] {dagbag.py:387} ERROR - Failed to import: /opt/airflow/dags/local_to_gcs.py
Traceback (most recent call last):
  File "/home/airflow/.local/lib/python3.12/site-packages/airflow/models/dagbag.py", line 383, in parse
    loader.exec_module(new_module)
  File "<frozen importlib._bootstrap_external>", line 999, in exec_module
  File "<frozen importlib._bootstrap>", line 488, in _call_with_frames_removed
  File "/opt/airflow/dags/local_to_gcs.py", line 66, in <module>
    retail_dag = retail()  # Instantiate the DAG
                 ^^^^^^^^
  File "/home/airflow/.local/lib/python3.12/site-packages/airflow/models/dag.py", line 4307, in factory
    f(**f_kwargs)
  File "/opt/airflow/dags/local_to_gcs.py", line 31, in retail
    csv_files = [f for f in os.listdir(dataset_folder) if f.endswith(".csv")]
                            ^^^^^^^^^^^^^^^^^^^^^^^^^^
FileNotFoundError: [Errno 2] No such file or directory: 'include/dataset/'
[2024-12-24T07:36:02.465+0000] {processor.py:927} WARNING - No viable dags retrieved from /opt/airflow/dags/local_to_gcs.py
[2024-12-24T07:36:02.497+0000] {processor.py:208} INFO - Processing /opt/airflow/dags/local_to_gcs.py took 0.098 seconds
[2024-12-24T07:36:33.214+0000] {processor.py:186} INFO - Started process (PID=1030) to work on /opt/airflow/dags/local_to_gcs.py
[2024-12-24T07:36:33.217+0000] {processor.py:914} INFO - Processing file /opt/airflow/dags/local_to_gcs.py for tasks to queue
[2024-12-24T07:36:33.226+0000] {logging_mixin.py:190} INFO - [2024-12-24T07:36:33.226+0000] {dagbag.py:588} INFO - Filling up the DagBag from /opt/airflow/dags/local_to_gcs.py
[2024-12-24T07:36:33.295+0000] {logging_mixin.py:190} INFO - [2024-12-24T07:36:33.284+0000] {dagbag.py:387} ERROR - Failed to import: /opt/airflow/dags/local_to_gcs.py
Traceback (most recent call last):
  File "/home/airflow/.local/lib/python3.12/site-packages/airflow/models/dagbag.py", line 383, in parse
    loader.exec_module(new_module)
  File "<frozen importlib._bootstrap_external>", line 999, in exec_module
  File "<frozen importlib._bootstrap>", line 488, in _call_with_frames_removed
  File "/opt/airflow/dags/local_to_gcs.py", line 66, in <module>
    retail_dag = retail()  # Instantiate the DAG
                 ^^^^^^^^
  File "/home/airflow/.local/lib/python3.12/site-packages/airflow/models/dag.py", line 4307, in factory
    f(**f_kwargs)
  File "/opt/airflow/dags/local_to_gcs.py", line 31, in retail
    csv_files = [f for f in os.listdir(dataset_folder) if f.endswith(".csv")]
                            ^^^^^^^^^^^^^^^^^^^^^^^^^^
FileNotFoundError: [Errno 2] No such file or directory: 'include/dataset/'
[2024-12-24T07:36:33.299+0000] {processor.py:927} WARNING - No viable dags retrieved from /opt/airflow/dags/local_to_gcs.py
[2024-12-24T07:36:33.333+0000] {processor.py:208} INFO - Processing /opt/airflow/dags/local_to_gcs.py took 0.139 seconds
[2024-12-24T07:37:04.028+0000] {processor.py:186} INFO - Started process (PID=1096) to work on /opt/airflow/dags/local_to_gcs.py
[2024-12-24T07:37:04.030+0000] {processor.py:914} INFO - Processing file /opt/airflow/dags/local_to_gcs.py for tasks to queue
[2024-12-24T07:37:04.034+0000] {logging_mixin.py:190} INFO - [2024-12-24T07:37:04.034+0000] {dagbag.py:588} INFO - Filling up the DagBag from /opt/airflow/dags/local_to_gcs.py
[2024-12-24T07:37:04.074+0000] {logging_mixin.py:190} INFO - [2024-12-24T07:37:04.064+0000] {dagbag.py:387} ERROR - Failed to import: /opt/airflow/dags/local_to_gcs.py
Traceback (most recent call last):
  File "/home/airflow/.local/lib/python3.12/site-packages/airflow/models/dagbag.py", line 383, in parse
    loader.exec_module(new_module)
  File "<frozen importlib._bootstrap_external>", line 999, in exec_module
  File "<frozen importlib._bootstrap>", line 488, in _call_with_frames_removed
  File "/opt/airflow/dags/local_to_gcs.py", line 66, in <module>
    retail_dag = retail()  # Instantiate the DAG
                 ^^^^^^^^
  File "/home/airflow/.local/lib/python3.12/site-packages/airflow/models/dag.py", line 4307, in factory
    f(**f_kwargs)
  File "/opt/airflow/dags/local_to_gcs.py", line 31, in retail
    csv_files = [f for f in os.listdir(dataset_folder) if f.endswith(".csv")]
                            ^^^^^^^^^^^^^^^^^^^^^^^^^^
FileNotFoundError: [Errno 2] No such file or directory: 'include/dataset/'
[2024-12-24T07:37:04.076+0000] {processor.py:927} WARNING - No viable dags retrieved from /opt/airflow/dags/local_to_gcs.py
[2024-12-24T07:37:04.105+0000] {processor.py:208} INFO - Processing /opt/airflow/dags/local_to_gcs.py took 0.086 seconds
[2024-12-24T07:37:25.813+0000] {processor.py:186} INFO - Started process (PID=1161) to work on /opt/airflow/dags/local_to_gcs.py
[2024-12-24T07:37:25.814+0000] {processor.py:914} INFO - Processing file /opt/airflow/dags/local_to_gcs.py for tasks to queue
[2024-12-24T07:37:25.818+0000] {logging_mixin.py:190} INFO - [2024-12-24T07:37:25.817+0000] {dagbag.py:588} INFO - Filling up the DagBag from /opt/airflow/dags/local_to_gcs.py
[2024-12-24T07:37:25.860+0000] {logging_mixin.py:190} INFO - [2024-12-24T07:37:25.860+0000] {local_to_gcs.py:31} ERROR - The directory include/dataset/ does not exist.
[2024-12-24T07:37:25.864+0000] {processor.py:925} INFO - DAG(s) 'local_to_gcs' retrieved from /opt/airflow/dags/local_to_gcs.py
[2024-12-24T07:37:26.010+0000] {logging_mixin.py:190} INFO - [2024-12-24T07:37:26.009+0000] {override.py:1911} INFO - Created Permission View: can read on DAG:local_to_gcs
[2024-12-24T07:37:26.043+0000] {logging_mixin.py:190} INFO - [2024-12-24T07:37:26.042+0000] {override.py:1911} INFO - Created Permission View: can edit on DAG:local_to_gcs
[2024-12-24T07:37:26.069+0000] {logging_mixin.py:190} INFO - [2024-12-24T07:37:26.068+0000] {override.py:1911} INFO - Created Permission View: can delete on DAG:local_to_gcs
[2024-12-24T07:37:26.097+0000] {logging_mixin.py:190} INFO - [2024-12-24T07:37:26.097+0000] {override.py:1911} INFO - Created Permission View: can read on DAG Run:local_to_gcs
[2024-12-24T07:37:26.121+0000] {logging_mixin.py:190} INFO - [2024-12-24T07:37:26.120+0000] {override.py:1911} INFO - Created Permission View: can create on DAG Run:local_to_gcs
[2024-12-24T07:37:26.158+0000] {logging_mixin.py:190} INFO - [2024-12-24T07:37:26.157+0000] {override.py:1911} INFO - Created Permission View: can delete on DAG Run:local_to_gcs
[2024-12-24T07:37:26.185+0000] {logging_mixin.py:190} INFO - [2024-12-24T07:37:26.184+0000] {override.py:1911} INFO - Created Permission View: menu access on DAG Run:local_to_gcs
[2024-12-24T07:37:26.192+0000] {logging_mixin.py:190} INFO - [2024-12-24T07:37:26.189+0000] {dag.py:3239} INFO - Sync 1 DAGs
[2024-12-24T07:37:26.223+0000] {logging_mixin.py:190} INFO - [2024-12-24T07:37:26.222+0000] {dag.py:3262} INFO - Creating ORM DAG for local_to_gcs
[2024-12-24T07:37:26.226+0000] {logging_mixin.py:190} INFO - [2024-12-24T07:37:26.225+0000] {dag.py:4180} INFO - Setting next_dagrun for local_to_gcs to None, run_after=None
[2024-12-24T07:37:26.264+0000] {processor.py:208} INFO - Processing /opt/airflow/dags/local_to_gcs.py took 0.459 seconds
[2024-12-24T07:37:56.383+0000] {processor.py:186} INFO - Started process (PID=1227) to work on /opt/airflow/dags/local_to_gcs.py
[2024-12-24T07:37:56.387+0000] {processor.py:914} INFO - Processing file /opt/airflow/dags/local_to_gcs.py for tasks to queue
[2024-12-24T07:37:56.403+0000] {logging_mixin.py:190} INFO - [2024-12-24T07:37:56.399+0000] {dagbag.py:588} INFO - Filling up the DagBag from /opt/airflow/dags/local_to_gcs.py
[2024-12-24T07:37:56.513+0000] {logging_mixin.py:190} INFO - [2024-12-24T07:37:56.512+0000] {local_to_gcs.py:31} ERROR - The directory include/dataset/ does not exist.
[2024-12-24T07:37:56.524+0000] {processor.py:925} INFO - DAG(s) 'local_to_gcs' retrieved from /opt/airflow/dags/local_to_gcs.py
[2024-12-24T07:37:56.577+0000] {logging_mixin.py:190} INFO - [2024-12-24T07:37:56.576+0000] {dag.py:3239} INFO - Sync 1 DAGs
[2024-12-24T07:37:56.605+0000] {logging_mixin.py:190} INFO - [2024-12-24T07:37:56.604+0000] {dag.py:4180} INFO - Setting next_dagrun for local_to_gcs to None, run_after=None
[2024-12-24T07:37:56.644+0000] {processor.py:208} INFO - Processing /opt/airflow/dags/local_to_gcs.py took 0.296 seconds
[2024-12-24T07:38:26.935+0000] {processor.py:186} INFO - Started process (PID=1292) to work on /opt/airflow/dags/local_to_gcs.py
[2024-12-24T07:38:26.936+0000] {processor.py:914} INFO - Processing file /opt/airflow/dags/local_to_gcs.py for tasks to queue
[2024-12-24T07:38:26.942+0000] {logging_mixin.py:190} INFO - [2024-12-24T07:38:26.941+0000] {dagbag.py:588} INFO - Filling up the DagBag from /opt/airflow/dags/local_to_gcs.py
[2024-12-24T07:38:26.972+0000] {logging_mixin.py:190} INFO - [2024-12-24T07:38:26.972+0000] {local_to_gcs.py:31} ERROR - The directory include/dataset/ does not exist.
[2024-12-24T07:38:26.977+0000] {processor.py:925} INFO - DAG(s) 'local_to_gcs' retrieved from /opt/airflow/dags/local_to_gcs.py
[2024-12-24T07:38:27.009+0000] {logging_mixin.py:190} INFO - [2024-12-24T07:38:27.009+0000] {dag.py:3239} INFO - Sync 1 DAGs
[2024-12-24T07:38:27.031+0000] {logging_mixin.py:190} INFO - [2024-12-24T07:38:27.031+0000] {dag.py:4180} INFO - Setting next_dagrun for local_to_gcs to None, run_after=None
[2024-12-24T07:38:27.064+0000] {processor.py:208} INFO - Processing /opt/airflow/dags/local_to_gcs.py took 0.137 seconds
[2024-12-24T07:38:57.214+0000] {processor.py:186} INFO - Started process (PID=1358) to work on /opt/airflow/dags/local_to_gcs.py
[2024-12-24T07:38:57.216+0000] {processor.py:914} INFO - Processing file /opt/airflow/dags/local_to_gcs.py for tasks to queue
[2024-12-24T07:38:57.219+0000] {logging_mixin.py:190} INFO - [2024-12-24T07:38:57.219+0000] {dagbag.py:588} INFO - Filling up the DagBag from /opt/airflow/dags/local_to_gcs.py
[2024-12-24T07:38:57.243+0000] {logging_mixin.py:190} INFO - [2024-12-24T07:38:57.243+0000] {local_to_gcs.py:31} ERROR - The directory include/dataset/ does not exist.
[2024-12-24T07:38:57.246+0000] {processor.py:925} INFO - DAG(s) 'local_to_gcs' retrieved from /opt/airflow/dags/local_to_gcs.py
[2024-12-24T07:38:57.272+0000] {logging_mixin.py:190} INFO - [2024-12-24T07:38:57.271+0000] {dag.py:3239} INFO - Sync 1 DAGs
[2024-12-24T07:38:57.290+0000] {logging_mixin.py:190} INFO - [2024-12-24T07:38:57.289+0000] {dag.py:4180} INFO - Setting next_dagrun for local_to_gcs to None, run_after=None
[2024-12-24T07:38:57.317+0000] {processor.py:208} INFO - Processing /opt/airflow/dags/local_to_gcs.py took 0.110 seconds
[2024-12-24T07:39:18.611+0000] {processor.py:186} INFO - Started process (PID=1389) to work on /opt/airflow/dags/local_to_gcs.py
[2024-12-24T07:39:18.613+0000] {processor.py:914} INFO - Processing file /opt/airflow/dags/local_to_gcs.py for tasks to queue
[2024-12-24T07:39:18.618+0000] {logging_mixin.py:190} INFO - [2024-12-24T07:39:18.617+0000] {dagbag.py:588} INFO - Filling up the DagBag from /opt/airflow/dags/local_to_gcs.py
[2024-12-24T07:39:18.695+0000] {logging_mixin.py:190} INFO - [2024-12-24T07:39:18.683+0000] {dagbag.py:387} ERROR - Failed to import: /opt/airflow/dags/local_to_gcs.py
Traceback (most recent call last):
  File "/home/airflow/.local/lib/python3.12/site-packages/airflow/models/dagbag.py", line 383, in parse
    loader.exec_module(new_module)
  File "<frozen importlib._bootstrap_external>", line 999, in exec_module
  File "<frozen importlib._bootstrap>", line 488, in _call_with_frames_removed
  File "/opt/airflow/dags/local_to_gcs.py", line 66, in <module>
    retail_dag = retail()  # Instantiate the DAG
                 ^^^^^^^^
  File "/home/airflow/.local/lib/python3.12/site-packages/airflow/models/dag.py", line 4307, in factory
    f(**f_kwargs)
  File "/opt/airflow/dags/local_to_gcs.py", line 31, in retail
    csv_files = [f for f in os.listdir(dataset_folder) if f.endswith(".csv")]
                            ^^^^^^^^^^^^^^^^^^^^^^^^^^
FileNotFoundError: [Errno 2] No such file or directory: 'include/dataset/'
[2024-12-24T07:39:18.697+0000] {processor.py:927} WARNING - No viable dags retrieved from /opt/airflow/dags/local_to_gcs.py
[2024-12-24T07:39:18.744+0000] {processor.py:208} INFO - Processing /opt/airflow/dags/local_to_gcs.py took 0.146 seconds
[2024-12-24T07:39:48.904+0000] {processor.py:186} INFO - Started process (PID=1454) to work on /opt/airflow/dags/local_to_gcs.py
[2024-12-24T07:39:48.905+0000] {processor.py:914} INFO - Processing file /opt/airflow/dags/local_to_gcs.py for tasks to queue
[2024-12-24T07:39:48.911+0000] {logging_mixin.py:190} INFO - [2024-12-24T07:39:48.910+0000] {dagbag.py:588} INFO - Filling up the DagBag from /opt/airflow/dags/local_to_gcs.py
[2024-12-24T07:39:48.945+0000] {logging_mixin.py:190} INFO - [2024-12-24T07:39:48.939+0000] {dagbag.py:387} ERROR - Failed to import: /opt/airflow/dags/local_to_gcs.py
Traceback (most recent call last):
  File "/home/airflow/.local/lib/python3.12/site-packages/airflow/models/dagbag.py", line 383, in parse
    loader.exec_module(new_module)
  File "<frozen importlib._bootstrap_external>", line 999, in exec_module
  File "<frozen importlib._bootstrap>", line 488, in _call_with_frames_removed
  File "/opt/airflow/dags/local_to_gcs.py", line 66, in <module>
    retail_dag = retail()  # Instantiate the DAG
                 ^^^^^^^^
  File "/home/airflow/.local/lib/python3.12/site-packages/airflow/models/dag.py", line 4307, in factory
    f(**f_kwargs)
  File "/opt/airflow/dags/local_to_gcs.py", line 31, in retail
    csv_files = [f for f in os.listdir(dataset_folder) if f.endswith(".csv")]
                            ^^^^^^^^^^^^^^^^^^^^^^^^^^
FileNotFoundError: [Errno 2] No such file or directory: 'include/dataset/'
[2024-12-24T07:39:48.946+0000] {processor.py:927} WARNING - No viable dags retrieved from /opt/airflow/dags/local_to_gcs.py
[2024-12-24T07:39:48.978+0000] {processor.py:208} INFO - Processing /opt/airflow/dags/local_to_gcs.py took 0.082 seconds
[2024-12-24T07:40:19.184+0000] {processor.py:186} INFO - Started process (PID=1518) to work on /opt/airflow/dags/local_to_gcs.py
[2024-12-24T07:40:19.186+0000] {processor.py:914} INFO - Processing file /opt/airflow/dags/local_to_gcs.py for tasks to queue
[2024-12-24T07:40:19.192+0000] {logging_mixin.py:190} INFO - [2024-12-24T07:40:19.189+0000] {dagbag.py:588} INFO - Filling up the DagBag from /opt/airflow/dags/local_to_gcs.py
[2024-12-24T07:40:19.256+0000] {logging_mixin.py:190} INFO - [2024-12-24T07:40:19.247+0000] {dagbag.py:387} ERROR - Failed to import: /opt/airflow/dags/local_to_gcs.py
Traceback (most recent call last):
  File "/home/airflow/.local/lib/python3.12/site-packages/airflow/models/dagbag.py", line 383, in parse
    loader.exec_module(new_module)
  File "<frozen importlib._bootstrap_external>", line 999, in exec_module
  File "<frozen importlib._bootstrap>", line 488, in _call_with_frames_removed
  File "/opt/airflow/dags/local_to_gcs.py", line 66, in <module>
    retail_dag = retail()  # Instantiate the DAG
                 ^^^^^^^^
  File "/home/airflow/.local/lib/python3.12/site-packages/airflow/models/dag.py", line 4307, in factory
    f(**f_kwargs)
  File "/opt/airflow/dags/local_to_gcs.py", line 31, in retail
    csv_files = [f for f in os.listdir(dataset_folder) if f.endswith(".csv")]
                            ^^^^^^^^^^^^^^^^^^^^^^^^^^
FileNotFoundError: [Errno 2] No such file or directory: 'include/dataset/'
[2024-12-24T07:40:19.258+0000] {processor.py:927} WARNING - No viable dags retrieved from /opt/airflow/dags/local_to_gcs.py
[2024-12-24T07:40:19.292+0000] {processor.py:208} INFO - Processing /opt/airflow/dags/local_to_gcs.py took 0.118 seconds
[2024-12-24T07:40:49.520+0000] {processor.py:186} INFO - Started process (PID=1586) to work on /opt/airflow/dags/local_to_gcs.py
[2024-12-24T07:40:49.523+0000] {processor.py:914} INFO - Processing file /opt/airflow/dags/local_to_gcs.py for tasks to queue
[2024-12-24T07:40:49.527+0000] {logging_mixin.py:190} INFO - [2024-12-24T07:40:49.526+0000] {dagbag.py:588} INFO - Filling up the DagBag from /opt/airflow/dags/local_to_gcs.py
[2024-12-24T07:40:49.618+0000] {logging_mixin.py:190} INFO - [2024-12-24T07:40:49.609+0000] {dagbag.py:387} ERROR - Failed to import: /opt/airflow/dags/local_to_gcs.py
Traceback (most recent call last):
  File "/home/airflow/.local/lib/python3.12/site-packages/airflow/models/dagbag.py", line 383, in parse
    loader.exec_module(new_module)
  File "<frozen importlib._bootstrap_external>", line 999, in exec_module
  File "<frozen importlib._bootstrap>", line 488, in _call_with_frames_removed
  File "/opt/airflow/dags/local_to_gcs.py", line 66, in <module>
    retail_dag = retail()  # Instantiate the DAG
                 ^^^^^^^^
  File "/home/airflow/.local/lib/python3.12/site-packages/airflow/models/dag.py", line 4307, in factory
    f(**f_kwargs)
  File "/opt/airflow/dags/local_to_gcs.py", line 31, in retail
    csv_files = [f for f in os.listdir(dataset_folder) if f.endswith(".csv")]
                            ^^^^^^^^^^^^^^^^^^^^^^^^^^
FileNotFoundError: [Errno 2] No such file or directory: 'include/dataset/'
[2024-12-24T07:40:49.623+0000] {processor.py:927} WARNING - No viable dags retrieved from /opt/airflow/dags/local_to_gcs.py
[2024-12-24T07:40:49.681+0000] {processor.py:208} INFO - Processing /opt/airflow/dags/local_to_gcs.py took 0.176 seconds
[2024-12-24T07:41:20.242+0000] {processor.py:186} INFO - Started process (PID=1652) to work on /opt/airflow/dags/local_to_gcs.py
[2024-12-24T07:41:20.244+0000] {processor.py:914} INFO - Processing file /opt/airflow/dags/local_to_gcs.py for tasks to queue
[2024-12-24T07:41:20.246+0000] {logging_mixin.py:190} INFO - [2024-12-24T07:41:20.246+0000] {dagbag.py:588} INFO - Filling up the DagBag from /opt/airflow/dags/local_to_gcs.py
[2024-12-24T07:41:20.296+0000] {logging_mixin.py:190} INFO - [2024-12-24T07:41:20.288+0000] {dagbag.py:387} ERROR - Failed to import: /opt/airflow/dags/local_to_gcs.py
Traceback (most recent call last):
  File "/home/airflow/.local/lib/python3.12/site-packages/airflow/models/dagbag.py", line 383, in parse
    loader.exec_module(new_module)
  File "<frozen importlib._bootstrap_external>", line 999, in exec_module
  File "<frozen importlib._bootstrap>", line 488, in _call_with_frames_removed
  File "/opt/airflow/dags/local_to_gcs.py", line 66, in <module>
    retail_dag = retail()  # Instantiate the DAG
                 ^^^^^^^^
  File "/home/airflow/.local/lib/python3.12/site-packages/airflow/models/dag.py", line 4307, in factory
    f(**f_kwargs)
  File "/opt/airflow/dags/local_to_gcs.py", line 31, in retail
    csv_files = [f for f in os.listdir(dataset_folder) if f.endswith(".csv")]
                            ^^^^^^^^^^^^^^^^^^^^^^^^^^
FileNotFoundError: [Errno 2] No such file or directory: 'include/dataset/'
[2024-12-24T07:41:20.298+0000] {processor.py:927} WARNING - No viable dags retrieved from /opt/airflow/dags/local_to_gcs.py
[2024-12-24T07:41:20.333+0000] {processor.py:208} INFO - Processing /opt/airflow/dags/local_to_gcs.py took 0.100 seconds
[2024-12-24T07:41:37.103+0000] {processor.py:186} INFO - Started process (PID=1689) to work on /opt/airflow/dags/local_to_gcs.py
[2024-12-24T07:41:37.107+0000] {processor.py:914} INFO - Processing file /opt/airflow/dags/local_to_gcs.py for tasks to queue
[2024-12-24T07:41:37.114+0000] {logging_mixin.py:190} INFO - [2024-12-24T07:41:37.112+0000] {dagbag.py:588} INFO - Filling up the DagBag from /opt/airflow/dags/local_to_gcs.py
[2024-12-24T07:41:37.206+0000] {logging_mixin.py:190} INFO - [2024-12-24T07:41:37.205+0000] {local_to_gcs.py:31} ERROR - The directory include/dataset/ does not exist.
[2024-12-24T07:41:37.216+0000] {processor.py:925} INFO - DAG(s) 'local_to_gcs' retrieved from /opt/airflow/dags/local_to_gcs.py
[2024-12-24T07:41:37.472+0000] {logging_mixin.py:190} INFO - [2024-12-24T07:41:37.472+0000] {dag.py:3239} INFO - Sync 1 DAGs
[2024-12-24T07:41:37.496+0000] {logging_mixin.py:190} INFO - [2024-12-24T07:41:37.496+0000] {dag.py:4180} INFO - Setting next_dagrun for local_to_gcs to None, run_after=None
[2024-12-24T07:41:37.535+0000] {processor.py:208} INFO - Processing /opt/airflow/dags/local_to_gcs.py took 0.446 seconds
[2024-12-24T07:42:07.663+0000] {processor.py:186} INFO - Started process (PID=1755) to work on /opt/airflow/dags/local_to_gcs.py
[2024-12-24T07:42:07.665+0000] {processor.py:914} INFO - Processing file /opt/airflow/dags/local_to_gcs.py for tasks to queue
[2024-12-24T07:42:07.667+0000] {logging_mixin.py:190} INFO - [2024-12-24T07:42:07.666+0000] {dagbag.py:588} INFO - Filling up the DagBag from /opt/airflow/dags/local_to_gcs.py
[2024-12-24T07:42:07.717+0000] {logging_mixin.py:190} INFO - [2024-12-24T07:42:07.710+0000] {dagbag.py:387} ERROR - Failed to import: /opt/airflow/dags/local_to_gcs.py
Traceback (most recent call last):
  File "/home/airflow/.local/lib/python3.12/site-packages/airflow/models/dagbag.py", line 383, in parse
    loader.exec_module(new_module)
  File "<frozen importlib._bootstrap_external>", line 999, in exec_module
  File "<frozen importlib._bootstrap>", line 488, in _call_with_frames_removed
  File "/opt/airflow/dags/local_to_gcs.py", line 66, in <module>
    retail_dag = retail()  # Instantiate the DAG
                 ^^^^^^^^
  File "/home/airflow/.local/lib/python3.12/site-packages/airflow/models/dag.py", line 4307, in factory
    f(**f_kwargs)
  File "/opt/airflow/dags/local_to_gcs.py", line 31, in retail
    csv_files = [f for f in os.listdir(dataset_folder) if f.endswith(".csv")]
                            ^^^^^^^^^^^^^^^^^^^^^^^^^^
FileNotFoundError: [Errno 2] No such file or directory: 'include/dataset/'
[2024-12-24T07:42:07.720+0000] {processor.py:927} WARNING - No viable dags retrieved from /opt/airflow/dags/local_to_gcs.py
[2024-12-24T07:42:07.748+0000] {processor.py:208} INFO - Processing /opt/airflow/dags/local_to_gcs.py took 0.094 seconds
[2024-12-24T07:42:07.796+0000] {processor.py:186} INFO - Started process (PID=1756) to work on /opt/airflow/dags/local_to_gcs.py
[2024-12-24T07:42:07.797+0000] {processor.py:914} INFO - Processing file /opt/airflow/dags/local_to_gcs.py for tasks to queue
[2024-12-24T07:42:07.800+0000] {logging_mixin.py:190} INFO - [2024-12-24T07:42:07.799+0000] {dagbag.py:588} INFO - Filling up the DagBag from /opt/airflow/dags/local_to_gcs.py
[2024-12-24T07:42:07.836+0000] {logging_mixin.py:190} INFO - [2024-12-24T07:42:07.828+0000] {dagbag.py:387} ERROR - Failed to import: /opt/airflow/dags/local_to_gcs.py
Traceback (most recent call last):
  File "/home/airflow/.local/lib/python3.12/site-packages/airflow/models/dagbag.py", line 383, in parse
    loader.exec_module(new_module)
  File "<frozen importlib._bootstrap_external>", line 999, in exec_module
  File "<frozen importlib._bootstrap>", line 488, in _call_with_frames_removed
  File "/opt/airflow/dags/local_to_gcs.py", line 66, in <module>
    retail_dag = retail()  # Instantiate the DAG
                 ^^^^^^^^
  File "/home/airflow/.local/lib/python3.12/site-packages/airflow/models/dag.py", line 4307, in factory
    f(**f_kwargs)
  File "/opt/airflow/dags/local_to_gcs.py", line 31, in retail
    csv_files = [f for f in os.listdir(dataset_folder) if f.endswith(".csv")]
                            ^^^^^^^^^^^^^^^^^^^^^^^^^^
FileNotFoundError: [Errno 2] No such file or directory: 'include/dataset/'
[2024-12-24T07:42:07.838+0000] {processor.py:927} WARNING - No viable dags retrieved from /opt/airflow/dags/local_to_gcs.py
[2024-12-24T07:42:07.872+0000] {processor.py:208} INFO - Processing /opt/airflow/dags/local_to_gcs.py took 0.084 seconds
[2024-12-24T07:42:07.925+0000] {processor.py:186} INFO - Started process (PID=1757) to work on /opt/airflow/dags/local_to_gcs.py
[2024-12-24T07:42:07.927+0000] {processor.py:914} INFO - Processing file /opt/airflow/dags/local_to_gcs.py for tasks to queue
[2024-12-24T07:42:07.929+0000] {logging_mixin.py:190} INFO - [2024-12-24T07:42:07.928+0000] {dagbag.py:588} INFO - Filling up the DagBag from /opt/airflow/dags/local_to_gcs.py
[2024-12-24T07:42:07.964+0000] {logging_mixin.py:190} INFO - [2024-12-24T07:42:07.957+0000] {dagbag.py:387} ERROR - Failed to import: /opt/airflow/dags/local_to_gcs.py
Traceback (most recent call last):
  File "/home/airflow/.local/lib/python3.12/site-packages/airflow/models/dagbag.py", line 383, in parse
    loader.exec_module(new_module)
  File "<frozen importlib._bootstrap_external>", line 999, in exec_module
  File "<frozen importlib._bootstrap>", line 488, in _call_with_frames_removed
  File "/opt/airflow/dags/local_to_gcs.py", line 66, in <module>
    retail_dag = retail()  # Instantiate the DAG
                 ^^^^^^^^
  File "/home/airflow/.local/lib/python3.12/site-packages/airflow/models/dag.py", line 4307, in factory
    f(**f_kwargs)
  File "/opt/airflow/dags/local_to_gcs.py", line 31, in retail
    csv_files = [f for f in os.listdir(dataset_folder) if f.endswith(".csv")]
                            ^^^^^^^^^^^^^^^^^^^^^^^^^^
FileNotFoundError: [Errno 2] No such file or directory: 'include/dataset/'
[2024-12-24T07:42:07.966+0000] {processor.py:927} WARNING - No viable dags retrieved from /opt/airflow/dags/local_to_gcs.py
[2024-12-24T07:42:07.997+0000] {processor.py:208} INFO - Processing /opt/airflow/dags/local_to_gcs.py took 0.081 seconds
